Workbook

Sheet ENERO
D1: FORMATO REGISTRO ANUAL DE GENERACION DE RESIDUOS GENERADOS EN LA ATENCION EN SALUD Y OTRAS ACTIVIDADES
A7: 1. Nombre de la institucion: | K7: 6. Correo Electronico
A8: 2. Ciudad | K8: 7. Responsable del diligenciamiento
A9: 3. Departamento | K9: 8. Cargo
A10: 4. Direccion | K10: 9. Mes:
A11: 5. Telefono
A14: CONSOLIDACION RESIDUOS POR DTS
B16: 10 | C16: 11 | D16: 12 | E16: 13 | F16: 14 | G16: 15 | H16: 16 | I16: 17 | J16: 18 | K16: 19 | L16: 20 | M16: 21 | N16: 22 | O16: 23 | P16: 24 | Q16: 25 | R16: 26
A17: DÍA | B17: RESIDUOS NO PELIGROS | E17: Subtotal Residuos no peligrosos | F17: RESIDUOS PELIGROSOS | Q17: Subtotal Residuos Peligrosos | R17: TOTAL
F18: INFECCIOSO O RIESGO BIOLOGICO | J18: Subtotal residuos de riesgo biologico o infeccioso | K18: OTROS RESIDUOS CON LAS SIGUIENTES CARACTERISTICAS | P18: Subtotal otros residuos
B19: BIODEGRADABLES (KG/AÑO) | C19: RECICLABLES (KG/AÑO) | D19: ORDINARIOS (KG/AÑO) | F19: BIOSANITARIOS (KG/AÑO) | G19: ANATOMOPATOLOGICOS (KG/AÑO) | H19: CORTOPUNZANTES (KG/AÑO) | I19: ANIMALES (KG/AÑO) | K19: CORROSIVA (KG/AÑO) | L19: EXPLOSIVO (KG/AÑO) | M19: TOXICO (KG/AÑO) | N19: INFLAMABLE (KG/AÑO) | O19: REACTIVO (KG/AÑO)
B20: 1 | C20: 2 | D20: 3 | E20: =SUM(B20:D20) -> 6 | F20: 4 | G20: 5 | H20: 6 | I20: 7 | J20: =SUM(F20:I20) -> 22 | K20: 8 | L20: 9 | M20: 0 | N20: 1 | O20: 2 | P20: =SUM(K20:O20) -> 20 | Q20: =J20+P20 -> 42 | R20: =SUM(B20:O20) -> 76
E21: =SUM(B21:D21) -> 0 | J21: =SUM(F21:I21) -> 0 | P21: =SUM(K21:O21) -> 0 | Q21: =J21+P21 -> 0 | R21: =SUM(B21:O21) -> 0
E22: =SUM(B22:D22) -> 0 | J22: =SUM(F22:I22) -> 0 | P22: =SUM(K22:O22) -> 0 | Q22: =J22+P22 -> 0 | R22: =SUM(B22:O22) -> 0
E23: =SUM(B23:D23) -> 0 | J23: =SUM(F23:I23) -> 0 | P23: =SUM(K23:O23) -> 0 | Q23: =J23+P23 -> 0 | R23: =SUM(B23:O23) -> 0
E24: =SUM(B24:D24) -> 0 | J24: =SUM(F24:I24) -> 0 | P24: =SUM(K24:O24) -> 0 | Q24: =J24+P24 -> 0 | R24: =SUM(B24:O24) -> 0
E25: =SUM(B25:D25) -> 0 | J25: =SUM(F25:I25) -> 0 | P25: =SUM(K25:O25) -> 0 | Q25: =J25+P25 -> 0 | R25: =SUM(B25:O25) -> 0
E26: =SUM(B26:D26) -> 0 | J26: =SUM(F26:I26) -> 0 | P26: =SUM(K26:O26) -> 0 | Q26: =J26+P26 -> 0 | R26: =SUM(B26:O26) -> 0
E27: =SUM(B27:D27) -> 0 | J27: =SUM(F27:I27) -> 0 | P27: =SUM(K27:O27) -> 0 | Q27: =J27+P27 -> 0 | R27: =SUM(B27:O27) -> 0
E28: =SUM(B28:D28) -> 0 | J28: =SUM(F28:I28) -> 0 | P28: =SUM(K28:O28) -> 0 | Q28: =J28+P28 -> 0 | R28: =SUM(B28:O28) -> 0
E29: =SUM(B29:D29) -> 0 | J29: =SUM(F29:I29) -> 0 | P29: =SUM(K29:O29) -> 0 | Q29: =J29+P29 -> 0 | R29: =SUM(B29:O29) -> 0
E30: =SUM(B30:D30) -> 0 | J30: =SUM(F30:I30) -> 0 | P30: =SUM(K30:O30) -> 0 | Q30: =J30+P30 -> 0 | R30: =SUM(B30:O30) -> 0
E31: =SUM(B31:D31) -> 0 | J31: =SUM(F31:I31) -> 0 | P31: =SUM(K31:O31) -> 0 | Q31: =J31+P31 -> 0 | R31: =SUM(B31:O31) -> 0
E32: =SUM(B32:D32) -> 0 | J32: =SUM(F32:I32) -> 0 | P32: =SUM(K32:O32) -> 0 | Q32: =J32+P32 -> 0 | R32: =SUM(B32:O32) -> 0
... E50: =SUM(B50:D50) -> 0 | J50: =SUM(F50:I50) -> 0 | P50: =SUM(K50:O50) -> 0 | Q50: =J50+P50 -> 0 | R50: =SUM(B50:O50) -> 0
A51: TOTAL | B51: =SUM(B20:B50) -> 1 | C51: =SUM(C20:C50) -> 2 | D51: =SUM(D20:D50) -> 3 | E51: =SUM(E20:E50) -> 6 | F51: =SUM(F20:F50) -> 4 | G51: =SUM(G20:G50) -> 5 | H51: =SUM(H20:H50) -> 6 | I51: =SUM(I20:I50) -> 7 | ... R51: =SUM(R20:R50) -> 76
A54: INDICADORES DE DESTINACION
B57: 27 | C57: 29 | D57: 29 | E57: 30 | F57: 31 | G57: 32 | J57: 33
A58: AÑO | B58: DESTINACIÓN DE RESIDUOS | G58: TOTAL | I58: MES | K58: INDICADORES DE DESTINACIÓN % | O58: INDICADOR TOTAL (%)
B59: DESACTIVACION (KG/AÑO) | C59: RECICLAJE (KG/AÑO) | D59: INCINERACIÓN (KG/AÑO) | E59: RELLENO SANITARIO (KG/AÑO) | F59: OTROS SISTEMAS DE DISPOSICION FINAL | J59: IDD | K59: IDR | L59: IDI | M59: IDRS | N59: IDOS
A60: Enero | G60: =SUM(B60:F60) -> 0 | I60: Enero | J60: =(B60/$R$51)*100 -> 0 | K60: =(C60/$R$51)*100 -> 0 | L60: =(D60/$R$51)*100 -> 0 | M60: =(E60/$R$51)*100 -> 0 | N60: =(F60/$R$51)*100 -> 0 | O60: =SUM(J60:N60)/100 -> 0
I63: IDD: Indicador de destinacion desactivacion de alta eficiencia
I64: IDR: Indicador de destinacion para reciclaje
I65: IDI: Indicador de destinacion para incineracion
I66: IDRS: Indicador de destinacion para relleno sanitario

Sheet FEBRERO
D1: FORMATO REGISTRO ANUAL DE GENERACION DE RESIDUOS GENERADOS EN LA ATENCION EN SALUD Y OTRAS ACTIVIDADES
A7: 1. Nombre de la institucion: | K7: 6. Correo Electronico
A8: 2. Ciudad | K8: 7. Responsable del diligenciamiento
A9: 3. Departamento | K9: 8. Cargo
A10: 4. Direccion | K10: 9. Mes:
A11: 5. Telefono
A14: CONSOLIDACION RESIDUOS POR DTS
B16: 10 | C16: 11 | D16: 12 | E16: 13 | F16: 14 | G16: 15 | H16: 16 | I16: 17 | J16: 18 | K16: 19 | L16: 20 | M16: 21 | N16: 22 | O16: 23 | P16: 24 | Q16: 25 | R16: 26
A17: DÍA | B17: RESIDUOS NO PELIGROS | E17: Subtotal Residuos no peligrosos | F17: RESIDUOS PELIGROSOS | Q17: Subtotal Residuos Peligrosos | R17: TOTAL
F18: INFECCIOSO O RIESGO BIOLOGICO | J18: Subtotal residuos de riesgo biologico o infeccioso | K18: OTROS RESIDUOS CON LAS SIGUIENTES CARACTERISTICAS | P18: Subtotal otros residuos
B19: BIODEGRADABLES (KG/AÑO) | C19: RECICLABLES (KG/AÑO) | D19: ORDINARIOS (KG/AÑO) | F19: BIOSANITARIOS (KG/AÑO) | G19: ANATOMOPATOLOGICOS (KG/AÑO) | H19: CORTOPUNZANTES (KG/AÑO) | I19: ANIMALES (KG/AÑO) | K19: CORROSIVA (KG/AÑO) | L19: EXPLOSIVO (KG/AÑO) | M19: TOXICO (KG/AÑO) | N19: INFLAMABLE (KG/AÑO) | O19: REACTIVO (KG/AÑO)
B20: 1 | C20: 2 | D20: 3 | E20: =SUM(B20:D20) -> 6 | F20: 4 | G20: 5 | H20: 6 | I20: 7 | J20: =SUM(F20:I20) -> 22 | K20: 8 | L20: 9 | M20: 0 | N20: 1 | O20: 2 | P20: =SUM(K20:O20) -> 20 | Q20: =J20+P20 -> 42 | R20: =SUM(B20:O20) -> 76
E21: =SUM(B21:D21) -> 0 | J21: =SUM(F21:I21) -> 0 | P21: =SUM(K21:O21) -> 0 | Q21: =J21+P21 -> 0 | R21: =SUM(B21:O21) -> 0
E22: =SUM(B22:D22) -> 0 | J22: =SUM(F22:I22) -> 0 | P22: =SUM(K22:O22) -> 0 | Q22: =J22+P22 -> 0 | R22: =SUM(B22:O22) -> 0
E23: =SUM(B23:D23) -> 0 | J23: =SUM(F23:I23) -> 0 | P23: =SUM(K23:O23) -> 0 | Q23: =J23+P23 -> 0 | R23: =SUM(B23:O23) -> 0
E24: =SUM(B24:D24) -> 0 | J24: =SUM(F24:I24) -> 0 | P24: =SUM(K24:O24) -> 0 | Q24: =J24+P24 -> 0 | R24: =SUM(B24:O24) -> 0
E25: =SUM(B25:D25) -> 0 | J25: =SUM(F25:I25) -> 0 | P25: =SUM(K25:O25) -> 0 | Q25: =J25+P25 -> 0 | R25: =SUM(B25:O25) -> 0
E26: =SUM(B26:D26) -> 0 | J26: =SUM(F26:I26) -> 0 | P26: =SUM(K26:O26) -> 0 | Q26: =J26+P26 -> 0 | R26: =SUM(B26:O26) -> 0
E27: =SUM(B27:D27) -> 0 | J27: =SUM(F27:I27) -> 0 | P27: =SUM(K27:O27) -> 0 | Q27: =J27+P27 -> 0 | R27: =SUM(B27:O27) -> 0
E28: =SUM(B28:D28) -> 0 | J28: =SUM(F28:I28) -> 0 | P28: =SUM(K28:O28) -> 0 | Q28: =J28+P28 -> 0 | R28: =SUM(B28:O28) -> 0
E29: =SUM(B29:D29) -> 0 | J29: =SUM(F29:I29) -> 0 | P29: =SUM(K29:O29) -> 0 | Q29: =J29+P29 -> 0 | R29: =SUM(B29:O29) -> 0
E30: =SUM(B30:D30) -> 0 | J30: =SUM(F30:I30) -> 0 | P30: =SUM(K30:O30) -> 0 | Q30: =J30+P30 -> 0 | R30: =SUM(B30:O30) -> 0
E31: =SUM(B31:D31) -> 0 | J31: =SUM(F31:I31) -> 0 | P31: =SUM(K31:O31) -> 0 | Q31: =J31+P31 -> 0 | R31: =SUM(B31:O31) -> 0
E32: =SUM(B32:D32) -> 0 | J32: =SUM(F32:I32) -> 0 | P32: =SUM(K32:O32) -> 0 | Q32: =J32+P32 -> 0 | R32: =SUM(B32:O32) -> 0
... E50: =SUM(B50:D50) -> 0 | J50: =SUM(F50:I50) -> 0 | P50: =SUM(K50:O50) -> 0 | Q50: =J50+P50 -> 0 | R50: =SUM(B50:O50) -> 0
A51: TOTAL | B51: =SUM(B20:B50) -> 1 | C51: =SUM(C20:C50) -> 2 | D51: =SUM(D20:D50) -> 3 | E51: =SUM(E20:E50) -> 6 | F51: =SUM(F20:F50) -> 4 | G51: =SUM(G20:G50) -> 5 | H51: =SUM(H20:H50) -> 6 | I51: =SUM(I20:I50) -> 7 | ... R51: =SUM(R20:R50) -> 76
A54: INDICADORES DE DESTINACION
B57: 27 | C57: 29 | D57: 29 | E57: 30 | F57: 31 | G57: 32 | J57: 33
A58: AÑO | B58: DESTINACIÓN DE RESIDUOS | G58: TOTAL | I58: MES | K58: INDICADORES DE DESTINACIÓN % | O58: INDICADOR TOTAL (%)
B59: DESACTIVACION (KG/AÑO) | C59: RECICLAJE (KG/AÑO) | D59: INCINERACIÓN (KG/AÑO) | E59: RELLENO SANITARIO (KG/AÑO) | F59: OTROS SISTEMAS DE DISPOSICION FINAL | J59: IDD | K59: IDR | L59: IDI | M59: IDRS | N59: IDOS
A60: Enero | B60: =+ENERO!B60 -> 0 | C60: =+ENERO!C60 -> 0 | D60: =+ENERO!D60 -> 0 | E60: =+ENERO!E60 -> 0 | F60: =+ENERO!F60 -> 0 | G60: =SUM(B60:F60) -> 0 | I60: Enero | J60: =(B60/ENERO!$R$51)*100 -> 0 | K60: =(C60/ENERO!$R$51)*100 -> 0 | L60: =(D60/ENERO!$R$51)*100 -> 0 | M60: =(E60/ENERO!$R$51)*100 -> 0 | N60: =(F60/ENERO!$R$51)*100 -> 0 | O60: =SUM(J60:N60)/100 -> 0
A61: Febrero | G61: =SUM(B61:F61) -> 0 | I61: Febrero | J61: =(B61/$R$51)*100 -> 0 | K61: =(C61/$R$51)*100 -> 0 | L61: =(D61/$R$51)*100 -> 0 | M61: =(E61/$R$51)*100 -> 0 | N61: =(F61/$R$51)*100 -> 0 | O61: =SUM(J61:N61)/100 -> 0
I64: IDD: Indicador de destinacion desactivacion de alta eficiencia
I65: IDR: Indicador de destinacion para reciclaje
I66: IDI: Indicador de destinacion para incineracion
I67: IDRS: Indicador de destinacion para relleno sanitario

Sheet MARZO
D1: FORMATO REGISTRO ANUAL DE GENERACION DE RESIDUOS GENERADOS EN LA ATENCION EN SALUD Y OTRAS ACTIVIDADES
A7: 1. Nombre de la institucion: | K7: 6. Correo Electronico
A8: 2. Ciudad | K8: 7. Responsable del diligenciamiento
A9: 3. Departamento | K9: 8. Cargo
A10: 4. Direccion | K10: 9. Mes:
A11: 5. Telefono
A14: CONSOLIDACION RESIDUOS POR DTS
B16: 10 | C16: 11 | D16: 12 | E16: 13 | F16: 14 | G16: 15 | H16: 16 | I16: 17 | J16: 18 | K16: 19 | L16: 20 | M16: 21 | N16: 22 | O16: 23 | P16: 24 | Q16: 25 | R16: 26
A17: DÍA | B17: RESIDUOS NO PELIGROS | E17: Subtotal Residuos no peligrosos | F17: RESIDUOS PELIGROSOS | Q17: Subtotal Residuos Peligrosos | R17: TOTAL
F18: INFECCIOSO O RIESGO BIOLOGICO | J18: Subtotal residuos de riesgo biologico o infeccioso | K18: OTROS RESIDUOS CON LAS SIGUIENTES CARACTERISTICAS | P18: Subtotal otros residuos
B19: BIODEGRADABLES (KG/AÑO) | C19: RECICLABLES (KG/AÑO) | D19: ORDINARIOS (KG/AÑO) | F19: BIOSANITARIOS (KG/AÑO) | G19: ANATOMOPATOLOGICOS (KG/AÑO) | H19: CORTOPUNZANTES (KG/AÑO) | I19: ANIMALES (KG/AÑO) | K19: CORROSIVA (KG/AÑO) | L19: EXPLOSIVO (KG/AÑO) | M19: TOXICO (KG/AÑO) | N19: INFLAMABLE (KG/AÑO) | O19: REACTIVO (KG/AÑO)
B20: 1 | C20: 2 | D20: 3 | E20: =SUM(B20:D20) -> 6 | F20: 4 | G20: 5 | H20: 6 | I20: 7 | J20: =SUM(F20:I20) -> 22 | K20: 8 | L20: 9 | M20: 0 | N20: 1 | O20: 2 | P20: =SUM(K20:O20) -> 20 | Q20: =J20+P20 -> 42 | R20: =SUM(B20:O20) -> 76
E21: =SUM(B21:D21) -> 0 | J21: =SUM(F21:I21) -> 0 | P21: =SUM(K21:O21) -> 0 | Q21: =J21+P21 -> 0 | R21: =SUM(B21:O21) -> 0
E22: =SUM(B22:D22) -> 0 | J22: =SUM(F22:I22) -> 0 | P22: =SUM(K22:O22) -> 0 | Q22: =J22+P22 -> 0 | R22: =SUM(B22:O22) -> 0
E23: =SUM(B23:D23) -> 0 | J23: =SUM(F23:I23) -> 0 | P23: =SUM(K23:O23) -> 0 | Q23: =J23+P23 -> 0 | R23: =SUM(B23:O23) -> 0
E24: =SUM(B24:D24) -> 0 | J24: =SUM(F24:I24) -> 0 | P24: =SUM(K24:O24) -> 0 | Q24: =J24+P24 -> 0 | R24: =SUM(B24:O24) -> 0
E25: =SUM(B25:D25) -> 0 | J25: =SUM(F25:I25) -> 0 | P25: =SUM(K25:O25) -> 0 | Q25: =J25+P25 -> 0 | R25: =SUM(B25:O25) -> 0
E26: =SUM(B26:D26) -> 0 | J26: =SUM(F26:I26) -> 0 | P26: =SUM(K26:O26) -> 0 | Q26: =J26+P26 -> 0 | R26: =SUM(B26:O26) -> 0
E27: =SUM(B27:D27) -> 0 | J27: =SUM(F27:I27) -> 0 | P27: =SUM(K27:O27) -> 0 | Q27: =J27+P27 -> 0 | R27: =SUM(B27:O27) -> 0
E28: =SUM(B28:D28) -> 0 | J28: =SUM(F28:I28) -> 0 | P28: =SUM(K28:O28) -> 0 | Q28: =J28+P28 -> 0 | R28: =SUM(B28:O28) -> 0
E29: =SUM(B29:D29) -> 0 | J29: =SUM(F29:I29) -> 0 | P29: =SUM(K29:O29) -> 0 | Q29: =J29+P29 -> 0 | R29: =SUM(B29:O29) -> 0
E30: =SUM(B30:D30) -> 0 | J30: =SUM(F30:I30) -> 0 | P30: =SUM(K30:O30) -> 0 | Q30: =J30+P30 -> 0 | R30: =SUM(B30:O30) -> 0
E31: =SUM(B31:D31) -> 0 | J31: =SUM(F31:I31) -> 0 | P31: =SUM(K31:O31) -> 0 | Q31: =J31+P31 -> 0 | R31: =SUM(B31:O31) -> 0
E32: =SUM(B32:D32) -> 0 | J32: =SUM(F32:I32) -> 0 | P32: =SUM(K32:O32) -> 0 | Q32: =J32+P32 -> 0 | R32: =SUM(B32:O32) -> 0
... E50: =SUM(B50:D50) -> 0 | J50: =SUM(F50:I50) -> 0 | P50: =SUM(K50:O50) -> 0 | Q50: =J50+P50 -> 0 | R50: =SUM(B50:O50) -> 0
A51: TOTAL | B51: =SUM(B20:B50) -> 1 | C51: =SUM(C20:C50) -> 2 | D51: =SUM(D20:D50) -> 3 | E51: =SUM(E20:E50) -> 6 | F51: =SUM(F20:F50) -> 4 | G51: =SUM(G20:G50) -> 5 | H51: =SUM(H20:H50) -> 6 | I51: =SUM(I20:I50) -> 7 | ... R51: =SUM(R20:R50) -> 76
A54: INDICADORES DE DESTINACION
B57: 27 | C57: 29 | D57: 29 | E57: 30 | F57: 31 | G57: 32 | J57: 33
A58: AÑO | B58: DESTINACIÓN DE RESIDUOS | G58: TOTAL | I58: MES | K58: INDICADORES DE DESTINACIÓN % | O58: INDICADOR TOTAL (%)
B59: DESACTIVACION (KG/AÑO) | C59: RECICLAJE (KG/AÑO) | D59: INCINERACIÓN (KG/AÑO) | E59: RELLENO SANITARIO (KG/AÑO) | F59: OTROS SISTEMAS DE DISPOSICION FINAL | J59: IDD | K59: IDR | L59: IDI | M59: IDRS | N59: IDOS
A60: Enero | B60: =+ENERO!B60 -> 0 | C60: =+ENERO!C60 -> 0 | D60: =+ENERO!D60 -> 0 | E60: =+ENERO!E60 -> 0 | F60: =+ENERO!F60 -> 0 | G60: =SUM(B60:F60) -> 0 | I60: Enero | J60: =(B60/ENERO!$R$51)*100 -> 0 | K60: =(C60/ENERO!$R$51)*100 -> 0 | L60: =(D60/ENERO!$R$51)*100 -> 0 | M60: =(E60/ENERO!$R$51)*100 -> 0 | N60: =(F60/ENERO!$R$51)*100 -> 0 | O60: =SUM(J60:N60)/100 -> 0
A61: Febrero | B61: =+FEBRERO!B61 -> 0 | C61: =+FEBRERO!C61 -> 0 | D61: =+FEBRERO!D61 -> 0 | E61: =+FEBRERO!E61 -> 0 | F61: =+FEBRERO!F61 -> 0 | G61: =SUM(B61:F61) -> 0 | I61: Febrero | J61: =(B61/FEBRERO!$R$51)*100 -> 0 | K61: =(C61/FEBRERO!$R$51)*100 -> 0 | L61: =(D61/FEBRERO!$R$51)*100 -> 0 | M61: =(E61/FEBRERO!$R$51)*100 -> 0 | N61: =(F61/FEBRERO!$R$51)*100 -> 0 | O61: =SUM(J61:N61)/100 -> 0
A62: Marzo | G62: =SUM(B62:F62) -> 0 | I62: Marzo | J62: =(B62/$R$51)*100 -> 0 | K62: =(C62/$R$51)*100 -> 0 | L62: =(D62/$R$51)*100 -> 0 | M62: =(E62/$R$51)*100 -> 0 | N62: =(F62/$R$51)*100 -> 0 | O62: =SUM(J62:N62)/100 -> 0
I65: IDD: Indicador de destinacion desactivacion de alta eficiencia
I66: IDR: Indicador de destinacion para reciclaje
I67: IDI: Indicador de destinacion para incineracion
I68: IDRS: Indicador de destinacion para relleno sanitario

Sheet ABRIL
D1: FORMATO REGISTRO ANUAL DE GENERACION DE RESIDUOS GENERADOS EN LA ATENCION EN SALUD Y OTRAS ACTIVIDADES
A7: 1. Nombre de la institucion: | K7: 6. Correo Electronico
A8: 2. Ciudad | K8: 7. Responsable del diligenciamiento
A9: 3. Departamento | K9: 8. Cargo
A10: 4. Direccion | K10: 9. Mes:
A11: 5. Telefono
A14: CONSOLIDACION RESIDUOS POR DTS
B16: 10 | C16: 11 | D16: 12 | E16: 13 | F16: 14 | G16: 15 | H16: 16 | I16: 17 | J16: 18 | K16: 19 | L16: 20 | M16: 21 | N16: 22 | O16: 23 | P16: 24 | Q16: 25 | R16: 26
A17: DÍA | B17: RESIDUOS NO PELIGROS | E17: Subtotal Residuos no peligrosos | F17: RESIDUOS PELIGROSOS | Q17: Subtotal Residuos Peligrosos | R17: TOTAL
F18: INFECCIOSO O RIESGO BIOLOGICO | J18: Subtotal residuos de riesgo biologico o infeccioso | K18: OTROS RESIDUOS CON LAS SIGUIENTES CARACTERISTICAS | P18: Subtotal otros residuos
B19: BIODEGRADABLES (KG/AÑO) | C19: RECICLABLES (KG/AÑO) | D19: ORDINARIOS (KG/AÑO) | F19: BIOSANITARIOS (KG/AÑO) | G19: ANATOMOPATOLOGICOS (KG/AÑO) | H19: CORTOPUNZANTES (KG/AÑO) | I19: ANIMALES (KG/AÑO) | K19: CORROSIVA (KG/AÑO) | L19: EXPLOSIVO (KG/AÑO) | M19: TOXICO (KG/AÑO) | N19: INFLAMABLE (KG/AÑO) | O19: REACTIVO (KG/AÑO)
B20: 1 | C20: 2 | D20: 3 | E20: =SUM(B20:D20) -> 6 | F20: 4 | G20: 5 | H20: 6 | I20: 7 | J20: =SUM(F20:I20) -> 22 | K20: 8 | L20: 9 | M20: 0 | N20: 1 | O20: 2 | P20: =SUM(K20:O20) -> 20 | Q20: =J20+P20 -> 42 | R20: =SUM(B20:O20) -> 76
E21: =SUM(B21:D21) -> 0 | J21: =SUM(F21:I21) -> 0 | P21: =SUM(K21:O21) -> 0 | Q21: =J21+P21 -> 0 | R21: =SUM(B21:O21) -> 0
E22: =SUM(B22:D22) -> 0 | J22: =SUM(F22:I22) -> 0 | P22: =SUM(K22:O22) -> 0 | Q22: =J22+P22 -> 0 | R22: =SUM(B22:O22) -> 0
E23: =SUM(B23:D23) -> 0 | J23: =SUM(F23:I23) -> 0 | P23: =SUM(K23:O23) -> 0 | Q23: =J23+P23 -> 0 | R23: =SUM(B23:O23) -> 0
E24: =SUM(B24:D24) -> 0 | J24: =SUM(F24:I24) -> 0 | P24: =SUM(K24:O24) -> 0 | Q24: =J24+P24 -> 0 | R24: =SUM(B24:O24) -> 0
E25: =SUM(B25:D25) -> 0 | J25: =SUM(F25:I25) -> 0 | P25: =SUM(K25:O25) -> 0 | Q25: =J25+P25 -> 0 | R25: =SUM(B25:O25) -> 0
E26: =SUM(B26:D26) -> 0 | J26: =SUM(F26:I26) -> 0 | P26: =SUM(K26:O26) -> 0 | Q26: =J26+P26 -> 0 | R26: =SUM(B26:O26) -> 0
E27: =SUM(B27:D27) -> 0 | J27: =SUM(F27:I27) -> 0 | P27: =SUM(K27:O27) -> 0 | Q27: =J27+P27 -> 0 | R27: =SUM(B27:O27) -> 0
E28: =SUM(B28:D28) -> 0 | J28: =SUM(F28:I28) -> 0 | P28: =SUM(K28:O28) -> 0 | Q28: =J28+P28 -> 0 | R28: =SUM(B28:O28) -> 0
E29: =SUM(B29:D29) -> 0 | J29: =SUM(F29:I29) -> 0 | P29: =SUM(K29:O29) -> 0 | Q29: =J29+P29 -> 0 | R29: =SUM(B29:O29) -> 0
E30: =SUM(B30:D30) -> 0 | J30: =SUM(F30:I30) -> 0 | P30: =SUM(K30:O30) -> 0 | Q30: =J30+P30 -> 0 | R30: =SUM(B30:O30) -> 0
E31: =SUM(B31:D31) -> 0 | J31: =SUM(F31:I31) -> 0 | P31: =SUM(K31:O31) -> 0 | Q31: =J31+P31 -> 0 | R31: =SUM(B31:O31) -> 0
E32: =SUM(B32:D32) -> 0 | J32: =SUM(F32:I32) -> 0 | P32: =SUM(K32:O32) -> 0 | Q32: =J32+P32 -> 0 | R32: =SUM(B32:O32) -> 0
... E50: =SUM(B50:D50) -> 0 | J50: =SUM(F50:I50) -> 0 | P50: =SUM(K50:O50) -> 0 | Q50: =J50+P50 -> 0 | R50: =SUM(B50:O50) -> 0
A51: TOTAL | B51: =SUM(B20:B50) -> 1 | C51: =SUM(C20:C50) -> 2 | D51: =SUM(D20:D50) -> 3 | E51: =SUM(E20:E50) -> 6 | F51: =SUM(F20:F50) -> 4 | G51: =SUM(G20:G50) -> 5 | H51: =SUM(H20:H50) -> 6 | I51: =SUM(I20:I50) -> 7 | ... R51: =SUM(R20:R50) -> 76
A54: INDICADORES DE DESTINACION
B57: 27 | C57: 29 | D57: 29 | E57: 30 | F57: 31 | G57: 32 | J57: 33
A58: AÑO | B58: DESTINACIÓN DE RESIDUOS | G58: TOTAL | I58: MES | K58: INDICADORES DE DESTINACIÓN % | O58: INDICADOR TOTAL (%)
B59: DESACTIVACION (KG/AÑO) | C59: RECICLAJE (KG/AÑO) | D59: INCINERACIÓN (KG/AÑO) | E59: RELLENO SANITARIO (KG/AÑO) | F59: OTROS SISTEMAS DE DISPOSICION FINAL | J59: IDD | K59: IDR | L59: IDI | M59: IDRS | N59: IDOS
A60: Enero | B60: =+ENERO!B60 -> 0 | C60: =+ENERO!C60 -> 0 | D60: =+ENERO!D60 -> 0 | E60: =+ENERO!E60 -> 0 | F60: =+ENERO!F60 -> 0 | G60: =SUM(B60:F60) -> 0 | I60: Enero | J60: =(B60/ENERO!$R$51)*100 -> 0 | K60: =(C60/ENERO!$R$51)*100 -> 0 | L60: =(D60/ENERO!$R$51)*100 -> 0 | M60: =(E60/ENERO!$R$51)*100 -> 0 | N60: =(F60/ENERO!$R$51)*100 -> 0 | O60: =SUM(J60:N60)/100 -> 0
A61: Febrero | B61: =+FEBRERO!B61 -> 0 | C61: =+FEBRERO!C61 -> 0 | D61: =+FEBRERO!D61 -> 0 | E61: =+FEBRERO!E61 -> 0 | F61: =+FEBRERO!F61 -> 0 | G61: =SUM(B61:F61) -> 0 | I61: Febrero | J61: =(B61/FEBRERO!$R$51)*100 -> 0 | K61: =(C61/FEBRERO!$R$51)*100 -> 0 | L61: =(D61/FEBRERO!$R$51)*100 -> 0 | M61: =(E61/FEBRERO!$R$51)*100 -> 0 | N61: =(F61/FEBRERO!$R$51)*100 -> 0 | O61: =SUM(J61:N61)/100 -> 0
A62: Marzo | B62: =+MARZO!B62 -> 0 | C62: =+MARZO!C62 -> 0 | D62: =+MARZO!D62 -> 0 | E62: =+MARZO!E62 -> 0 | F62: =+MARZO!F62 -> 0 | G62: =SUM(B62:F62) -> 0 | I62: Marzo | J62: =(B62/MARZO!$R$51)*100 -> 0 | K62: =(C62/MARZO!$R$51)*100 -> 0 | L62: =(D62/MARZO!$R$51)*100 -> 0 | M62: =(E62/MARZO!$R$51)*100 -> 0 | N62: =(F62/MARZO!$R$51)*100 -> 0 | O62: =SUM(J62:N62)/100 -> 0
A63: Abril | G63: =SUM(B63:F63) -> 0 | I63: Abril | J63: =(B63/$R$51)*100 -> 0 | K63: =(C63/$R$51)*100 -> 0 | L63: =(D63/$R$51)*100 -> 0 | M63: =(E63/$R$51)*100 -> 0 | N63: =(F63/$R$51)*100 -> 0 | O63: =SUM(J63:N63)/100 -> 0
I66: IDD: Indicador de destinacion desactivacion de alta eficiencia
I67: IDR: Indicador de destinacion para reciclaje
I68: IDI: Indicador de destinacion para incineracion
I69: IDRS: Indicador de destinacion para relleno sanitario

Sheet MAYO
D1: FORMATO REGISTRO ANUAL DE GENERACION DE RESIDUOS GENERADOS EN LA ATENCION EN SALUD Y OTRAS ACTIVIDADES
A7: 1. Nombre de la institucion: | K7: 6. Correo Electronico
A8: 2. Ciudad | K8: 7. Responsable del diligenciamiento
A9: 3. Departamento | K9: 8. Cargo
A10: 4. Direccion | K10: 9. Mes:
A11: 5. Telefono
A14: CONSOLIDACION RESIDUOS POR DTS
B16: 10 | C16: 11 | D16: 12 | E16: 13 | F16: 14 | G16: 15 | H16: 16 | I16: 17 | J16: 18 | K16: 19 | L16: 20 | M16: 21 | N16: 22 | O16: 23 | P16: 24 | Q16: 25 | R16: 26
A17: DÍA | B17: RESIDUOS NO PELIGROS | E17: Subtotal Residuos no peligrosos | F17: RESIDUOS PELIGROSOS | Q17: Subtotal Residuos Peligrosos | R17: TOTAL
F18: INFECCIOSO O RIESGO BIOLOGICO | J18: Subtotal residuos de riesgo biologico o infeccioso | K18: OTROS RESIDUOS CON LAS SIGUIENTES CARACTERISTICAS | P18: Subtotal otros residuos
B19: BIODEGRADABLES (KG/AÑO) | C19: RECICLABLES (KG/AÑO) | D19: ORDINARIOS (KG/AÑO) | F19: BIOSANITARIOS (KG/AÑO) | G19: ANATOMOPATOLOGICOS (KG/AÑO) | H19: CORTOPUNZANTES (KG/AÑO) | I19: ANIMALES (KG/AÑO) | K19: CORROSIVA (KG/AÑO) | L19: EXPLOSIVO (KG/AÑO) | M19: TOXICO (KG/AÑO) | N19: INFLAMABLE (KG/AÑO) | O19: REACTIVO (KG/AÑO)
B20: 1 | C20: 2 | D20: 3 | E20: =SUM(B20:D20) -> 6 | F20: 4 | G20: 5 | H20: 6 | I20: 7 | J20: =SUM(F20:I20) -> 22 | K20: 8 | L20: 9 | M20: 0 | N20: 1 | O20: 2 | P20: =SUM(K20:O20) -> 20 | Q20: =J20+P20 -> 42 | R20: =SUM(B20:O20) -> 76
E21: =SUM(B21:D21) -> 0 | J21: =SUM(F21:I21) -> 0 | P21: =SUM(K21:O21) -> 0 | Q21: =J21+P21 -> 0 | R21: =SUM(B21:O21) -> 0
E22: =SUM(B22:D22) -> 0 | J22: =SUM(F22:I22) -> 0 | P22: =SUM(K22:O22) -> 0 | Q22: =J22+P22 -> 0 | R22: =SUM(B22:O22) -> 0
E23: =SUM(B23:D23) -> 0 | J23: =SUM(F23:I23) -> 0 | P23: =SUM(K23:O23) -> 0 | Q23: =J23+P23 -> 0 | R23: =SUM(B23:O23) -> 0
E24: =SUM(B24:D24) -> 0 | J24: =SUM(F24:I24) -> 0 | P24: =SUM(K24:O24) -> 0 | Q24: =J24+P24 -> 0 | R24: =SUM(B24:O24) -> 0
E25: =SUM(B25:D25) -> 0 | J25: =SUM(F25:I25) -> 0 | P25: =SUM(K25:O25) -> 0 | Q25: =J25+P25 -> 0 | R25: =SUM(B25:O25) -> 0
E26: =SUM(B26:D26) -> 0 | J26: =SUM(F26:I26) -> 0 | P26: =SUM(K26:O26) -> 0 | Q26: =J26+P26 -> 0 | R26: =SUM(B26:O26) -> 0
E27: =SUM(B27:D27) -> 0 | J27: =SUM(F27:I27) -> 0 | P27: =SUM(K27:O27) -> 0 | Q27: =J27+P27 -> 0 | R27: =SUM(B27:O27) -> 0
E28: =SUM(B28:D28) -> 0 | J28: =SUM(F28:I28) -> 0 | P28: =SUM(K28:O28) -> 0 | Q28: =J28+P28 -> 0 | R28: =SUM(B28:O28) -> 0
E29: =SUM(B29:D29) -> 0 | J29: =SUM(F29:I29) -> 0 | P29: =SUM(K29:O29) -> 0 | Q29: =J29+P29 -> 0 | R29: =SUM(B29:O29) -> 0
E30: =SUM(B30:D30) -> 0 | J30: =SUM(F30:I30) -> 0 | P30: =SUM(K30:O30) -> 0 | Q30: =J30+P30 -> 0 | R30: =SUM(B30:O30) -> 0
E31: =SUM(B31:D31) -> 0 | J31: =SUM(F31:I31) -> 0 | P31: =SUM(K31:O31) -> 0 | Q31: =J31+P31 -> 0 | R31: =SUM(B31:O31) -> 0
E32: =SUM(B32:D32) -> 0 | J32: =SUM(F32:I32) -> 0 | P32: =SUM(K32:O32) -> 0 | Q32: =J32+P32 -> 0 | R32: =SUM(B32:O32) -> 0
... E50: =SUM(B50:D50) -> 0 | J50: =SUM(F50:I50) -> 0 | P50: =SUM(K50:O50) -> 0 | Q50: =J50+P50 -> 0 | R50: =SUM(B50:O50) -> 0
A51: TOTAL | B51: =SUM(B20:B50) -> 1 | C51: =SUM(C20:C50) -> 2 | D51: =SUM(D20:D50) -> 3 | E51: =SUM(E20:E50) -> 6 | F51: =SUM(F20:F50) -> 4 | G51: =SUM(G20:G50) -> 5 | H51: =SUM(H20:H50) -> 6 | I51: =SUM(I20:I50) -> 7 | ... R51: =SUM(R20:R50) -> 76
A54: INDICADORES DE DESTINACION
B57: 27 | C57: 29 | D57: 29 | E57: 30 | F57: 31 | G57: 32 | J57: 33
A58: AÑO | B58: DESTINACIÓN DE RESIDUOS | G58: TOTAL | I58: MES | K58: INDICADORES DE DESTINACIÓN % | O58: INDICADOR TOTAL (%)
B59: DESACTIVACION (KG/AÑO) | C59: RECICLAJE (KG/AÑO) | D59: INCINERACIÓN (KG/AÑO) | E59: RELLENO SANITARIO (KG/AÑO) | F59: OTROS SISTEMAS DE DISPOSICION FINAL | J59: IDD | K59: IDR | L59: IDI | M59: IDRS | N59: IDOS
A60: Enero | B60: =+ENERO!B60 -> 0 | C60: =+ENERO!C60 -> 0 | D60: =+ENERO!D60 -> 0 | E60: =+ENERO!E60 -> 0 | F60: =+ENERO!F60 -> 0 | G60: =SUM(B60:F60) -> 0 | I60: Enero | J60: =(B60/ENERO!$R$51)*100 -> 0 | K60: =(C60/ENERO!$R$51)*100 -> 0 | L60: =(D60/ENERO!$R$51)*100 -> 0 | M60: =(E60/ENERO!$R$51)*100 -> 0 | N60: =(F60/ENERO!$R$51)*100 -> 0 | O60: =SUM(J60:N60)/100 -> 0
A61: Febrero | B61: =+FEBRERO!B61 -> 0 | C61: =+FEBRERO!C61 -> 0 | D61: =+FEBRERO!D61 -> 0 | E61: =+FEBRERO!E61 -> 0 | F61: =+FEBRERO!F61 -> 0 | G61: =SUM(B61:F61) -> 0 | I61: Febrero | J61: =(B61/FEBRERO!$R$51)*100 -> 0 | K61: =(C61/FEBRERO!$R$51)*100 -> 0 | L61: =(D61/FEBRERO!$R$51)*100 -> 0 | M61: =(E61/FEBRERO!$R$51)*100 -> 0 | N61: =(F61/FEBRERO!$R$51)*100 -> 0 | O61: =SUM(J61:N61)/100 -> 0
A62: Marzo | B62: =+MARZO!B62 -> 0 | C62: =+MARZO!C62 -> 0 | D62: =+MARZO!D62 -> 0 | E62: =+MARZO!E62 -> 0 | F62: =+MARZO!F62 -> 0 | G62: =SUM(B62:F62) -> 0 | I62: Marzo | J62: =(B62/MARZO!$R$51)*100 -> 0 | K62: =(C62/MARZO!$R$51)*100 -> 0 | L62: =(D62/MARZO!$R$51)*100 -> 0 | M62: =(E62/MARZO!$R$51)*100 -> 0 | N62: =(F62/MARZO!$R$51)*100 -> 0 | O62: =SUM(J62:N62)/100 -> 0
A63: Abril | B63: =+ABRIL!B63 -> 0 | C63: =+ABRIL!C63 -> 0 | D63: =+ABRIL!D63 -> 0 | E63: =+ABRIL!E63 -> 0 | F63: =+ABRIL!F63 -> 0 | G63: =SUM(B63:F63) -> 0 | I63: Abril | J63: =(B63/ABRIL!$R$51)*100 -> 0 | K63: =(C63/ABRIL!$R$51)*100 -> 0 | L63: =(D63/ABRIL!$R$51)*100 -> 0 | M63: =(E63/ABRIL!$R$51)*100 -> 0 | N63: =(F63/ABRIL!$R$51)*100 -> 0 | O63: =SUM(J63:N63)/100 -> 0
A64: Mayo | G64: =SUM(B64:F64) -> 0 | I64: Mayo | J64: =(B64/$R$51)*100 -> 0 | K64: =(C64/$R$51)*100 -> 0 | L64: =(D64/$R$51)*100 -> 0 | M64: =(E64/$R$51)*100 -> 0 | N64: =(F64/$R$51)*100 -> 0 | O64: =SUM(J64:N64)/100 -> 0
I67: IDD: Indicador de destinacion desactivacion de alta eficiencia
I68: IDR: Indicador de destinacion para reciclaje
I69: IDI: Indicador de destinacion para incineracion
I70: IDRS: Indicador de destinacion para relleno sanitario

Sheet JUNIO
D1: FORMATO REGISTRO ANUAL DE GENERACION DE RESIDUOS GENERADOS EN LA ATENCION EN SALUD Y OTRAS ACTIVIDADES
A7: 1. Nombre de la institucion: | K7: 6. Correo Electronico
A8: 2. Ciudad | K8: 7. Responsable del diligenciamiento
A9: 3. Departamento | K9: 8. Cargo
A10: 4. Direccion | K10: 9. Mes:
A11: 5. Telefono
A14: CONSOLIDACION RESIDUOS POR DTS
B16: 10 | C16: 11 | D16: 12 | E16: 13 | F16: 14 | G16: 15 | H16: 16 | I16: 17 | J16: 18 | K16: 19 | L16: 20 | M16: 21 | N16: 22 | O16: 23 | P16: 24 | Q16: 25 | R16: 26
A17: DÍA | B17: RESIDUOS NO PELIGROS | E17: Subtotal Residuos no peligrosos | F17: RESIDUOS PELIGROSOS | Q17: Subtotal Residuos Peligrosos | R17: TOTAL
F18: INFECCIOSO O RIESGO BIOLOGICO | J18: Subtotal residuos de riesgo biologico o infeccioso | K18: OTROS RESIDUOS CON LAS SIGUIENTES CARACTERISTICAS | P18: Subtotal otros residuos
B19: BIODEGRADABLES (KG/AÑO) | C19: RECICLABLES (KG/AÑO) | D19: ORDINARIOS (KG/AÑO) | F19: BIOSANITARIOS (KG/AÑO) | G19: ANATOMOPATOLOGICOS (KG/AÑO) | H19: CORTOPUNZANTES (KG/AÑO) | I19: ANIMALES (KG/AÑO) | K19: CORROSIVA (KG/AÑO) | L19: EXPLOSIVO (KG/AÑO) | M19: TOXICO (KG/AÑO) | N19: INFLAMABLE (KG/AÑO) | O19: REACTIVO (KG/AÑO)
B20: 1 | C20: 2 | D20: 3 | E20: =SUM(B20:D20) -> 6 | F20: 4 | G20: 5 | H20: 6 | I20: 7 | J20: =SUM(F20:I20) -> 22 | K20: 8 | L20: 9 | M20: 0 | N20: 1 | O20: 2 | P20: =SUM(K20:O20) -> 20 | Q20: =J20+P20 -> 42 | R20: =SUM(B20:O20) -> 76
E21: =SUM(B21:D21) -> 0 | J21: =SUM(F21:I21) -> 0 | P21: =SUM(K21:O21) -> 0 | Q21: =J21+P21 -> 0 | R21: =SUM(B21:O21) -> 0
E22: =SUM(B22:D22) -> 0 | J22: =SUM(F22:I22) -> 0 | P22: =SUM(K22:O22) -> 0 | Q22: =J22+P22 -> 0 | R22: =SUM(B22:O22) -> 0
E23: =SUM(B23:D23) -> 0 | J23: =SUM(F23:I23) -> 0 | P23: =SUM(K23:O23) -> 0 | Q23: =J23+P23 -> 0 | R23: =SUM(B23:O23) -> 0
E24: =SUM(B24:D24) -> 0 | J24: =SUM(F24:I24) -> 0 | P24: =SUM(K24:O24) -> 0 | Q24: =J24+P24 -> 0 | R24: =SUM(B24:O24) -> 0
E25: =SUM(B25:D25) -> 0 | J25: =SUM(F25:I25) -> 0 | P25: =SUM(K25:O25) -> 0 | Q25: =J25+P25 -> 0 | R25: =SUM(B25:O25) -> 0
E26: =SUM(B26:D26) -> 0 | J26: =SUM(F26:I26) -> 0 | P26: =SUM(K26:O26) -> 0 | Q26: =J26+P26 -> 0 | R26: =SUM(B26:O26) -> 0
E27: =SUM(B27:D27) -> 0 | J27: =SUM(F27:I27) -> 0 | P27: =SUM(K27:O27) -> 0 | Q27: =J27+P27 -> 0 | R27: =SUM(B27:O27) -> 0
E28: =SUM(B28:D28) -> 0 | J28: =SUM(F28:I28) -> 0 | P28: =SUM(K28:O28) -> 0 | Q28: =J28+P28 -> 0 | R28: =SUM(B28:O28) -> 0
E29: =SUM(B29:D29) -> 0 | J29: =SUM(F29:I29) -> 0 | P29: =SUM(K29:O29) -> 0 | Q29: =J29+P29 -> 0 | R29: =SUM(B29:O29) -> 0
E30: =SUM(B30:D30) -> 0 | J30: =SUM(F30:I30) -> 0 | P30: =SUM(K30:O30) -> 0 | Q30: =J30+P30 -> 0 | R30: =SUM(B30:O30) -> 0
E31: =SUM(B31:D31) -> 0 | J31: =SUM(F31:I31) -> 0 | P31: =SUM(K31:O31) -> 0 | Q31: =J31+P31 -> 0 | R31: =SUM(B31:O31) -> 0
E32: =SUM(B32:D32) -> 0 | J32: =SUM(F32:I32) -> 0 | P32: =SUM(K32:O32) -> 0 | Q32: =J32+P32 -> 0 | R32: =SUM(B32:O32) -> 0
... E50: =SUM(B50:D50) -> 0 | J50: =SUM(F50:I50) -> 0 | P50: =SUM(K50:O50) -> 0 | Q50: =J50+P50 -> 0 | R50: =SUM(B50:O50) -> 0
A51: TOTAL | B51: =SUM(B20:B50) -> 1 | C51: =SUM(C20:C50) -> 2 | D51: =SUM(D20:D50) -> 3 | E51: =SUM(E20:E50) -> 6 | F51: =SUM(F20:F50) -> 4 | G51: =SUM(G20:G50) -> 5 | H51: =SUM(H20:H50) -> 6 | I51: =SUM(I20:I50) -> 7 | ... R51: =SUM(R20:R50) -> 76
A54: INDICADORES DE DESTINACION
B57: 27 | C57: 29 | D57: 29 | E57: 30 | F57: 31 | G57: 32 | J57: 33
A58: AÑO | B58: DESTINACIÓN DE RESIDUOS | G58: TOTAL | I58: MES | K58: INDICADORES DE DESTINACIÓN % | O58: INDICADOR TOTAL (%)
B59: DESACTIVACION (KG/AÑO) | C59: RECICLAJE (KG/AÑO) | D59: INCINERACIÓN (KG/AÑO) | E59: RELLENO SANITARIO (KG/AÑO) | F59: OTROS SISTEMAS DE DISPOSICION FINAL | J59: IDD | K59: IDR | L59: IDI | M59: IDRS | N59: IDOS
A60: Enero | B60: =+ENERO!B60 -> 0 | C60: =+ENERO!C60 -> 0 | D60: =+ENERO!D60 -> 0 | E60: =+ENERO!E60 -> 0 | F60: =+ENERO!F60 -> 0 | G60: =SUM(B60:F60) -> 0 | I60: Enero | J60: =(B60/ENERO!$R$51)*100 -> 0 | K60: =(C60/ENERO!$R$51)*100 -> 0 | L60: =(D60/ENERO!$R$51)*100 -> 0 | M60: =(E60/ENERO!$R$51)*100 -> 0 | N60: =(F60/ENERO!$R$51)*100 -> 0 | O60: =SUM(J60:N60)/100 -> 0
A61: Febrero | B61: =+FEBRERO!B61 -> 0 | C61: =+FEBRERO!C61 -> 0 | D61: =+FEBRERO!D61 -> 0 | E61: =+FEBRERO!E61 -> 0 | F61: =+FEBRERO!F61 -> 0 | G61: =SUM(B61:F61) -> 0 | I61: Febrero | J61: =(B61/FEBRERO!$R$51)*100 -> 0 | K61: =(C61/FEBRERO!$R$51)*100 -> 0 | L61: =(D61/FEBRERO!$R$51)*100 -> 0 | M61: =(E61/FEBRERO!$R$51)*100 -> 0 | N61: =(F61/FEBRERO!$R$51)*100 -> 0 | O61: =SUM(J61:N61)/100 -> 0
A62: Marzo | B62: =+MARZO!B62 -> 0 | C62: =+MARZO!C62 -> 0 | D62: =+MARZO!D62 -> 0 | E62: =+MARZO!E62 -> 0 | F62: =+MARZO!F62 -> 0 | G62: =SUM(B62:F62) -> 0 | I62: Marzo | J62: =(B62/MARZO!$R$51)*100 -> 0 | K62: =(C62/MARZO!$R$51)*100 -> 0 | L62: =(D62/MARZO!$R$51)*100 -> 0 | M62: =(E62/MARZO!$R$51)*100 -> 0 | N62: =(F62/MARZO!$R$51)*100 -> 0 | O62: =SUM(J62:N62)/100 -> 0
A63: Abril | B63: =+ABRIL!B63 -> 0 | C63: =+ABRIL!C63 -> 0 | D63: =+ABRIL!D63 -> 0 | E63: =+ABRIL!E63 -> 0 | F63: =+ABRIL!F63 -> 0 | G63: =SUM(B63:F63) -> 0 | I63: Abril | J63: =(B63/ABRIL!$R$51)*100 -> 0 | K63: =(C63/ABRIL!$R$51)*100 -> 0 | L63: =(D63/ABRIL!$R$51)*100 -> 0 | M63: =(E63/ABRIL!$R$51)*100 -> 0 | N63: =(F63/ABRIL!$R$51)*100 -> 0 | O63: =SUM(J63:N63)/100 -> 0
A64: Mayo | B64: =+MAYO!B64 -> 0 | C64: =+MAYO!C64 -> 0 | D64: =+MAYO!D64 -> 0 | E64: =+MAYO!E64 -> 0 | F64: =+MAYO!F64 -> 0 | G64: =SUM(B64:F64) -> 0 | I64: Mayo | J64: =(B64/MAYO!$R$51)*100 -> 0 | K64: =(C64/MAYO!$R$51)*100 -> 0 | L64: =(D64/MAYO!$R$51)*100 -> 0 | M64: =(E64/MAYO!$R$51)*100 -> 0 | N64: =(F64/MAYO!$R$51)*100 -> 0 | O64: =SUM(J64:N64)/100 -> 0
A65: Junio | G65: =SUM(B65:F65) -> 0 | I65: Junio | J65: =(B65/$R$51)*100 -> 0 | K65: =(C65/$R$51)*100 -> 0 | L65: =(D65/$R$51)*100 -> 0 | M65: =(E65/$R$51)*100 -> 0 | N65: =(F65/$R$51)*100 -> 0 | O65: =SUM(J65:N65)/100 -> 0
I68: IDD: Indicador de destinacion desactivacion de alta eficiencia
I69: IDR: Indicador de destinacion para reciclaje
I70: IDI: Indicador de destinacion para incineracion
I71: IDRS: Indicador de destinacion para relleno sanitario

Sheet JULIO
D1: FORMATO REGISTRO ANUAL DE GENERACION DE RESIDUOS GENERADOS EN LA ATENCION EN SALUD Y OTRAS ACTIVIDADES
A7: 1. Nombre de la institucion: | K7: 6. Correo Electronico
A8: 2. Ciudad | K8: 7. Responsable del diligenciamiento
A9: 3. Departamento | K9: 8. Cargo
A10: 4. Direccion | K10: 9. Mes:
A11: 5. Telefono
A14: CONSOLIDACION RESIDUOS POR DTS
B16: 10 | C16: 11 | D16: 12 | E16: 13 | F16: 14 | G16: 15 | H16: 16 | I16: 17 | J16: 18 | K16: 19 | L16: 20 | M16: 21 | N16: 22 | O16: 23 | P16: 24 | Q16: 25 | R16: 26
A17: DÍA | B17: RESIDUOS NO PELIGROS | E17: Subtotal Residuos no peligrosos | F17: RESIDUOS PELIGROSOS | Q17: Subtotal Residuos Peligrosos | R17: TOTAL
F18: INFECCIOSO O RIESGO BIOLOGICO | J18: Subtotal residuos de riesgo biologico o infeccioso | K18: OTROS RESIDUOS CON LAS SIGUIENTES CARACTERISTICAS | P18: Subtotal otros residuos
B19: BIODEGRADABLES (KG/AÑO) | C19: RECICLABLES (KG/AÑO) | D19: ORDINARIOS (KG/AÑO) | F19: BIOSANITARIOS (KG/AÑO) | G19: ANATOMOPATOLOGICOS (KG/AÑO) | H19: CORTOPUNZANTES (KG/AÑO) | I19: ANIMALES (KG/AÑO) | K19: CORROSIVA (KG/AÑO) | L19: EXPLOSIVO (KG/AÑO) | M19: TOXICO (KG/AÑO) | N19: INFLAMABLE (KG/AÑO) | O19: REACTIVO (KG/AÑO)
B20: 1 | C20: 2 | D20: 3 | E20: =SUM(B20:D20) -> 6 | F20: 4 | G20: 5 | H20: 6 | I20: 7 | J20: =SUM(F20:I20) -> 22 | K20: 8 | L20: 9 | M20: 0 | N20: 1 | O20: 2 | P20: =SUM(K20:O20) -> 20 | Q20: =J20+P20 -> 42 | R20: =SUM(B20:O20) -> 76
E21: =SUM(B21:D21) -> 0 | J21: =SUM(F21:I21) -> 0 | P21: =SUM(K21:O21) -> 0 | Q21: =J21+P21 -> 0 | R21: =SUM(B21:O21) -> 0
E22: =SUM(B22:D22) -> 0 | J22: =SUM(F22:I22) -> 0 | P22: =SUM(K22:O22) -> 0 | Q22: =J22+P22 -> 0 | R22: =SUM(B22:O22) -> 0
E23: =SUM(B23:D23) -> 0 | J23: =SUM(F23:I23) -> 0 | P23: =SUM(K23:O23) -> 0 | Q23: =J23+P23 -> 0 | R23: =SUM(B23:O23) -> 0
E24: =SUM(B24:D24) -> 0 | J24: =SUM(F24:I24) -> 0 | P24: =SUM(K24:O24) -> 0 | Q24: =J24+P24 -> 0 | R24: =SUM(B24:O24) -> 0
E25: =SUM(B25:D25) -> 0 | J25: =SUM(F25:I25) -> 0 | P25: =SUM(K25:O25) -> 0 | Q25: =J25+P25 -> 0 | R25: =SUM(B25:O25) -> 0
E26: =SUM(B26:D26) -> 0 | J26: =SUM(F26:I26) -> 0 | P26: =SUM(K26:O26) -> 0 | Q26: =J26+P26 -> 0 | R26: =SUM(B26:O26) -> 0
E27: =SUM(B27:D27) -> 0 | J27: =SUM(F27:I27) -> 0 | P27: =SUM(K27:O27) -> 0 | Q27: =J27+P27 -> 0 | R27: =SUM(B27:O27) -> 0
E28: =SUM(B28:D28) -> 0 | J28: =SUM(F28:I28) -> 0 | P28: =SUM(K28:O28) -> 0 | Q28: =J28+P28 -> 0 | R28: =SUM(B28:O28) -> 0
E29: =SUM(B29:D29) -> 0 | J29: =SUM(F29:I29) -> 0 | P29: =SUM(K29:O29) -> 0 | Q29: =J29+P29 -> 0 | R29: =SUM(B29:O29) -> 0
E30: =SUM(B30:D30) -> 0 | J30: =SUM(F30:I30) -> 0 | P30: =SUM(K30:O30) -> 0 | Q30: =J30+P30 -> 0 | R30: =SUM(B30:O30) -> 0
E31: =SUM(B31:D31) -> 0 | J31: =SUM(F31:I31) -> 0 | P31: =SUM(K31:O31) -> 0 | Q31: =J31+P31 -> 0 | R31: =SUM(B31:O31) -> 0
E32: =SUM(B32:D32) -> 0 | J32: =SUM(F32:I32) -> 0 | P32: =SUM(K32:O32) -> 0 | Q32: =J32+P32 -> 0 | R32: =SUM(B32:O32) -> 0
... E50: =SUM(B50:D50) -> 0 | J50: =SUM(F50:I50) -> 0 | P50: =SUM(K50:O50) -> 0 | Q50: =J50+P50 -> 0 | R50: =SUM(B50:O50) -> 0
A51: TOTAL | B51: =SUM(B20:B50) -> 1 | C51: =SUM(C20:C50) -> 2 | D51: =SUM(D20:D50) -> 3 | E51: =SUM(E20:E50) -> 6 | F51: =SUM(F20:F50) -> 4 | G51: =SUM(G20:G50) -> 5 | H51: =SUM(H20:H50) -> 6 | I51: =SUM(I20:I50) -> 7 | ... R51: =SUM(R20:R50) -> 76
A54: INDICADORES DE DESTINACION
B57: 27 | C57: 29 | D57: 29 | E57: 30 | F57: 31 | G57: 32 | J57: 33
A58: AÑO | B58: DESTINACIÓN DE RESIDUOS | G58: TOTAL | I58: MES | K58: INDICADORES DE DESTINACIÓN % | O58: INDICADOR TOTAL (%)
B59: DESACTIVACION (KG/AÑO) | C59: RECICLAJE (KG/AÑO) | D59: INCINERACIÓN (KG/AÑO) | E59: RELLENO SANITARIO (KG/AÑO) | F59: OTROS SISTEMAS DE DISPOSICION FINAL | J59: IDD | K59: IDR | L59: IDI | M59: IDRS | N59: IDOS
A60: Enero | B60: =+ENERO!B60 -> 0 | C60: =+ENERO!C60 -> 0 | D60: =+ENERO!D60 -> 0 | E60: =+ENERO!E60 -> 0 | F60: =+ENERO!F60 -> 0 | G60: =SUM(B60:F60) -> 0 | I60: Enero | J60: =(B60/ENERO!$R$51)*100 -> 0 | K60: =(C60/ENERO!$R$51)*100 -> 0 | L60: =(D60/ENERO!$R$51)*100 -> 0 | M60: =(E60/ENERO!$R$51)*100 -> 0 | N60: =(F60/ENERO!$R$51)*100 -> 0 | O60: =SUM(J60:N60)/100 -> 0
A61: Febrero | B61: =+FEBRERO!B61 -> 0 | C61: =+FEBRERO!C61 -> 0 | D61: =+FEBRERO!D61 -> 0 | E61: =+FEBRERO!E61 -> 0 | F61: =+FEBRERO!F61 -> 0 | G61: =SUM(B61:F61) -> 0 | I61: Febrero | J61: =(B61/FEBRERO!$R$51)*100 -> 0 | K61: =(C61/FEBRERO!$R$51)*100 -> 0 | L61: =(D61/FEBRERO!$R$51)*100 -> 0 | M61: =(E61/FEBRERO!$R$51)*100 -> 0 | N61: =(F61/FEBRERO!$R$51)*100 -> 0 | O61: =SUM(J61:N61)/100 -> 0
A62: Marzo | B62: =+MARZO!B62 -> 0 | C62: =+MARZO!C62 -> 0 | D62: =+MARZO!D62 -> 0 | E62: =+MARZO!E62 -> 0 | F62: =+MARZO!F62 -> 0 | G62: =SUM(B62:F62) -> 0 | I62: Marzo | J62: =(B62/MARZO!$R$51)*100 -> 0 | K62: =(C62/MARZO!$R$51)*100 -> 0 | L62: =(D62/MARZO!$R$51)*100 -> 0 | M62: =(E62/MARZO!$R$51)*100 -> 0 | N62: =(F62/MARZO!$R$51)*100 -> 0 | O62: =SUM(J62:N62)/100 -> 0
A63: Abril | B63: =+ABRIL!B63 -> 0 | C63: =+ABRIL!C63 -> 0 | D63: =+ABRIL!D63 -> 0 | E63: =+ABRIL!E63 -> 0 | F63: =+ABRIL!F63 -> 0 | G63: =SUM(B63:F63) -> 0 | I63: Abril | J63: =(B63/ABRIL!$R$51)*100 -> 0 | K63: =(C63/ABRIL!$R$51)*100 -> 0 | L63: =(D63/ABRIL!$R$51)*100 -> 0 | M63: =(E63/ABRIL!$R$51)*100 -> 0 | N63: =(F63/ABRIL!$R$51)*100 -> 0 | O63: =SUM(J63:N63)/100 -> 0
A64: Mayo | B64: =+MAYO!B64 -> 0 | C64: =+MAYO!C64 -> 0 | D64: =+MAYO!D64 -> 0 | E64: =+MAYO!E64 -> 0 | F64: =+MAYO!F64 -> 0 | G64: =SUM(B64:F64) -> 0 | I64: Mayo | J64: =(B64/MAYO!$R$51)*100 -> 0 | K64: =(C64/MAYO!$R$51)*100 -> 0 | L64: =(D64/MAYO!$R$51)*100 -> 0 | M64: =(E64/MAYO!$R$51)*100 -> 0 | N64: =(F64/MAYO!$R$51)*100 -> 0 | O64: =SUM(J64:N64)/100 -> 0
A65: Junio | B65: =+JUNIO!B65 -> 0 | C65: =+JUNIO!C65 -> 0 | D65: =+JUNIO!D65 -> 0 | E65: =+JUNIO!E65 -> 0 | F65: =+JUNIO!F65 -> 0 | G65: =SUM(B65:F65) -> 0 | I65: Junio | J65: =(B65/JUNIO!$R$51)*100 -> 0 | K65: =(C65/JUNIO!$R$51)*100 -> 0 | L65: =(D65/JUNIO!$R$51)*100 -> 0 | M65: =(E65/JUNIO!$R$51)*100 -> 0 | N65: =(F65/JUNIO!$R$51)*100 -> 0 | O65: =SUM(J65:N65)/100 -> 0
A66: Julio | G66: =SUM(B66:F66) -> 0 | I66: Julio | J66: =(B66/$R$51)*100 -> 0 | K66: =(C66/$R$51)*100 -> 0 | L66: =(D66/$R$51)*100 -> 0 | M66: =(E66/$R$51)*100 -> 0 | N66: =(F66/$R$51)*100 -> 0 | O66: =SUM(J66:N66)/100 -> 0
I69: IDD: Indicador de destinacion desactivacion de alta eficiencia
I70: IDR: Indicador de destinacion para reciclaje
I71: IDI: Indicador de destinacion para incineracion
...

Sheet AGOSTO
D1: FORMATO REGISTRO ANUAL DE GENERACION DE RESIDUOS GENERADOS EN LA ATENCION EN SALUD Y OTRAS ACTIVIDADES
A7: 1. Nombre de la institucion: | K7: 6. Correo Electronico
A8: 2. Ciudad | K8: 7. Responsable del diligenciamiento
A9: 3. Departamento | K9: 8. Cargo
A10: 4. Direccion | K10: 9. Mes:
A11: 5. Telefono
A14: CONSOLIDACION RESIDUOS POR DTS
B16: 10 | C16: 11 | D16: 12 | E16: 13 | F16: 14 | G16: 15 | H16: 16 | I16: 17 | J16: 18 | K16: 19 | L16: 20 | M16: 21 | N16: 22 | O16: 23 | P16: 24 | Q16: 25 | R16: 26
A17: DÍA | B17: RESIDUOS NO PELIGROS | E17: Subtotal Residuos no peligrosos | F17: RESIDUOS PELIGROSOS | Q17: Subtotal Residuos Peligrosos | R17: TOTAL
F18: INFECCIOSO O RIESGO BIOLOGICO | J18: Subtotal residuos de riesgo biologico o infeccioso | K18: OTROS RESIDUOS CON LAS SIGUIENTES CARACTERISTICAS | P18: Subtotal otros residuos
B19: BIODEGRADABLES (KG/AÑO) | C19: RECICLABLES (KG/AÑO) | D19: ORDINARIOS (KG/AÑO) | F19: BIOSANITARIOS (KG/AÑO) | G19: ANATOMOPATOLOGICOS (KG/AÑO) | H19: CORTOPUNZANTES (KG/AÑO) | I19: ANIMALES (KG/AÑO) | K19: CORROSIVA (KG/AÑO) | L19: EXPLOSIVO (KG/AÑO) | M19: TOXICO (KG/AÑO) | N19: INFLAMABLE (KG/AÑO) | O19: REACTIVO (KG/AÑO)
B20: 1 | C20: 2 | D20: 3 | E20: =SUM(B20:D20) -> 6 | F20: 4 | G20: 5 | H20: 6 | I20: 7 | J20: =SUM(F20:I20) -> 22 | K20: 8 | L20: 9 | M20: 0 | N20: 1 | O20: 2 | P20: =SUM(K20:O20) -> 20 | Q20: =J20+P20 -> 42 | R20: =SUM(B20:O20) -> 76
E21: =SUM(B21:D21) -> 0 | J21: =SUM(F21:I21) -> 0 | P21: =SUM(K21:O21) -> 0 | Q21: =J21+P21 -> 0 | R21: =SUM(B21:O21) -> 0
E22: =SUM(B22:D22) -> 0 | J22: =SUM(F22:I22) -> 0 | P22: =SUM(K22:O22) -> 0 | Q22: =J22+P22 -> 0 | R22: =SUM(B22:O22) -> 0
E23: =SUM(B23:D23) -> 0 | J23: =SUM(F23:I23) -> 0 | P23: =SUM(K23:O23) -> 0 | Q23: =J23+P23 -> 0 | R23: =SUM(B23:O23) -> 0
E24: =SUM(B24:D24) -> 0 | J24: =SUM(F24:I24) -> 0 | P24: =SUM(K24:O24) -> 0 | Q24: =J24+P24 -> 0 | R24: =SUM(B24:O24) -> 0
E25: =SUM(B25:D25) -> 0 | J25: =SUM(F25:I25) -> 0 | P25: =SUM(K25:O25) -> 0 | Q25: =J25+P25 -> 0 | R25: =SUM(B25:O25) -> 0
E26: =SUM(B26:D26) -> 0 | J26: =SUM(F26:I26) -> 0 | P26: =SUM(K26:O26) -> 0 | Q26: =J26+P26 -> 0 | R26: =SUM(B26:O26) -> 0
E27: =SUM(B27:D27) -> 0 | J27: =SUM(F27:I27) -> 0 | P27: =SUM(K27:O27) -> 0 | Q27: =J27+P27 -> 0 | R27: =SUM(B27:O27) -> 0
E28: =SUM(B28:D28) -> 0 | J28: =SUM(F28:I28) -> 0 | P28: =SUM(K28:O28) -> 0 | Q28: =J28+P28 -> 0 | R28: =SUM(B28:O28) -> 0
E29: =SUM(B29:D29) -> 0 | J29: =SUM(F29:I29) -> 0 | P29: =SUM(K29:O29) -> 0 | Q29: =J29+P29 -> 0 | R29: =SUM(B29:O29) -> 0
E30: =SUM(B30:D30) -> 0 | J30: =SUM(F30:I30) -> 0 | P30: =SUM(K30:O30) -> 0 | Q30: =J30+P30 -> 0 | R30: =SUM(B30:O30) -> 0
E31: =SUM(B31:D31) -> 0 | J31: =SUM(F31:I31) -> 0 | P31: =SUM(K31:O31) -> 0 | Q31: =J31+P31 -> 0 | R31: =SUM(B31:O31) -> 0
E32: =SUM(B32:D32) -> 0 | J32: =SUM(F32:I32) -> 0 | P32: =SUM(K32:O32) -> 0 | Q32: =J32+P32 -> 0 | R32: =SUM(B32:O32) -> 0
... E50: =SUM(B50:D50) -> 0 | J50: =SUM(F50:I50) -> 0 | P50: =SUM(K50:O50) -> 0 | Q50: =J50+P50 -> 0 | R50: =SUM(B50:O50) -> 0
A51: TOTAL | B51: =SUM(B20:B50) -> 1 | C51: =SUM(C20:C50) -> 2 | D51: =SUM(D20:D50) -> 3 | E51: =SUM(E20:E50) -> 6 | F51: =SUM(F20:F50) -> 4 | G51: =SUM(G20:G50) -> 5 | H51: =SUM(H20:H50) -> 6 | I51: =SUM(I20:I50) -> 7 | ... R51: =SUM(R20:R50) -> 76
A54: INDICADORES DE DESTINACION
B57: 27 | C57: 29 | D57: 29 | E57: 30 | F57: 31 | G57: 32 | J57: 33
A58: AÑO | B58: DESTINACIÓN DE RESIDUOS | G58: TOTAL | I58: MES | K58: INDICADORES DE DESTINACIÓN % | O58: INDICADOR TOTAL (%)
B59: DESACTIVACION (KG/AÑO) | C59: RECICLAJE (KG/AÑO) | D59: INCINERACIÓN (KG/AÑO) | E59: RELLENO SANITARIO (KG/AÑO) | F59: OTROS SISTEMAS DE DISPOSICION FINAL | J59: IDD | K59: IDR | L59: IDI | M59: IDRS | N59: IDOS
A60: Enero | B60: =+ENERO!B60 -> 0 | C60: =+ENERO!C60 -> 0 | D60: =+ENERO!D60 -> 0 | E60: =+ENERO!E60 -> 0 | F60: =+ENERO!F60 -> 0 | G60: =SUM(B60:F60) -> 0 | I60: Enero | J60: =(B60/ENERO!$R$51)*100 -> 0 | K60: =(C60/ENERO!$R$51)*100 -> 0 | L60: =(D60/ENERO!$R$51)*100 -> 0 | M60: =(E60/ENERO!$R$51)*100 -> 0 | N60: =(F60/ENERO!$R$51)*100 -> 0 | O60: =SUM(J60:N60)/100 -> 0
A61: Febrero | B61: =+FEBRERO!B61 -> 0 | C61: =+FEBRERO!C61 -> 0 | D61: =+FEBRERO!D61 -> 0 | E61: =+FEBRERO!E61 -> 0 | F61: =+FEBRERO!F61 -> 0 | G61: =SUM(B61:F61) -> 0 | I61: Febrero | J61: =(B61/FEBRERO!$R$51)*100 -> 0 | K61: =(C61/FEBRERO!$R$51)*100 -> 0 | L61: =(D61/FEBRERO!$R$51)*100 -> 0 | M61: =(E61/FEBRERO!$R$51)*100 -> 0 | N61: =(F61/FEBRERO!$R$51)*100 -> 0 | O61: =SUM(J61:N61)/100 -> 0
A62: Marzo | B62: =+MARZO!B62 -> 0 | C62: =+MARZO!C62 -> 0 | D62: =+MARZO!D62 -> 0 | E62: =+MARZO!E62 -> 0 | F62: =+MARZO!F62 -> 0 | G62: =SUM(B62:F62) -> 0 | I62: Marzo | J62: =(B62/MARZO!$R$51)*100 -> 0 | K62: =(C62/MARZO!$R$51)*100 -> 0 | L62: =(D62/MARZO!$R$51)*100 -> 0 | M62: =(E62/MARZO!$R$51)*100 -> 0 | N62: =(F62/MARZO!$R$51)*100 -> 0 | O62: =SUM(J62:N62)/100 -> 0
A63: Abril | B63: =+ABRIL!B63 -> 0 | C63: =+ABRIL!C63 -> 0 | D63: =+ABRIL!D63 -> 0 | E63: =+ABRIL!E63 -> 0 | F63: =+ABRIL!F63 -> 0 | G63: =SUM(B63:F63) -> 0 | I63: Abril | J63: =(B63/ABRIL!$R$51)*100 -> 0 | K63: =(C63/ABRIL!$R$51)*100 -> 0 | L63: =(D63/ABRIL!$R$51)*100 -> 0 | M63: =(E63/ABRIL!$R$51)*100 -> 0 | N63: =(F63/ABRIL!$R$51)*100 -> 0 | O63: =SUM(J63:N63)/100 -> 0
A64: Mayo | B64: =+MAYO!B64 -> 0 | C64: =+MAYO!C64 -> 0 | D64: =+MAYO!D64 -> 0 | E64: =+MAYO!E64 -> 0 | F64: =+MAYO!F64 -> 0 | G64: =SUM(B64:F64) -> 0 | I64: Mayo | J64: =(B64/MAYO!$R$51)*100 -> 0 | K64: =(C64/MAYO!$R$51)*100 -> 0 | L64: =(D64/MAYO!$R$51)*100 -> 0 | M64: =(E64/MAYO!$R$51)*100 -> 0 | N64: =(F64/MAYO!$R$51)*100 -> 0 | O64: =SUM(J64:N64)/100 -> 0
A65: Junio | B65: =+JUNIO!B65 -> 0 | C65: =+JUNIO!C65 -> 0 | D65: =+JUNIO!D65 -> 0 | E65: =+JUNIO!E65 -> 0 | F65: =+JUNIO!F65 -> 0 | G65: =SUM(B65:F65) -> 0 | I65: Junio | J65: =(B65/JUNIO!$R$51)*100 -> 0 | K65: =(C65/JUNIO!$R$51)*100 -> 0 | L65: =(D65/JUNIO!$R$51)*100 -> 0 | M65: =(E65/JUNIO!$R$51)*100 -> 0 | N65: =(F65/JUNIO!$R$51)*100 -> 0 | O65: =SUM(J65:N65)/100 -> 0
A66: Julio | B66: =+JULIO!B66 -> 0 | C66: =+JULIO!C66 -> 0 | D66: =+JULIO!D66 -> 0 | E66: =+JULIO!E66 -> 0 | F66: =+JULIO!F66 -> 0 | G66: =SUM(B66:F66) -> 0 | I66: Julio | J66: =(B66/JULIO!$R$51)*100 -> 0 | K66: =(C66/JULIO!$R$51)*100 -> 0 | L66: =(D66/JULIO!$R$51)*100 -> 0 | M66: =(E66/JULIO!$R$51)*100 -> 0 | N66: =(F66/JULIO!$R$51)*100 -> 0 | O66: =SUM(J66:N66)/100 -> 0
A67: Agosto | G67: =SUM(B67:F67) -> 0 | I67: Agosto | J67: =(B67/$R$51)*100 -> 0 | K67: =(C67/$R$51)*100 -> 0 | L67: =(D67/$R$51)*100 -> 0 | M67: =(E67/$R$51)*100 -> 0 | N67: =(F67/$R$51)*100 -> 0 | O67: =SUM(J67:N67)/100 -> 0
I70: IDD: Indicador de destinacion desactivacion de alta eficiencia
I71: IDR: Indicador de destinacion para reciclaje
...

Sheet SEPTIEMBRE
D1: FORMATO REGISTRO ANUAL DE GENERACION DE RESIDUOS GENERADOS EN LA ATENCION EN SALUD Y OTRAS ACTIVIDADES
A7: 1. Nombre de la institucion: | K7: 6. Correo Electronico
A8: 2. Ciudad | K8: 7. Responsable del diligenciamiento
A9: 3. Departamento | K9: 8. Cargo
A10: 4. Direccion | K10: 9. Mes:
A11: 5. Telefono
A14: CONSOLIDACION RESIDUOS POR DTS
B16: 10 | C16: 11 | D16: 12 | E16: 13 | F16: 14 | G16: 15 | H16: 16 | I16: 17 | J16: 18 | K16: 19 | L16: 20 | M16: 21 | N16: 22 | O16: 23 | P16: 24 | Q16: 25 | R16: 26
A17: DÍA | B17: RESIDUOS NO PELIGROS | E17: Subtotal Residuos no peligrosos | F17: RESIDUOS PELIGROSOS | Q17: Subtotal Residuos Peligrosos | R17: TOTAL
F18: INFECCIOSO O RIESGO BIOLOGICO | J18: Subtotal residuos de riesgo biologico o infeccioso | K18: OTROS RESIDUOS CON LAS SIGUIENTES CARACTERISTICAS | P18: Subtotal otros residuos
B19: BIODEGRADABLES (KG/AÑO) | C19: RECICLABLES (KG/AÑO) | D19: ORDINARIOS (KG/AÑO) | F19: BIOSANITARIOS (KG/AÑO) | G19: ANATOMOPATOLOGICOS (KG/AÑO) | H19: CORTOPUNZANTES (KG/AÑO) | I19: ANIMALES (KG/AÑO) | K19: CORROSIVA (KG/AÑO) | L19: EXPLOSIVO (KG/AÑO) | M19: TOXICO (KG/AÑO) | N19: INFLAMABLE (KG/AÑO) | O19: REACTIVO (KG/AÑO)
B20: 1 | C20: 2 | D20: 3 | E20: =SUM(B20:D20) -> 6 | F20: 4 | G20: 5 | H20: 6 | I20: 7 | J20: =SUM(F20:I20) -> 22 | K20: 8 | L20: 9 | M20: 0 | N20: 1 | O20: 2 | P20: =SUM(K20:O20) -> 20 | Q20: =J20+P20 -> 42 | R20: =SUM(B20:O20) -> 76
E21: =SUM(B21:D21) -> 0 | J21: =SUM(F21:I21) -> 0 | P21: =SUM(K21:O21) -> 0 | Q21: =J21+P21 -> 0 | R21: =SUM(B21:O21) -> 0
E22: =SUM(B22:D22) -> 0 | J22: =SUM(F22:I22) -> 0 | P22: =SUM(K22:O22) -> 0 | Q22: =J22+P22 -> 0 | R22: =SUM(B22:O22) -> 0
E23: =SUM(B23:D23) -> 0 | J23: =SUM(F23:I23) -> 0 | P23: =SUM(K23:O23) -> 0 | Q23: =J23+P23 -> 0 | R23: =SUM(B23:O23) -> 0
E24: =SUM(B24:D24) -> 0 | J24: =SUM(F24:I24) -> 0 | P24: =SUM(K24:O24) -> 0 | Q24: =J24+P24 -> 0 | R24: =SUM(B24:O24) -> 0
E25: =SUM(B25:D25) -> 0 | J25: =SUM(F25:I25) -> 0 | P25: =SUM(K25:O25) -> 0 | Q25: =J25+P25 -> 0 | R25: =SUM(B25:O25) -> 0
E26: =SUM(B26:D26) -> 0 | J26: =SUM(F26:I26) -> 0 | P26: =SUM(K26:O26) -> 0 | Q26: =J26+P26 -> 0 | R26: =SUM(B26:O26) -> 0
E27: =SUM(B27:D27) -> 0 | J27: =SUM(F27:I27) -> 0 | P27: =SUM(K27:O27) -> 0 | Q27: =J27+P27 -> 0 | R27: =SUM(B27:O27) -> 0
E28: =SUM(B28:D28) -> 0 | J28: =SUM(F28:I28) -> 0 | P28: =SUM(K28:O28) -> 0 | Q28: =J28+P28 -> 0 | R28: =SUM(B28:O28) -> 0
E29: =SUM(B29:D29) -> 0 | J29: =SUM(F29:I29) -> 0 | P29: =SUM(K29:O29) -> 0 | Q29: =J29+P29 -> 0 | R29: =SUM(B29:O29) -> 0
E30: =SUM(B30:D30) -> 0 | J30: =SUM(F30:I30) -> 0 | P30: =SUM(K30:O30) -> 0 | Q30: =J30+P30 -> 0 | R30: =SUM(B30:O30) -> 0
E31: =SUM(B31:D31) -> 0 | J31: =SUM(F31:I31) -> 0 | P31: =SUM(K31:O31) -> 0 | Q31: =J31+P31 -> 0 | R31: =SUM(B31:O31) -> 0
E32: =SUM(B32:D32) -> 0 | J32: =SUM(F32:I32) -> 0 | P32: =SUM(K32:O32) -> 0 | Q32: =J32+P32 -> 0 | R32: =SUM(B32:O32) -> 0
... E50: =SUM(B50:D50) -> 0 | J50: =SUM(F50:I50) -> 0 | P50: =SUM(K50:O50) -> 0 | Q50: =J50+P50 -> 0 | R50: =SUM(B50:O50) -> 0
A51: TOTAL | B51: =SUM(B20:B50) -> 1 | C51: =SUM(C20:C50) -> 2 | D51: =SUM(D20:D50) -> 3 | E51: =SUM(E20:E50) -> 6 | F51: =SUM(F20:F50) -> 4 | G51: =SUM(G20:G50) -> 5 | H51: =SUM(H20:H50) -> 6 | I51: =SUM(I20:I50) -> 7 | ... R51: =SUM(R20:R50) -> 76
A54: INDICADORES DE DESTINACION
B57: 27 | C57: 29 | D57: 29 | E57: 30 | F57: 31 | G57: 32 | J57: 33
A58: AÑO | B58: DESTINACIÓN DE RESIDUOS | G58: TOTAL | I58: MES | K58: INDICADORES DE DESTINACIÓN % | O58: INDICADOR TOTAL (%)
B59: DESACTIVACION (KG/AÑO) | C59: RECICLAJE (KG/AÑO) | D59: INCINERACIÓN (KG/AÑO) | E59: RELLENO SANITARIO (KG/AÑO) | F59: OTROS SISTEMAS DE DISPOSICION FINAL | J59: IDD | K59: IDR | L59: IDI | M59: IDRS | N59: IDOS
A60: Enero | B60: =+ENERO!B60 -> 0 | C60: =+ENERO!C60 -> 0 | D60: =+ENERO!D60 -> 0 | E60: =+ENERO!E60 -> 0 | F60: =+ENERO!F60 -> 0 | G60: =SUM(B60:F60) -> 0 | I60: Enero | J60: =(B60/ENERO!$R$51)*100 -> 0 | K60: =(C60/ENERO!$R$51)*100 -> 0 | L60: =(D60/ENERO!$R$51)*100 -> 0 | M60: =(E60/ENERO!$R$51)*100 -> 0 | N60: =(F60/ENERO!$R$51)*100 -> 0 | O60: =SUM(J60:N60)/100 -> 0
A61: Febrero | B61: =+FEBRERO!B61 -> 0 | C61: =+FEBRERO!C61 -> 0 | D61: =+FEBRERO!D61 -> 0 | E61: =+FEBRERO!E61 -> 0 | F61: =+FEBRERO!F61 -> 0 | G61: =SUM(B61:F61) -> 0 | I61: Febrero | J61: =(B61/FEBRERO!$R$51)*100 -> 0 | K61: =(C61/FEBRERO!$R$51)*100 -> 0 | L61: =(D61/FEBRERO!$R$51)*100 -> 0 | M61: =(E61/FEBRERO!$R$51)*100 -> 0 | N61: =(F61/FEBRERO!$R$51)*100 -> 0 | O61: =SUM(J61:N61)/100 -> 0
A62: Marzo | B62: =+MARZO!B62 -> 0 | C62: =+MARZO!C62 -> 0 | D62: =+MARZO!D62 -> 0 | E62: =+MARZO!E62 -> 0 | F62: =+MARZO!F62 -> 0 | G62: =SUM(B62:F62) -> 0 | I62: Marzo | J62: =(B62/MARZO!$R$51)*100 -> 0 | K62: =(C62/MARZO!$R$51)*100 -> 0 | L62: =(D62/MARZO!$R$51)*100 -> 0 | M62: =(E62/MARZO!$R$51)*100 -> 0 | N62: =(F62/MARZO!$R$51)*100 -> 0 | O62: =SUM(J62:N62)/100 -> 0
A63: Abril | B63: =+ABRIL!B63 -> 0 | C63: =+ABRIL!C63 -> 0 | D63: =+ABRIL!D63 -> 0 | E63: =+ABRIL!E63 -> 0 | F63: =+ABRIL!F63 -> 0 | G63: =SUM(B63:F63) -> 0 | I63: Abril | J63: =(B63/ABRIL!$R$51)*100 -> 0 | K63: =(C63/ABRIL!$R$51)*100 -> 0 | L63: =(D63/ABRIL!$R$51)*100 -> 0 | M63: =(E63/ABRIL!$R$51)*100 -> 0 | N63: =(F63/ABRIL!$R$51)*100 -> 0 | O63: =SUM(J63:N63)/100 -> 0
A64: Mayo | B64: =+MAYO!B64 -> 0 | C64: =+MAYO!C64 -> 0 | D64: =+MAYO!D64 -> 0 | E64: =+MAYO!E64 -> 0 | F64: =+MAYO!F64 -> 0 | G64: =SUM(B64:F64) -> 0 | I64: Mayo | J64: =(B64/MAYO!$R$51)*100 -> 0 | K64: =(C64/MAYO!$R$51)*100 -> 0 | L64: =(D64/MAYO!$R$51)*100 -> 0 | M64: =(E64/MAYO!$R$51)*100 -> 0 | N64: =(F64/MAYO!$R$51)*100 -> 0 | O64: =SUM(J64:N64)/100 -> 0
A65: Junio | B65: =+JUNIO!B65 -> 0 | C65: =+JUNIO!C65 -> 0 | D65: =+JUNIO!D65 -> 0 | E65: =+JUNIO!E65 -> 0 | F65: =+JUNIO!F65 -> 0 | G65: =SUM(B65:F65) -> 0 | I65: Junio | J65: =(B65/JUNIO!$R$51)*100 -> 0 | K65: =(C65/JUNIO!$R$51)*100 -> 0 | L65: =(D65/JUNIO!$R$51)*100 -> 0 | M65: =(E65/JUNIO!$R$51)*100 -> 0 | N65: =(F65/JUNIO!$R$51)*100 -> 0 | O65: =SUM(J65:N65)/100 -> 0
A66: Julio | B66: =+JULIO!B66 -> 0 | C66: =+JULIO!C66 -> 0 | D66: =+JULIO!D66 -> 0 | E66: =+JULIO!E66 -> 0 | F66: =+JULIO!F66 -> 0 | G66: =SUM(B66:F66) -> 0 | I66: Julio | J66: =(B66/JULIO!$R$51)*100 -> 0 | K66: =(C66/JULIO!$R$51)*100 -> 0 | L66: =(D66/JULIO!$R$51)*100 -> 0 | M66: =(E66/JULIO!$R$51)*100 -> 0 | N66: =(F66/JULIO!$R$51)*100 -> 0 | O66: =SUM(J66:N66)/100 -> 0
A67: Agosto | B67: =+AGOSTO!B67 -> 0 | C67: =+AGOSTO!C67 -> 0 | D67: =+AGOSTO!D67 -> 0 | E67: =+AGOSTO!E67 -> 0 | F67: =+AGOSTO!F67 -> 0 | G67: =SUM(B67:F67) -> 0 | I67: Agosto | J67: =(B67/AGOSTO!$R$51)*100 -> 0 | K67: =(C67/AGOSTO!$R$51)*100 -> 0 | L67: =(D67/AGOSTO!$R$51)*100 -> 0 | M67: =(E67/AGOSTO!$R$51)*100 -> 0 | N67: =(F67/AGOSTO!$R$51)*100 -> 0 | O67: =SUM(J67:N67)/100 -> 0
A68: Septiembre | G68: =SUM(B68:F68) -> 0 | I68: Septiembre | J68: =(B68/$R$51)*100 -> 0 | K68: =(C68/$R$51)*100 -> 0 | L68: =(D68/$R$51)*100 -> 0 | M68: =(E68/$R$51)*100 -> 0 | N68: =(F68/$R$51)*100 -> 0 | O68: =SUM(J68:N68)/100 -> 0
I71: IDD: Indicador de destinacion desactivacion de alta eficiencia
...

Sheet OCTUBRE
D1: FORMATO REGISTRO ANUAL DE GENERACION DE RESIDUOS GENERADOS EN LA ATENCION EN SALUD Y OTRAS ACTIVIDADES
A7: 1. Nombre de la institucion: | K7: 6. Correo Electronico
A8: 2. Ciudad | K8: 7. Responsable del diligenciamiento
A9: 3. Departamento | K9: 8. Cargo
A10: 4. Direccion | K10: 9. Mes:
A11: 5. Telefono
A14: CONSOLIDACION RESIDUOS POR DTS
B16: 10 | C16: 11 | D16: 12 | E16: 13 | F16: 14 | G16: 15 | H16: 16 | I16: 17 | J16: 18 | K16: 19 | L16: 20 | M16: 21 | N16: 22 | O16: 23 | P16: 24 | Q16: 25 | R16: 26
A17: DÍA | B17: RESIDUOS NO PELIGROS | E17: Subtotal Residuos no peligrosos | F17: RESIDUOS PELIGROSOS | Q17: Subtotal Residuos Peligrosos | R17: TOTAL
F18: INFECCIOSO O RIESGO BIOLOGICO | J18: Subtotal residuos de riesgo biologico o infeccioso | K18: OTROS RESIDUOS CON LAS SIGUIENTES CARACTERISTICAS | P18: Subtotal otros residuos
B19: BIODEGRADABLES (KG/AÑO) | C19: RECICLABLES (KG/AÑO) | D19: ORDINARIOS (KG/AÑO) | F19: BIOSANITARIOS (KG/AÑO) | G19: ANATOMOPATOLOGICOS (KG/AÑO) | H19: CORTOPUNZANTES (KG/AÑO) | I19: ANIMALES (KG/AÑO) | K19: CORROSIVA (KG/AÑO) | L19: EXPLOSIVO (KG/AÑO) | M19: TOXICO (KG/AÑO) | N19: INFLAMABLE (KG/AÑO) | O19: REACTIVO (KG/AÑO)
B20: 1 | C20: 2 | D20: 3 | E20: =SUM(B20:D20) -> 6 | F20: 4 | G20: 5 | H20: 6 | I20: 7 | J20: =SUM(F20:I20) -> 22 | K20: 8 | L20: 9 | M20: 0 | N20: 1 | O20: 2 | P20: =SUM(K20:O20) -> 20 | Q20: =J20+P20 -> 42 | R20: =SUM(B20:O20) -> 76
E21: =SUM(B21:D21) -> 0 | J21: =SUM(F21:I21) -> 0 | P21: =SUM(K21:O21) -> 0 | Q21: =J21+P21 -> 0 | R21: =SUM(B21:O21) -> 0
E22: =SUM(B22:D22) -> 0 | J22: =SUM(F22:I22) -> 0 | P22: =SUM(K22:O22) -> 0 | Q22: =J22+P22 -> 0 | R22: =SUM(B22:O22) -> 0
E23: =SUM(B23:D23) -> 0 | J23: =SUM(F23:I23) -> 0 | P23: =SUM(K23:O23) -> 0 | Q23: =J23+P23 -> 0 | R23: =SUM(B23:O23) -> 0
E24: =SUM(B24:D24) -> 0 | J24: =SUM(F24:I24) -> 0 | P24: =SUM(K24:O24) -> 0 | Q24: =J24+P24 -> 0 | R24: =SUM(B24:O24) -> 0
E25: =SUM(B25:D25) -> 0 | J25: =SUM(F25:I25) -> 0 | P25: =SUM(K25:O25) -> 0 | Q25: =J25+P25 -> 0 | R25: =SUM(B25:O25) -> 0
E26: =SUM(B26:D26) -> 0 | J26: =SUM(F26:I26) -> 0 | P26: =SUM(K26:O26) -> 0 | Q26: =J26+P26 -> 0 | R26: =SUM(B26:O26) -> 0
E27: =SUM(B27:D27) -> 0 | J27: =SUM(F27:I27) -> 0 | P27: =SUM(K27:O27) -> 0 | Q27: =J27+P27 -> 0 | R27: =SUM(B27:O27) -> 0
E28: =SUM(B28:D28) -> 0 | J28: =SUM(F28:I28) -> 0 | P28: =SUM(K28:O28) -> 0 | Q28: =J28+P28 -> 0 | R28: =SUM(B28:O28) -> 0
E29: =SUM(B29:D29) -> 0 | J29: =SUM(F29:I29) -> 0 | P29: =SUM(K29:O29) -> 0 | Q29: =J29+P29 -> 0 | R29: =SUM(B29:O29) -> 0
E30: =SUM(B30:D30) -> 0 | J30: =SUM(F30:I30) -> 0 | P30: =SUM(K30:O30) -> 0 | Q30: =J30+P30 -> 0 | R30: =SUM(B30:O30) -> 0
E31: =SUM(B31:D31) -> 0 | J31: =SUM(F31:I31) -> 0 | P31: =SUM(K31:O31) -> 0 | Q31: =J31+P31 -> 0 | R31: =SUM(B31:O31) -> 0
E32: =SUM(B32:D32) -> 0 | J32: =SUM(F32:I32) -> 0 | P32: =SUM(K32:O32) -> 0 | Q32: =J32+P32 -> 0 | R32: =SUM(B32:O32) -> 0
... E40: =SUM(B40:D40) -> 0 | J40: =SUM(F40:I40) -> 0 | P40: =SUM(K40:O40) -> 0 | Q40: =J40+P40 -> 0 | R40: =SUM(B40:O40) -> 0
D41: 5 | E41: =SUM(B41:D41) -> 5 | J41: =SUM(F41:I41) -> 0 | P41: =SUM(K41:O41) -> 0 | Q41: =J41+P41 -> 0 | R41: =SUM(B41:O41) -> 10
E42: =SUM(B42:D42) -> 0 | J42: =SUM(F42:I42) -> 0 | P42: =SUM(K42:O42) -> 0 | Q42: =J42+P42 -> 0 | R42: =SUM(B42:O42) -> 0
E43: =SUM(B43:D43) -> 0 | J43: =SUM(F43:I43) -> 0 | P43: =SUM(K43:O43) -> 0 | Q43: =J43+P43 -> 0 | R43: =SUM(B43:O43) -> 0
E44: =SUM(B44:D44) -> 0 | J44: =SUM(F44:I44) -> 0 | P44: =SUM(K44:O44) -> 0 | Q44: =J44+P44 -> 0 | R44: =SUM(B44:O44) -> 0
E45: =SUM(B45:D45) -> 0 | J45: =SUM(F45:I45) -> 0 | P45: =SUM(K45:O45) -> 0 | Q45: =J45+P45 -> 0 | R45: =SUM(B45:O45) -> 0
E46: =SUM(B46:D46) -> 0 | J46: =SUM(F46:I46) -> 0 | P46: =SUM(K46:O46) -> 0 | Q46: =J46+P46 -> 0 | R46: =SUM(B46:O46) -> 0
E47: =SUM(B47:D47) -> 0 | J47: =SUM(F47:I47) -> 0 | P47: =SUM(K47:O47) -> 0 | Q47: =J47+P47 -> 0 | R47: =SUM(B47:O47) -> 0
E48: =SUM(B48:D48) -> 0 | J48: =SUM(F48:I48) -> 0 | P48: =SUM(K48:O48) -> 0 | Q48: =J48+P48 -> 0 | R48: =SUM(B48:O48) -> 0
E49: =SUM(B49:D49) -> 0 | J49: =SUM(F49:I49) -> 0 | P49: =SUM(K49:O49) -> 0 | Q49: =J49+P49 -> 0 | R49: =SUM(B49:O49) -> 0
E50: =SUM(B50:D50) -> 0 | J50: =SUM(F50:I50) -> 0 | P50: =SUM(K50:O50) -> 0 | Q50: =J50+P50 -> 0 | R50: =SUM(B50:O50) -> 0
A51: TOTAL | B51: =SUM(B20:B50) -> 1 | C51: =SUM(C20:C50) -> 2 | D51: =SUM(D20:D50) -> 8 | E51: =SUM(E20:E50) -> 11 | F51: =SUM(F20:F50) -> 4 | G51: =SUM(G20:G50) -> 5 | H51: =SUM(H20:H50) -> 6 | I51: =SUM(I20:I50) -> 7 | ... R51: =SUM(R20:R50) -> 86
A54: INDICADORES DE DESTINACION
B57: 27 | C57: 29 | D57: 29 | E57: 30 | F57: 31 | G57: 32 | J57: 33
A58: AÑO | B58: DESTINACIÓN DE RESIDUOS | G58: TOTAL | I58: MES | K58: INDICADORES DE DESTINACIÓN % | O58: INDICADOR TOTAL (%)
B59: DESACTIVACION (KG/AÑO) | C59: RECICLAJE (KG/AÑO) | D59: INCINERACIÓN (KG/AÑO) | E59: RELLENO SANITARIO (KG/AÑO) | F59: OTROS SISTEMAS DE DISPOSICION FINAL | J59: IDD | K59: IDR | L59: IDI | M59: IDRS | N59: IDOS
...

Sheet NOVIEMBRE
D1: FORMATO REGISTRO ANUAL DE GENERACION DE RESIDUOS GENERADOS EN LA ATENCION EN SALUD Y OTRAS ACTIVIDADES
A7: 1. Nombre de la institucion: | K7: 6. Correo Electronico
A8: 2. Ciudad | K8: 7. Responsable del diligenciamiento
A9: 3. Departamento | K9: 8. Cargo
A10: 4. Direccion | K10: 9. Mes:
A11: 5. Telefono
A14: CONSOLIDACION RESIDUOS POR DTS
B16: 10 | C16: 11 | D16: 12 | E16: 13 | F16: 14 | G16: 15 | H16: 16 | I16: 17 | J16: 18 | K16: 19 | L16: 20 | M16: 21 | N16: 22 | O16: 23 | P16: 24 | Q16: 25 | R16: 26
A17: DÍA | B17: RESIDUOS NO PELIGROS | E17: Subtotal Residuos no peligrosos | F17: RESIDUOS PELIGROSOS | Q17: Subtotal Residuos Peligrosos | R17: TOTAL
F18: INFECCIOSO O RIESGO BIOLOGICO | J18: Subtotal residuos de riesgo biologico o infeccioso | K18: OTROS RESIDUOS CON LAS SIGUIENTES CARACTERISTICAS | P18: Subtotal otros residuos
B19: BIODEGRADABLES (KG/AÑO) | C19: RECICLABLES (KG/AÑO) | D19: ORDINARIOS (KG/AÑO) | F19: BIOSANITARIOS (KG/AÑO) | G19: ANATOMOPATOLOGICOS (KG/AÑO) | H19: CORTOPUNZANTES (KG/AÑO) | I19: ANIMALES (KG/AÑO) | K19: CORROSIVA (KG/AÑO) | L19: EXPLOSIVO (KG/AÑO) | M19: TOXICO (KG/AÑO) | N19: INFLAMABLE (KG/AÑO) | O19: REACTIVO (KG/AÑO)
B20: 1 | C20: 2 | D20: 3 | E20: =SUM(B20:D20) -> 6 | F20: 4 | G20: 5 | H20: 6 | I20: 7 | J20: =SUM(F20:I20) -> 22 | K20: 8 | L20: 9 | M20: 0 | N20: 1 | O20: 2 | P20: =SUM(K20:O20) -> 20 | Q20: =J20+P20 -> 42 | R20: =SUM(B20:O20) -> 76
E21: =SUM(B21:D21) -> 0 | J21: =SUM(F21:I21) -> 0 | P21: =SUM(K21:O21) -> 0 | Q21: =J21+P21 -> 0 | R21: =SUM(B21:O21) -> 0
E22: =SUM(B22:D22) -> 0 | J22: =SUM(F22:I22) -> 0 | P22: =SUM(K22:O22) -> 0 | Q22: =J22+P22 -> 0 | R22: =SUM(B22:O22) -> 0
E23: =SUM(B23:D23) -> 0 | J23: =SUM(F23:I23) -> 0 | P23: =SUM(K23:O23) -> 0 | Q23: =J23+P23 -> 0 | R23: =SUM(B23:O23) -> 0
E24: =SUM(B24:D24) -> 0 | J24: =SUM(F24:I24) -> 0 | P24: =SUM(K24:O24) -> 0 | Q24: =J24+P24 -> 0 | R24: =SUM(B24:O24) -> 0
E25: =SUM(B25:D25) -> 0 | J25: =SUM(F25:I25) -> 0 | P25: =SUM(K25:O25) -> 0 | Q25: =J25+P25 -> 0 | R25: =SUM(B25:O25) -> 0
E26: =SUM(B26:D26) -> 0 | J26: =SUM(F26:I26) -> 0 | P26: =SUM(K26:O26) -> 0 | Q26: =J26+P26 -> 0 | R26: =SUM(B26:O26) -> 0
E27: =SUM(B27:D27) -> 0 | J27: =SUM(F27:I27) -> 0 | P27: =SUM(K27:O27) -> 0 | Q27: =J27+P27 -> 0 | R27: =SUM(B27:O27) -> 0
E28: =SUM(B28:D28) -> 0 | J28: =SUM(F28:I28) -> 0 | P28: =SUM(K28:O28) -> 0 | Q28: =J28+P28 -> 0 | R28: =SUM(B28:O28) -> 0
E29: =SUM(B29:D29) -> 0 | J29: =SUM(F29:I29) -> 0 | P29: =SUM(K29:O29) -> 0 | Q29: =J29+P29 -> 0 | R29: =SUM(B29:O29) -> 0
E30: =SUM(B30:D30) -> 0 | J30: =SUM(F30:I30) -> 0 | P30: =SUM(K30:O30) -> 0 | Q30: =J30+P30 -> 0 | R30: =SUM(B30:O30) -> 0
E31: =SUM(B31:D31) -> 0 | J31: =SUM(F31:I31) -> 0 | P31: =SUM(K31:O31) -> 0 | Q31: =J31+P31 -> 0 | R31: =SUM(B31:O31) -> 0
E32: =SUM(B32:D32) -> 0 | J32: =SUM(F32:I32) -> 0 | P32: =SUM(K32:O32) -> 0 | Q32: =J32+P32 -> 0 | R32: =SUM(B32:O32) -> 0
... E50: =SUM(B50:D50) -> 0 | J50: =SUM(F50:I50) -> 0 | P50: =SUM(K50:O50) -> 0 | Q50: =J50+P50 -> 0 | R50: =SUM(B50:O50) -> 0
A51: TOTAL | B51: =SUM(B20:B50) -> 1 | C51: =SUM(C20:C50) -> 2 | D51: =SUM(D20:D50) -> 3 | E51: =SUM(E20:E50) -> 6 | F51: =SUM(F20:F50) -> 4 | G51: =SUM(G20:G50) -> 5 | H51: =SUM(H20:H50) -> 6 | I51: =SUM(I20:I50) -> 7 | ... R51: =SUM(R20:R50) -> 76
A54: INDICADORES DE DESTINACION
B57: 27 | C57: 29 | D57: 29 | E57: 30 | F57: 31 | G57: 32 | J57: 33
A58: AÑO | B58: DESTINACIÓN DE RESIDUOS | G58: TOTAL | I58: MES | K58: INDICADORES DE DESTINACIÓN % | O58: INDICADOR TOTAL (%)
B59: DESACTIVACION (KG/AÑO) | C59: RECICLAJE (KG/AÑO) | D59: INCINERACIÓN (KG/AÑO) | E59: RELLENO SANITARIO (KG/AÑO) | F59: OTROS SISTEMAS DE DISPOSICION FINAL | J59: IDD | K59: IDR | L59: IDI | M59: IDRS | N59: IDOS
