Workbook

Sheet Instructivo
C1: Instructivo: Formato registro anual de generacion de residuos generados en la atencion en salud y otras actividades
A2: SECRETARIA DE DESARROLLO DE LA SALUD DE CÓRDOBA
A3: SALUD AMBIENTAL
A5: Bloque | B5: No. | D5: Item | E5: Diligenciamiento
A6: Información general | B6: 1 | C6: Nombre del generador de residuos | E6: Nombre completo del establecimiento generador de residuos
B7: 2 | C7: Ciudad | E7: Ciudad de ubicación del establecimiento generador de residuos
B8: 3 | C8: Departamento | E8: Departamento de ubicación del establecimiento generador de residuos
B9: 4 | C9: Direccion | E9: Dirección del establecimiento generador de residuos
B10: 5 | C10: Telefono | E10: Teléfono del establecimiento generador de residuos
B11: 6 | C11: Correo Electronico | E11: Correo electrónico del establecimiento generador de residuos
B12: 7 | C12: Responsable del diligenciamiento | E12: Nombre completo del encargado de diligenciar el formulario
B13: 8 | C13: Cargo | E13: Cargo del encargado de diligenciar el formato
B14: 9 | C14: Fecha del reporte | E14: Fecha de diligenciamiento del formato
A15: Consolidación residuos por DTS | B15: 10 | C15: Residuos no peligrosos - | D15: Biodegradables | E15: Cantidad en Kg/mes de residuos Biodegradables (residuos orgánicos aprovechables*) generados por el establecimiento de atención en salud y otras actividades
B16: 11 | D16: Reciclables | E16: Cantidad en Kg/mes de residuos reciclables (residuos aprovechables*) generados por el establecimiento de atención en salud y otras actividades
B17: 12 | D17: Ordinarios | E17: Cantidad en Kg/mes de residuos ordinarios (residios no aprovechables*) generados por el establecimiento de atención en salud y otras actividades
B18: 13 | D18: Subtotal Residuos no peligrosos | E18: Celda formulada que no requiere diligenciar. Sumatoria de las cantidades de residuos no peligrosos
B19: 14 | C19: Residuos peligrosos riesgo biológico o infeccioso | D19: Biosanitarios | E19: Cantidad en Kg/mes de residuos biosanitarios generados por el establecimiento de atención en salud y otras actividades
B20: 15 | D20: Cortopunzantes | E20: Cantidad en Kg/mes de residuos cortopunzantes generados por el establecimiento de atención en salud y otras actividades
B21: 16 | D21: Anatomopatológicos | E21: Cantidad en Kg/mes de residuos biosanitarios generados por el establecimiento de atención en salud y otras actividades
B22: 17 | D22: Animales | E22: Cantidad en Kg/mes de residuos biosanitarios generados por el establecimiento de atención en salud y otras actividades
B23: 18 | D23: Subtotal residuos de riesgo biologico o infeccioso | E23: Celda formulada que no requiere diligenciar. Sumatoria de las cantidades de residuos de riesgo biológico o infeccioso
B24: 19 | C24: Residuos peligrosos otros residuos con las siguientes características ** | D24: Corrosivo | E24: Cantidad en Kg/mes de residuos de característica corrosivo generados por el establecimiento de atención en salud y otras actividades
B25: 20 | D25: Explosivo | E25: Cantidad en Kg/mes de residuos de característica explosivo generados por el establecimiento de atención en salud y otras actividades
B26: 21 | D26: Toxico | E26: Cantidad en Kg/mes de residuos de característica tóxico generados por el establecimiento de atención en salud y otras actividades
B27: 22 | D27: Inflamable | E27: Cantidad en Kg/mes de residuos de característica inflamable generados por el establecimiento de atención en salud y otras actividades
B28: 23 | D28: Reactivo | E28: Cantidad en Kg/mes de residuos de característica reactivo generados por el establecimiento de atención en salud y otras actividades
B29: 24 | D29: Subtotal otros residuos | E29: Celda formulada que no requiere diligenciar. Sumatoria de las cantidades de otros residuos
B30: 25 | D30: Subtotal Residuos Peligrosos | E30: Celda formulada que no requiere diligenciar. Sumatoria de las cantidades de residuos peligrosos
B31: 26 | C31: Total | E31: Celda formulada que no requiere diligenciar. Sumatoria de las cantidades de residuos generados por el establecimiento de atención en salud y otras actividades
A32: Indicadores de destinación | B32: 27 | C32: Destinación de residuos | D32: Desactivación | E32: Cantidad en Kg/mes de residuos destinados a desactivación
B33: 28 | D33: Reciclaje | E33: Cantidad en Kg/mes de residuos destinados a reciclaje (aprovechamiento)
B34: 29 | D34: Incineración | E34: Cantidad en Kg/mes de residuos destinados a incineración
B35: 30 | D35: Relleno sanitario | E35: Cantidad en Kg/mes de residuos destinados a disposición en relleno sanitario
D36: Otros sistemas de disposición final | E36: Cantidad en Kg/mes de residuos destinados en otros sistemas de disposición final aceptada por la legislación
B37: 31 | D37: Total | E37: Celda formulada que no requiere diligenciar. Sumatoria de las cantidades destinación de residuos generados por el establecimiento de atención en salud y otras actividades. Atención: La sumatoria de esta celda deberá ser igual a la sumatoria de las cantidades de residuos generados por el establecimiento de atención en salud y otras actividades (Item no. 26). Si no coinciden los valores la celda se mostrará de color rojo.
B38: 28 | C38: Indicadores de destinación | E38: Celdas formuladas que no requieren ser diligenciadas. Cálculo de la cantidad de residuos sometidos a desactivación de alta eficiencia, incineración, reciclaje, disposición en rellenos sanitarios, u otros sistemas de gestión dividido entre la cantidad total de residuos que fueron generados. Atención: Si el total del indicador de destinación no es 100% la celda se mostrará en color rojo.
B40: * Titulo 2 del Decreto 1077 de 2015 del MVCT, Resolución 2184 de 2019 del MADS y MVCT

Sheet Enero
D1: FORMATO REGISTRO ANUAL DE GENERACION DE RESIDUOS GENERADOS EN LA ATENCION EN SALUD Y OTRAS ACTIVIDADES | Q1: Version 2.0
Q3: Fecha: 08/03/2022
Q5: CODIGO
A7: 1. Nombre del Generador | D7: GESTAR SALUD IPS SEDE CIENAGA DE ORO CONTRIBUTIVO | K7: 6. Correo Electronico | N7: SEDECIENAGA@GESTARSALUDIPS.COM
A8: 2. Ciudad | D8: CIENAGA DE ORO | K8: 7. Responsable del diligenciamiento | N8: YULIS PAULINA DURANGO
A9: 3. Departamento | D9: CORDOBA | K9: 8. Cargo | N9: SERVICIOS GENERALES
A10: 4. Direccion | D10: CALLE 7 14-16 BARRIO CENTRO | K10: 9. Mes: | N10: ENERO
A11: 5. Telefono
A16: CONSOLIDACION RESIDUOS POR ESTABLECIMIENTO GENERADOR DE RESIDUOS
B18: 10 | C18: 11 | D18: 12 | E18: 13 | F18: 14 | G18: 15 | H18: 16 | I18: 17 | J18: 18 | K18: 19 | L18: 20 | M18: 21 | N18: 22 | O18: 23 | P18: 24 | Q18: 0 | R18: 26
A19: DÍA | B19: RESIDUOS NO PELIGROS | E19: Subtotal Residuos no peligrosos | F19: RESIDUOS PELIGROSOS | Q19: Subtotal Residuos Peligrosos | R19: TOTAL
F20: INFECCIOSO O RIESGO BIOLOGICO | J20: Subtotal residuos de riesgo biologico o infeccioso | K20: OTROS RESIDUOS CON LAS SIGUIENTES CARACTERISTICAS | P20: Subtotal otros residuos
B21: BIODEGRADABLES (KG/DÍA) | C21: RECICLABLES (KG/DÍA) | D21: ORDINARIOS (KG/DÍA) | F21: BIOSANITARIOS (KG/DÍA) | G21: ANATOMOPATOLOGICOS (KG/DÍA) | H21: CORTOPUNZANTES (KG/DÍA) | I21: ANIMALES (KG/DÍA) | K21: CORROSIVA (KG/DÍA) | L21: EXPLOSIVO (KG/DÍA) | M21: TOXICO (KG/DÍA) | N21: INFLAMABLE (KG/DÍA) | O21: REACTIVO (KG/DÍA)
A22: 1 | E22: =+SUM(B22:D22) -> 0 | J22: =+SUM(F22:I22) -> 0 | P22: =+SUM(K22:O22) -> 0 | Q22: =+J22+P22 -> 0 | R22: =+E22+Q22 -> 0
A23: 2 | E23: =+SUM(B23:D23) -> 0 | J23: =+SUM(F23:I23) -> 0 | P23: =+SUM(K23:O23) -> 0 | Q23: =+J23+P23 -> 0 | R23: =+E23+Q23 -> 0
A24: 3 | E24: =+SUM(B24:D24) -> 0 | J24: =+SUM(F24:I24) -> 0 | P24: =+SUM(K24:O24) -> 0 | Q24: =+J24+P24 -> 0 | R24: =+E24+Q24 -> 0
A25: 4 | E25: =+SUM(B25:D25) -> 0 | J25: =+SUM(F25:I25) -> 0 | P25: =+SUM(K25:O25) -> 0 | Q25: =+J25+P25 -> 0 | R25: =+E25+Q25 -> 0
A26: 5 | E26: =+SUM(B26:D26) -> 0 | J26: =+SUM(F26:I26) -> 0 | P26: =+SUM(K26:O26) -> 0 | Q26: =+J26+P26 -> 0 | R26: =+E26+Q26 -> 0
A27: 6 | E27: =+SUM(B27:D27) -> 0 | J27: =+SUM(F27:I27) -> 0 | P27: =+SUM(K27:O27) -> 0 | Q27: =+J27+P27 -> 0 | R27: =+E27+Q27 -> 0
A28: 7 | E28: =+SUM(B28:D28) -> 0 | J28: =+SUM(F28:I28) -> 0 | P28: =+SUM(K28:O28) -> 0 | Q28: =+J28+P28 -> 0 | R28: =+E28+Q28 -> 0
A29: 8 | D29: 3.2 | E29: =+SUM(B29:D29) -> 3.2 | J29: =+SUM(F29:I29) -> 0 | P29: =+SUM(K29:O29) -> 0 | Q29: =+J29+P29 -> 0 | R29: =+E29+Q29 -> 3.2
A30: 9 | E30: =+SUM(B30:D30) -> 0 | J30: =+SUM(F30:I30) -> 0 | P30: =+SUM(K30:O30) -> 0 | Q30: =+J30+P30 -> 0 | R30: =+E30+Q30 -> 0
A31: 10 | E31: =+SUM(B31:D31) -> 0 | J31: =+SUM(F31:I31) -> 0 | P31: =+SUM(K31:O31) -> 0 | Q31: =+J31+P31 -> 0 | R31: =+E31+Q31 -> 0
A32: 11 | E32: =+SUM(B32:D32) -> 0 | J32: =+SUM(F32:I32) -> 0 | P32: =+SUM(K32:O32) -> 0 | Q32: =+J32+P32 -> 0 | R32: =+E32+Q32 -> 0
A33: 12 | E33: =+SUM(B33:D33) -> 0 | J33: =+SUM(F33:I33) -> 0 | P33: =+SUM(K33:O33) -> 0 | Q33: =+J33+P33 -> 0 | R33: =+E33+Q33 -> 0
A34: 13 | E34: =+SUM(B34:D34) -> 0 | J34: =+SUM(F34:I34) -> 0 | P34: =+SUM(K34:O34) -> 0 | Q34: =+J34+P34 -> 0 | R34: =+E34+Q34 -> 0
A35: 14 | E35: =+SUM(B35:D35) -> 0 | J35: =+SUM(F35:I35) -> 0 | P35: =+SUM(K35:O35) -> 0 | Q35: =+J35+P35 -> 0 | R35: =+E35+Q35 -> 0
A36: 15 | E36: =+SUM(B36:D36) -> 0 | J36: =+SUM(F36:I36) -> 0 | P36: =+SUM(K36:O36) -> 0 | Q36: =+J36+P36 -> 0 | R36: =+E36+Q36 -> 0
A37: 16 | E37: =+SUM(B37:D37) -> 0 | J37: =+SUM(F37:I37) -> 0 | P37: =+SUM(K37:O37) -> 0 | Q37: =+J37+P37 -> 0 | R37: =+E37+Q37 -> 0
A38: 17 | E38: =+SUM(B38:D38) -> 0 | J38: =+SUM(F38:I38) -> 0 | P38: =+SUM(K38:O38) -> 0 | Q38: =+J38+P38 -> 0 | R38: =+E38+Q38 -> 0
A39: 18 | E39: =+SUM(B39:D39) -> 0 | J39: =+SUM(F39:I39) -> 0 | P39: =+SUM(K39:O39) -> 0 | Q39: =+J39+P39 -> 0 | R39: =+E39+Q39 -> 0
A40: 19 | E40: =+SUM(B40:D40) -> 0 | J40: =+SUM(F40:I40) -> 0 | P40: =+SUM(K40:O40) -> 0 | Q40: =+J40+P40 -> 0 | R40: =+E40+Q40 -> 0
A41: 20 | E41: =+SUM(B41:D41) -> 0 | J41: =+SUM(F41:I41) -> 0 | P41: =+SUM(K41:O41) -> 0 | Q41: =+J41+P41 -> 0 | R41: =+E41+Q41 -> 0
A42: 21 | E42: =+SUM(B42:D42) -> 0 | J42: =+SUM(F42:I42) -> 0 | P42: =+SUM(K42:O42) -> 0 | Q42: =+J42+P42 -> 0 | R42: =+E42+Q42 -> 0
A43: 22 | D43: 10 | E43: =+SUM(B43:D43) -> 10 | F43: 0.5 | J43: =+SUM(F43:I43) -> 0.5 | P43: =+SUM(K43:O43) -> 0 | Q43: =+J43+P43 -> 0.5 | R43: =+E43+Q43 -> 10.5
A44: 23 | E44: =+SUM(B44:D44) -> 0 | J44: =+SUM(F44:I44) -> 0 | P44: =+SUM(K44:O44) -> 0 | Q44: =+J44+P44 -> 0 | R44: =+E44+Q44 -> 0
A45: 24 | E45: =+SUM(B45:D45) -> 0 | J45: =+SUM(F45:I45) -> 0 | P45: =+SUM(K45:O45) -> 0 | Q45: =+J45+P45 -> 0 | R45: =+E45+Q45 -> 0
A46: 25 | E46: =+SUM(B46:D46) -> 0 | J46: =+SUM(F46:I46) -> 0 | P46: =+SUM(K46:O46) -> 0 | Q46: =+J46+P46 -> 0 | R46: =+E46+Q46 -> 0
A47: 26 | E47: =+SUM(B47:D47) -> 0 | J47: =+SUM(F47:I47) -> 0 | P47: =+SUM(K47:O47) -> 0 | Q47: =+J47+P47 -> 0 | R47: =+E47+Q47 -> 0
A48: 27 | E48: =+SUM(B48:D48) -> 0 | J48: =+SUM(F48:I48) -> 0 | P48: =+SUM(K48:O48) -> 0 | Q48: =+J48+P48 -> 0 | R48: =+E48+Q48 -> 0
...

Sheet Febrero
D1: FORMATO REGISTRO ANUAL DE GENERACION DE RESIDUOS GENERADOS EN LA ATENCION EN SALUD Y OTRAS ACTIVIDADES | Q1: Version 2.0
Q3: Fecha: 08/03/2022
Q5: CODIGO
A7: 1. Nombre del Generador | D7: GESTAR SALUD CIENAGA DE ORO - CONTRIBUTIVO | K7: 6. Correo Electronico | N7: SEDECIENAGA@GESTARSALUDIPS.COM
A8: 2. Ciudad | D8: CIENAGA DE ORO | K8: 7. Responsable del diligenciamiento | N8: YULIS DURANGO
A9: 3. Departamento | D9: CORDOBA | K9: 8. Cargo | N9: SERVICIOS GENERALES
A10: 4. Direccion | D10: CALLE 7 14-16 BARRIO CENTRO | K10: 9. Mes: | N10: FEBRERO
A11: 5. Telefono
A16: CONSOLIDACION RESIDUOS POR ESTABLECIMIENTO GENERADOR DE RESIDUOS
B18: 10 | C18: 11 | D18: 12 | E18: 13 | F18: 14 | G18: 15 | H18: 16 | I18: 17 | J18: 18 | K18: 19 | L18: 20 | M18: 21 | N18: 22 | O18: 23 | P18: 24 | Q18: 0 | R18: 26
A19: DÍA | B19: RESIDUOS NO PELIGROS | E19: Subtotal Residuos no peligrosos | F19: RESIDUOS PELIGROSOS | Q19: Subtotal Residuos Peligrosos | R19: TOTAL
F20: INFECCIOSO O RIESGO BIOLOGICO | J20: Subtotal residuos de riesgo biologico o infeccioso | K20: OTROS RESIDUOS CON LAS SIGUIENTES CARACTERISTICAS | P20: Subtotal otros residuos
B21: BIODEGRADABLES (KG/DÍA) | C21: RECICLABLES (KG/DÍA) | D21: ORDINARIOS (KG/DÍA) | F21: BIOSANITARIOS (KG/DÍA) | G21: ANATOMOPATOLOGICOS (KG/DÍA) | H21: CORTOPUNZANTES (KG/DÍA) | I21: ANIMALES (KG/DÍA) | K21: CORROSIVA (KG/DÍA) | L21: EXPLOSIVO (KG/DÍA) | M21: TOXICO (KG/DÍA) | N21: INFLAMABLE (KG/DÍA) | O21: REACTIVO (KG/DÍA)
A22: 1 | E22: =+SUM(B22:D22) -> 0 | J22: =+SUM(F22:I22) -> 0 | P22: =+SUM(K22:O22) -> 0 | Q22: =+J22+P22 -> 0 | R22: =+E22+Q22 -> 0
A23: 2 | E23: =+SUM(B23:D23) -> 0 | J23: =+SUM(F23:I23) -> 0 | P23: =+SUM(K23:O23) -> 0 | Q23: =+J23+P23 -> 0 | R23: =+E23+Q23 -> 0
A24: 3 | E24: =+SUM(B24:D24) -> 0 | J24: =+SUM(F24:I24) -> 0 | P24: =+SUM(K24:O24) -> 0 | Q24: =+J24+P24 -> 0 | R24: =+E24+Q24 -> 0
A25: 4 | E25: =+SUM(B25:D25) -> 0 | J25: =+SUM(F25:I25) -> 0 | P25: =+SUM(K25:O25) -> 0 | Q25: =+J25+P25 -> 0 | R25: =+E25+Q25 -> 0
A26: 5 | D26: 9 | E26: =+SUM(B26:D26) -> 9 | F26: 0.45 | J26: =+SUM(F26:I26) -> 0.45 | P26: =+SUM(K26:O26) -> 0 | Q26: =+J26+P26 -> 0.45 | R26: =+E26+Q26 -> 9.45
A27: 6 | E27: =+SUM(B27:D27) -> 0 | J27: =+SUM(F27:I27) -> 0 | P27: =+SUM(K27:O27) -> 0 | Q27: =+J27+P27 -> 0 | R27: =+E27+Q27 -> 0
A28: 7 | E28: =+SUM(B28:D28) -> 0 | J28: =+SUM(F28:I28) -> 0 | P28: =+SUM(K28:O28) -> 0 | Q28: =+J28+P28 -> 0 | R28: =+E28+Q28 -> 0
A29: 8 | E29: =+SUM(B29:D29) -> 0 | J29: =+SUM(F29:I29) -> 0 | P29: =+SUM(K29:O29) -> 0 | Q29: =+J29+P29 -> 0 | R29: =+E29+Q29 -> 0
A30: 9 | E30: =+SUM(B30:D30) -> 0 | J30: =+SUM(F30:I30) -> 0 | P30: =+SUM(K30:O30) -> 0 | Q30: =+J30+P30 -> 0 | R30: =+E30+Q30 -> 0
A31: 10 | E31: =+SUM(B31:D31) -> 0 | J31: =+SUM(F31:I31) -> 0 | P31: =+SUM(K31:O31) -> 0 | Q31: =+J31+P31 -> 0 | R31: =+E31+Q31 -> 0
A32: 11 | E32: =+SUM(B32:D32) -> 0 | J32: =+SUM(F32:I32) -> 0 | P32: =+SUM(K32:O32) -> 0 | Q32: =+J32+P32 -> 0 | R32: =+E32+Q32 -> 0
A33: 12 | E33: =+SUM(B33:D33) -> 0 | J33: =+SUM(F33:I33) -> 0 | P33: =+SUM(K33:O33) -> 0 | Q33: =+J33+P33 -> 0 | R33: =+E33+Q33 -> 0
A34: 13 | E34: =+SUM(B34:D34) -> 0 | J34: =+SUM(F34:I34) -> 0 | P34: =+SUM(K34:O34) -> 0 | Q34: =+J34+P34 -> 0 | R34: =+E34+Q34 -> 0
A35: 14 | E35: =+SUM(B35:D35) -> 0 | J35: =+SUM(F35:I35) -> 0 | P35: =+SUM(K35:O35) -> 0 | Q35: =+J35+P35 -> 0 | R35: =+E35+Q35 -> 0
A36: 15 | E36: =+SUM(B36:D36) -> 0 | J36: =+SUM(F36:I36) -> 0 | P36: =+SUM(K36:O36) -> 0 | Q36: =+J36+P36 -> 0 | R36: =+E36+Q36 -> 0
A37: 16 | E37: =+SUM(B37:D37) -> 0 | J37: =+SUM(F37:I37) -> 0 | P37: =+SUM(K37:O37) -> 0 | Q37: =+J37+P37 -> 0 | R37: =+E37+Q37 -> 0
A38: 17 | E38: =+SUM(B38:D38) -> 0 | J38: =+SUM(F38:I38) -> 0 | P38: =+SUM(K38:O38) -> 0 | Q38: =+J38+P38 -> 0 | R38: =+E38+Q38 -> 0
A39: 18 | E39: =+SUM(B39:D39) -> 0 | J39: =+SUM(F39:I39) -> 0 | P39: =+SUM(K39:O39) -> 0 | Q39: =+J39+P39 -> 0 | R39: =+E39+Q39 -> 0
A40: 19 | D40: 11 | E40: =+SUM(B40:D40) -> 11 | H40: 0.4 | J40: =+SUM(F40:I40) -> 0.4 | P40: =+SUM(K40:O40) -> 0 | Q40: =+J40+P40 -> 0.4 | R40: =+E40+Q40 -> 11.4
A41: 20 | E41: =+SUM(B41:D41) -> 0 | J41: =+SUM(F41:I41) -> 0 | P41: =+SUM(K41:O41) -> 0 | Q41: =+J41+P41 -> 0 | R41: =+E41+Q41 -> 0
A42: 21 | E42: =+SUM(B42:D42) -> 0 | J42: =+SUM(F42:I42) -> 0 | P42: =+SUM(K42:O42) -> 0 | Q42: =+J42+P42 -> 0 | R42: =+E42+Q42 -> 0
A43: 22 | E43: =+SUM(B43:D43) -> 0 | J43: =+SUM(F43:I43) -> 0 | P43: =+SUM(K43:O43) -> 0 | Q43: =+J43+P43 -> 0 | R43: =+E43+Q43 -> 0
A44: 23 | E44: =+SUM(B44:D44) -> 0 | J44: =+SUM(F44:I44) -> 0 | P44: =+SUM(K44:O44) -> 0 | Q44: =+J44+P44 -> 0 | R44: =+E44+Q44 -> 0
A45: 24 | E45: =+SUM(B45:D45) -> 0 | J45: =+SUM(F45:I45) -> 0 | P45: =+SUM(K45:O45) -> 0 | Q45: =+J45+P45 -> 0 | R45: =+E45+Q45 -> 0
A46: 25 | E46: =+SUM(B46:D46) -> 0 | J46: =+SUM(F46:I46) -> 0 | P46: =+SUM(K46:O46) -> 0 | Q46: =+J46+P46 -> 0 | R46: =+E46+Q46 -> 0
A47: 26 | E47: =+SUM(B47:D47) -> 0 | J47: =+SUM(F47:I47) -> 0 | P47: =+SUM(K47:O47) -> 0 | Q47: =+J47+P47 -> 0 | R47: =+E47+Q47 -> 0
A48: 27 | E48: =+SUM(B48:D48) -> 0 | J48: =+SUM(F48:I48) -> 0 | P48: =+SUM(K48:O48) -> 0 | Q48: =+J48+P48 -> 0 | R48: =+E48+Q48 -> 0
...

Sheet Marzo
D1: FORMATO REGISTRO ANUAL DE GENERACION DE RESIDUOS GENERADOS EN LA ATENCION EN SALUD Y OTRAS ACTIVIDADES | Q1: Version 2.0
Q3: Fecha: 08/03/2022
Q5: CODIGO
A7: 1. Nombre del Generador | D7: GESTAR SALUD CIENAGA DE ORO- CONTRIBUTIVO | K7: 6. Correo Electronico | N7: SEDECIENAGA@GESTARSALUDIPS.COM
A8: 2. Ciudad | D8: CIENAGA DE ORO | K8: 7. Responsable del diligenciamiento | N8: YULIS DURANGO
A9: 3. Departamento | D9: CORDOBA | K9: 8. Cargo | N9: SERVICIOS GENERALES
A10: 4. Direccion | D10: CALLE 7 14-16 BARRIO CENTRO | K10: 9. Mes: | N10: MARZO
A11: 5. Telefono
A16: CONSOLIDACION RESIDUOS POR ESTABLECIMIENTO GENERADOR DE RESIDUOS
B18: 10 | C18: 11 | D18: 12 | E18: 13 | F18: 14 | G18: 15 | H18: 16 | I18: 17 | J18: 18 | K18: 19 | L18: 20 | M18: 21 | N18: 22 | O18: 23 | P18: 24 | Q18: 0 | R18: 26
A19: DÍA | B19: RESIDUOS NO PELIGROS | E19: Subtotal Residuos no peligrosos | F19: RESIDUOS PELIGROSOS | Q19: Subtotal Residuos Peligrosos | R19: TOTAL
F20: INFECCIOSO O RIESGO BIOLOGICO | J20: Subtotal residuos de riesgo biologico o infeccioso | K20: OTROS RESIDUOS CON LAS SIGUIENTES CARACTERISTICAS | P20: Subtotal otros residuos
B21: BIODEGRADABLES (KG/DÍA) | C21: RECICLABLES (KG/DÍA) | D21: ORDINARIOS (KG/DÍA) | F21: BIOSANITARIOS (KG/DÍA) | G21: ANATOMOPATOLOGICOS (KG/DÍA) | H21: CORTOPUNZANTES (KG/DÍA) | I21: ANIMALES (KG/DÍA) | K21: CORROSIVA (KG/DÍA) | L21: EXPLOSIVO (KG/DÍA) | M21: TOXICO (KG/DÍA) | N21: INFLAMABLE (KG/DÍA) | O21: REACTIVO (KG/DÍA)
A22: 1 | E22: =+SUM(B22:D22) -> 0 | J22: =+SUM(F22:I22) -> 0 | P22: =+SUM(K22:O22) -> 0 | Q22: =+J22+P22 -> 0 | R22: =+E22+Q22 -> 0
A23: 2 | E23: =+SUM(B23:D23) -> 0 | J23: =+SUM(F23:I23) -> 0 | P23: =+SUM(K23:O23) -> 0 | Q23: =+J23+P23 -> 0 | R23: =+E23+Q23 -> 0
A24: 3 | E24: =+SUM(B24:D24) -> 0 | J24: =+SUM(F24:I24) -> 0 | P24: =+SUM(K24:O24) -> 0 | Q24: =+J24+P24 -> 0 | R24: =+E24+Q24 -> 0
A25: 4 | E25: =+SUM(B25:D25) -> 0 | J25: =+SUM(F25:I25) -> 0 | P25: =+SUM(K25:O25) -> 0 | Q25: =+J25+P25 -> 0 | R25: =+E25+Q25 -> 0
A26: 5 | D26: 11.2 | E26: =+SUM(B26:D26) -> 11.2 | H26: 0.7 | J26: =+SUM(F26:I26) -> 0.7 | P26: =+SUM(K26:O26) -> 0 | Q26: =+J26+P26 -> 0.7 | R26: =+E26+Q26 -> 11.9
A27: 6 | E27: =+SUM(B27:D27) -> 0 | J27: =+SUM(F27:I27) -> 0 | P27: =+SUM(K27:O27) -> 0 | Q27: =+J27+P27 -> 0 | R27: =+E27+Q27 -> 0
A28: 7 | E28: =+SUM(B28:D28) -> 0 | J28: =+SUM(F28:I28) -> 0 | P28: =+SUM(K28:O28) -> 0 | Q28: =+J28+P28 -> 0 | R28: =+E28+Q28 -> 0
A29: 8 | E29: =+SUM(B29:D29) -> 0 | J29: =+SUM(F29:I29) -> 0 | P29: =+SUM(K29:O29) -> 0 | Q29: =+J29+P29 -> 0 | R29: =+E29+Q29 -> 0
A30: 9 | E30: =+SUM(B30:D30) -> 0 | J30: =+SUM(F30:I30) -> 0 | P30: =+SUM(K30:O30) -> 0 | Q30: =+J30+P30 -> 0 | R30: =+E30+Q30 -> 0
A31: 10 | E31: =+SUM(B31:D31) -> 0 | J31: =+SUM(F31:I31) -> 0 | P31: =+SUM(K31:O31) -> 0 | Q31: =+J31+P31 -> 0 | R31: =+E31+Q31 -> 0
A32: 11 | E32: =+SUM(B32:D32) -> 0 | J32: =+SUM(F32:I32) -> 0 | P32: =+SUM(K32:O32) -> 0 | Q32: =+J32+P32 -> 0 | R32: =+E32+Q32 -> 0
A33: 12 | E33: =+SUM(B33:D33) -> 0 | J33: =+SUM(F33:I33) -> 0 | P33: =+SUM(K33:O33) -> 0 | Q33: =+J33+P33 -> 0 | R33: =+E33+Q33 -> 0
A34: 13 | E34: =+SUM(B34:D34) -> 0 | J34: =+SUM(F34:I34) -> 0 | P34: =+SUM(K34:O34) -> 0 | Q34: =+J34+P34 -> 0 | R34: =+E34+Q34 -> 0
A35: 14 | E35: =+SUM(B35:D35) -> 0 | J35: =+SUM(F35:I35) -> 0 | P35: =+SUM(K35:O35) -> 0 | Q35: =+J35+P35 -> 0 | R35: =+E35+Q35 -> 0
A36: 15 | E36: =+SUM(B36:D36) -> 0 | J36: =+SUM(F36:I36) -> 0 | P36: =+SUM(K36:O36) -> 0 | Q36: =+J36+P36 -> 0 | R36: =+E36+Q36 -> 0
A37: 16 | E37: =+SUM(B37:D37) -> 0 | J37: =+SUM(F37:I37) -> 0 | P37: =+SUM(K37:O37) -> 0 | Q37: =+J37+P37 -> 0 | R37: =+E37+Q37 -> 0
A38: 17 | E38: =+SUM(B38:D38) -> 0 | J38: =+SUM(F38:I38) -> 0 | P38: =+SUM(K38:O38) -> 0 | Q38: =+J38+P38 -> 0 | R38: =+E38+Q38 -> 0
A39: 18 | E39: =+SUM(B39:D39) -> 0 | J39: =+SUM(F39:I39) -> 0 | P39: =+SUM(K39:O39) -> 0 | Q39: =+J39+P39 -> 0 | R39: =+E39+Q39 -> 0
A40: 19 | D40: 10 | E40: =+SUM(B40:D40) -> 10 | J40: =+SUM(F40:I40) -> 0 | P40: =+SUM(K40:O40) -> 0 | Q40: =+J40+P40 -> 0 | R40: =+E40+Q40 -> 10
A41: 20 | E41: =+SUM(B41:D41) -> 0 | J41: =+SUM(F41:I41) -> 0 | P41: =+SUM(K41:O41) -> 0 | Q41: =+J41+P41 -> 0 | R41: =+E41+Q41 -> 0
A42: 21 | E42: =+SUM(B42:D42) -> 0 | J42: =+SUM(F42:I42) -> 0 | P42: =+SUM(K42:O42) -> 0 | Q42: =+J42+P42 -> 0 | R42: =+E42+Q42 -> 0
A43: 22 | E43: =+SUM(B43:D43) -> 0 | J43: =+SUM(F43:I43) -> 0 | P43: =+SUM(K43:O43) -> 0 | Q43: =+J43+P43 -> 0 | R43: =+E43+Q43 -> 0
A44: 23 | E44: =+SUM(B44:D44) -> 0 | J44: =+SUM(F44:I44) -> 0 | P44: =+SUM(K44:O44) -> 0 | Q44: =+J44+P44 -> 0 | R44: =+E44+Q44 -> 0
A45: 24 | E45: =+SUM(B45:D45) -> 0 | J45: =+SUM(F45:I45) -> 0 | P45: =+SUM(K45:O45) -> 0 | Q45: =+J45+P45 -> 0 | R45: =+E45+Q45 -> 0
A46: 25 | E46: =+SUM(B46:D46) -> 0 | J46: =+SUM(F46:I46) -> 0 | P46: =+SUM(K46:O46) -> 0 | Q46: =+J46+P46 -> 0 | R46: =+E46+Q46 -> 0
A47: 26 | E47: =+SUM(B47:D47) -> 0 | J47: =+SUM(F47:I47) -> 0 | P47: =+SUM(K47:O47) -> 0 | Q47: =+J47+P47 -> 0 | R47: =+E47+Q47 -> 0
A48: 27 | E48: =+SUM(B48:D48) -> 0 | J48: =+SUM(F48:I48) -> 0 | P48: =+SUM(K48:O48) -> 0 | Q48: =+J48+P48 -> 0 | R48: =+E48+Q48 -> 0
...

Sheet Abril
D1: FORMATO REGISTRO ANUAL DE GENERACION DE RESIDUOS GENERADOS EN LA ATENCION EN SALUD Y OTRAS ACTIVIDADES | Q1: Version 2.0
Q3: Fecha: 08/03/2022
Q5: CODIGO
A7: 1. Nombre del Generador | D7: GESTAR SALUD CIENAGA DE ORO- CONTRIBUTIVO | K7: 6. Correo Electronico | N7: SEDECIENAGA@GESTARSALUDIPS.COM
A8: 2. Ciudad | D8: CIENAGA DE ORO | K8: 7. Responsable del diligenciamiento | N8: YULIS DURANGO
A9: 3. Departamento | D9: CORDOBA | K9: 8. Cargo | N9: SERVICIOS GENERALES
A10: 4. Direccion | D10: CALLE 7 14-16 BARRIO CENTRO | K10: 9. Mes: | N10: ABRIL
A11: 5. Telefono
A16: CONSOLIDACION RESIDUOS POR ESTABLECIMIENTO GENERADOR DE RESIDUOS
B18: 10 | C18: 11 | D18: 12 | E18: 13 | F18: 14 | G18: 15 | H18: 16 | I18: 17 | J18: 18 | K18: 19 | L18: 20 | M18: 21 | N18: 22 | O18: 23 | P18: 24 | Q18: 0 | R18: 26
A19: DÍA | B19: RESIDUOS NO PELIGROS | E19: Subtotal Residuos no peligrosos | F19: RESIDUOS PELIGROSOS | Q19: Subtotal Residuos Peligrosos | R19: TOTAL
F20: INFECCIOSO O RIESGO BIOLOGICO | J20: Subtotal residuos de riesgo biologico o infeccioso | K20: OTROS RESIDUOS CON LAS SIGUIENTES CARACTERISTICAS | P20: Subtotal otros residuos
B21: BIODEGRADABLES (KG/DÍA) | C21: RECICLABLES (KG/DÍA) | D21: ORDINARIOS (KG/DÍA) | F21: BIOSANITARIOS (KG/DÍA) | G21: ANATOMOPATOLOGICOS (KG/DÍA) | H21: CORTOPUNZANTES (KG/DÍA) | I21: ANIMALES (KG/DÍA) | K21: CORROSIVA (KG/DÍA) | L21: EXPLOSIVO (KG/DÍA) | M21: TOXICO (KG/DÍA) | N21: INFLAMABLE (KG/DÍA) | O21: REACTIVO (KG/DÍA)
A22: 1 | E22: =+SUM(B22:D22) -> 0 | J22: =+SUM(F22:I22) -> 0 | P22: =+SUM(K22:O22) -> 0 | Q22: =+J22+P22 -> 0 | R22: =+E22+Q22 -> 0
A23: 2 | E23: =+SUM(B23:D23) -> 0 | J23: =+SUM(F23:I23) -> 0 | P23: =+SUM(K23:O23) -> 0 | Q23: =+J23+P23 -> 0 | R23: =+E23+Q23 -> 0
A24: 3 | E24: =+SUM(B24:D24) -> 0 | J24: =+SUM(F24:I24) -> 0 | P24: =+SUM(K24:O24) -> 0 | Q24: =+J24+P24 -> 0 | R24: =+E24+Q24 -> 0
A25: 4 | E25: =+SUM(B25:D25) -> 0 | J25: =+SUM(F25:I25) -> 0 | P25: =+SUM(K25:O25) -> 0 | Q25: =+J25+P25 -> 0 | R25: =+E25+Q25 -> 0
A26: 5 | E26: =+SUM(B26:D26) -> 0 | J26: =+SUM(F26:I26) -> 0 | P26: =+SUM(K26:O26) -> 0 | Q26: =+J26+P26 -> 0 | R26: =+E26+Q26 -> 0
A27: 6 | E27: =+SUM(B27:D27) -> 0 | J27: =+SUM(F27:I27) -> 0 | P27: =+SUM(K27:O27) -> 0 | Q27: =+J27+P27 -> 0 | R27: =+E27+Q27 -> 0
A28: 7 | E28: =+SUM(B28:D28) -> 0 | J28: =+SUM(F28:I28) -> 0 | P28: =+SUM(K28:O28) -> 0 | Q28: =+J28+P28 -> 0 | R28: =+E28+Q28 -> 0
A29: 8 | E29: =+SUM(B29:D29) -> 0 | J29: =+SUM(F29:I29) -> 0 | P29: =+SUM(K29:O29) -> 0 | Q29: =+J29+P29 -> 0 | R29: =+E29+Q29 -> 0
A30: 9 | E30: =+SUM(B30:D30) -> 0 | J30: =+SUM(F30:I30) -> 0 | P30: =+SUM(K30:O30) -> 0 | Q30: =+J30+P30 -> 0 | R30: =+E30+Q30 -> 0
A31: 10 | E31: =+SUM(B31:D31) -> 0 | J31: =+SUM(F31:I31) -> 0 | P31: =+SUM(K31:O31) -> 0 | Q31: =+J31+P31 -> 0 | R31: =+E31+Q31 -> 0
A32: 11 | E32: =+SUM(B32:D32) -> 0 | J32: =+SUM(F32:I32) -> 0 | P32: =+SUM(K32:O32) -> 0 | Q32: =+J32+P32 -> 0 | R32: =+E32+Q32 -> 0
A33: 12 | E33: =+SUM(B33:D33) -> 0 | J33: =+SUM(F33:I33) -> 0 | P33: =+SUM(K33:O33) -> 0 | Q33: =+J33+P33 -> 0 | R33: =+E33+Q33 -> 0
... A36: 15 | E36: =+SUM(B36:D36) -> 0 | J36: =+SUM(F36:I36) -> 0 | P36: =+SUM(K36:O36) -> 0 | Q36: =+J36+P36 -> 0 | R36: =+E36+Q36 -> 0
A37: 16 | D37: 10 | E37: =+SUM(B37:D37) -> 10 | J37: =+SUM(F37:I37) -> 0 | P37: =+SUM(K37:O37) -> 0 | Q37: =+J37+P37 -> 0 | R37: =+E37+Q37 -> 10
A38: 17 | E38: =+SUM(B38:D38) -> 0 | J38: =+SUM(F38:I38) -> 0 | P38: =+SUM(K38:O38) -> 0 | Q38: =+J38+P38 -> 0 | R38: =+E38+Q38 -> 0
A39: 18 | E39: =+SUM(B39:D39) -> 0 | J39: =+SUM(F39:I39) -> 0 | P39: =+SUM(K39:O39) -> 0 | Q39: =+J39+P39 -> 0 | R39: =+E39+Q39 -> 0
A40: 19 | E40: =+SUM(B40:D40) -> 0 | J40: =+SUM(F40:I40) -> 0 | P40: =+SUM(K40:O40) -> 0 | Q40: =+J40+P40 -> 0 | R40: =+E40+Q40 -> 0
A41: 20 | E41: =+SUM(B41:D41) -> 0 | J41: =+SUM(F41:I41) -> 0 | P41: =+SUM(K41:O41) -> 0 | Q41: =+J41+P41 -> 0 | R41: =+E41+Q41 -> 0
A42: 21 | E42: =+SUM(B42:D42) -> 0 | J42: =+SUM(F42:I42) -> 0 | P42: =+SUM(K42:O42) -> 0 | Q42: =+J42+P42 -> 0 | R42: =+E42+Q42 -> 0
A43: 22 | E43: =+SUM(B43:D43) -> 0 | J43: =+SUM(F43:I43) -> 0 | P43: =+SUM(K43:O43) -> 0 | Q43: =+J43+P43 -> 0 | R43: =+E43+Q43 -> 0
A44: 23 | E44: =+SUM(B44:D44) -> 0 | J44: =+SUM(F44:I44) -> 0 | P44: =+SUM(K44:O44) -> 0 | Q44: =+J44+P44 -> 0 | R44: =+E44+Q44 -> 0
A45: 24 | E45: =+SUM(B45:D45) -> 0 | J45: =+SUM(F45:I45) -> 0 | P45: =+SUM(K45:O45) -> 0 | Q45: =+J45+P45 -> 0 | R45: =+E45+Q45 -> 0
A46: 25 | E46: =+SUM(B46:D46) -> 0 | J46: =+SUM(F46:I46) -> 0 | P46: =+SUM(K46:O46) -> 0 | Q46: =+J46+P46 -> 0 | R46: =+E46+Q46 -> 0
A47: 26 | E47: =+SUM(B47:D47) -> 0 | J47: =+SUM(F47:I47) -> 0 | P47: =+SUM(K47:O47) -> 0 | Q47: =+J47+P47 -> 0 | R47: =+E47+Q47 -> 0
A48: 27 | E48: =+SUM(B48:D48) -> 0 | J48: =+SUM(F48:I48) -> 0 | P48: =+SUM(K48:O48) -> 0 | Q48: =+J48+P48 -> 0 | R48: =+E48+Q48 -> 0
A49: 28 | E49: =+SUM(B49:D49) -> 0 | J49: =+SUM(F49:I49) -> 0 | P49: =+SUM(K49:O49) -> 0 | Q49: =+J49+P49 -> 0 | R49: =+E49+Q49 -> 0
A50: 29 | E50: =+SUM(B50:D50) -> 0 | J50: =+SUM(F50:I50) -> 0 | P50: =+SUM(K50:O50) -> 0 | Q50: =+J50+P50 -> 0 | R50: =+E50+Q50 -> 0
...

Sheet Mayo
D1: FORMATO REGISTRO ANUAL DE GENERACION DE RESIDUOS GENERADOS EN LA ATENCION EN SALUD Y OTRAS ACTIVIDADES | Q1: Version 2.0
Q3: Fecha: 08/03/2022
Q5: CODIGO
A7: 1. Nombre del Generador | D7: GESTAR SALUD CIENAGA DE ORO CONTRIBUTIVO | K7: 6. Correo Electronico | N7: SEDECIENAGA@GESTARSALUDIPS.COM
A8: 2. Ciudad | D8: CIENAGA DE ORO | K8: 7. Responsable del diligenciamiento | N8: YULIS DURANGO
A9: 3. Departamento | D9: CORDOBA | K9: 8. Cargo | N9: SERVICIOS GENERALES
A10: 4. Direccion | D10: CALLE 7 14-16 BARRIO CENTRO | K10: 9. Mes: | N10: MAYO
A11: 5. Telefono
A16: CONSOLIDACION RESIDUOS POR ESTABLECIMIENTO GENERADOR DE RESIDUOS
B18: 10 | C18: 11 | D18: 12 | E18: 13 | F18: 14 | G18: 15 | H18: 16 | I18: 17 | J18: 18 | K18: 19 | L18: 20 | M18: 21 | N18: 22 | O18: 23 | P18: 24 | Q18: 0 | R18: 26
A19: DÍA | B19: RESIDUOS NO PELIGROS | E19: Subtotal Residuos no peligrosos | F19: RESIDUOS PELIGROSOS | Q19: Subtotal Residuos Peligrosos | R19: TOTAL
F20: INFECCIOSO O RIESGO BIOLOGICO | J20: Subtotal residuos de riesgo biologico o infeccioso | K20: OTROS RESIDUOS CON LAS SIGUIENTES CARACTERISTICAS | P20: Subtotal otros residuos
B21: BIODEGRADABLES (KG/DÍA) | C21: RECICLABLES (KG/DÍA) | D21: ORDINARIOS (KG/DÍA) | F21: BIOSANITARIOS (KG/DÍA) | G21: ANATOMOPATOLOGICOS (KG/DÍA) | H21: CORTOPUNZANTES (KG/DÍA) | I21: ANIMALES (KG/DÍA) | K21: CORROSIVA (KG/DÍA) | L21: EXPLOSIVO (KG/DÍA) | M21: TOXICO (KG/DÍA) | N21: INFLAMABLE (KG/DÍA) | O21: REACTIVO (KG/DÍA)
A22: 1 | E22: =+SUM(B22:D22) -> 0 | J22: =+SUM(F22:I22) -> 0 | P22: =+SUM(K22:O22) -> 0 | Q22: =+J22+P22 -> 0 | R22: =+E22+Q22 -> 0
A23: 2 | E23: =+SUM(B23:D23) -> 0 | J23: =+SUM(F23:I23) -> 0 | P23: =+SUM(K23:O23) -> 0 | Q23: =+J23+P23 -> 0 | R23: =+E23+Q23 -> 0
A24: 3 | E24: =+SUM(B24:D24) -> 0 | J24: =+SUM(F24:I24) -> 0 | P24: =+SUM(K24:O24) -> 0 | Q24: =+J24+P24 -> 0 | R24: =+E24+Q24 -> 0
A25: 4 | E25: =+SUM(B25:D25) -> 0 | J25: =+SUM(F25:I25) -> 0 | P25: =+SUM(K25:O25) -> 0 | Q25: =+J25+P25 -> 0 | R25: =+E25+Q25 -> 0
A26: 5 | E26: =+SUM(B26:D26) -> 0 | J26: =+SUM(F26:I26) -> 0 | P26: =+SUM(K26:O26) -> 0 | Q26: =+J26+P26 -> 0 | R26: =+E26+Q26 -> 0
A27: 6 | E27: =+SUM(B27:D27) -> 0 | J27: =+SUM(F27:I27) -> 0 | P27: =+SUM(K27:O27) -> 0 | Q27: =+J27+P27 -> 0 | R27: =+E27+Q27 -> 0
A28: 7 | E28: =+SUM(B28:D28) -> 0 | J28: =+SUM(F28:I28) -> 0 | P28: =+SUM(K28:O28) -> 0 | Q28: =+J28+P28 -> 0 | R28: =+E28+Q28 -> 0
A29: 8 | E29: =+SUM(B29:D29) -> 0 | J29: =+SUM(F29:I29) -> 0 | P29: =+SUM(K29:O29) -> 0 | Q29: =+J29+P29 -> 0 | R29: =+E29+Q29 -> 0
A30: 9 | E30: =+SUM(B30:D30) -> 0 | J30: =+SUM(F30:I30) -> 0 | P30: =+SUM(K30:O30) -> 0 | Q30: =+J30+P30 -> 0 | R30: =+E30+Q30 -> 0
A31: 10 | E31: =+SUM(B31:D31) -> 0 | J31: =+SUM(F31:I31) -> 0 | P31: =+SUM(K31:O31) -> 0 | Q31: =+J31+P31 -> 0 | R31: =+E31+Q31 -> 0
A32: 11 | E32: =+SUM(B32:D32) -> 0 | J32: =+SUM(F32:I32) -> 0 | P32: =+SUM(K32:O32) -> 0 | Q32: =+J32+P32 -> 0 | R32: =+E32+Q32 -> 0
A33: 12 | E33: =+SUM(B33:D33) -> 0 | J33: =+SUM(F33:I33) -> 0 | P33: =+SUM(K33:O33) -> 0 | Q33: =+J33+P33 -> 0 | R33: =+E33+Q33 -> 0
A34: 13 | E34: =+SUM(B34:D34) -> 0 | J34: =+SUM(F34:I34) -> 0 | P34: =+SUM(K34:O34) -> 0 | Q34: =+J34+P34 -> 0 | R34: =+E34+Q34 -> 0
A35: 14 | D35: 8 | E35: =+SUM(B35:D35) -> 8 | H35: 1 | J35: =+SUM(F35:I35) -> 1 | P35: =+SUM(K35:O35) -> 0 | Q35: =+J35+P35 -> 1 | R35: =+E35+Q35 -> 9
A36: 15 | E36: =+SUM(B36:D36) -> 0 | J36: =+SUM(F36:I36) -> 0 | P36: =+SUM(K36:O36) -> 0 | Q36: =+J36+P36 -> 0 | R36: =+E36+Q36 -> 0
A37: 16 | E37: =+SUM(B37:D37) -> 0 | J37: =+SUM(F37:I37) -> 0 | P37: =+SUM(K37:O37) -> 0 | Q37: =+J37+P37 -> 0 | R37: =+E37+Q37 -> 0
A38: 17 | E38: =+SUM(B38:D38) -> 0 | J38: =+SUM(F38:I38) -> 0 | P38: =+SUM(K38:O38) -> 0 | Q38: =+J38+P38 -> 0 | R38: =+E38+Q38 -> 0
A39: 18 | E39: =+SUM(B39:D39) -> 0 | J39: =+SUM(F39:I39) -> 0 | P39: =+SUM(K39:O39) -> 0 | Q39: =+J39+P39 -> 0 | R39: =+E39+Q39 -> 0
A40: 19 | E40: =+SUM(B40:D40) -> 0 | J40: =+SUM(F40:I40) -> 0 | P40: =+SUM(K40:O40) -> 0 | Q40: =+J40+P40 -> 0 | R40: =+E40+Q40 -> 0
A41: 20 | E41: =+SUM(B41:D41) -> 0 | J41: =+SUM(F41:I41) -> 0 | P41: =+SUM(K41:O41) -> 0 | Q41: =+J41+P41 -> 0 | R41: =+E41+Q41 -> 0
A42: 21 | E42: =+SUM(B42:D42) -> 0 | J42: =+SUM(F42:I42) -> 0 | P42: =+SUM(K42:O42) -> 0 | Q42: =+J42+P42 -> 0 | R42: =+E42+Q42 -> 0
A43: 22 | E43: =+SUM(B43:D43) -> 0 | J43: =+SUM(F43:I43) -> 0 | P43: =+SUM(K43:O43) -> 0 | Q43: =+J43+P43 -> 0 | R43: =+E43+Q43 -> 0
A44: 23 | E44: =+SUM(B44:D44) -> 0 | J44: =+SUM(F44:I44) -> 0 | P44: =+SUM(K44:O44) -> 0 | Q44: =+J44+P44 -> 0 | R44: =+E44+Q44 -> 0
A45: 24 | E45: =+SUM(B45:D45) -> 0 | J45: =+SUM(F45:I45) -> 0 | P45: =+SUM(K45:O45) -> 0 | Q45: =+J45+P45 -> 0 | R45: =+E45+Q45 -> 0
A46: 25 | E46: =+SUM(B46:D46) -> 0 | J46: =+SUM(F46:I46) -> 0 | P46: =+SUM(K46:O46) -> 0 | Q46: =+J46+P46 -> 0 | R46: =+E46+Q46 -> 0
A47: 26 | E47: =+SUM(B47:D47) -> 0 | J47: =+SUM(F47:I47) -> 0 | P47: =+SUM(K47:O47) -> 0 | Q47: =+J47+P47 -> 0 | R47: =+E47+Q47 -> 0
A48: 27 | E48: =+SUM(B48:D48) -> 0 | J48: =+SUM(F48:I48) -> 0 | P48: =+SUM(K48:O48) -> 0 | Q48: =+J48+P48 -> 0 | R48: =+E48+Q48 -> 0
...

Sheet Junio
D1: FORMATO REGISTRO ANUAL DE GENERACION DE RESIDUOS GENERADOS EN LA ATENCION EN SALUD Y OTRAS ACTIVIDADES | Q1: Version 2.0
Q3: Fecha: 08/03/2022
Q5: CODIGO
A7: 1. Nombre del Generador | D7: GESTAR SALUD SEDE CIENAGA CONTRIBUTIVO | K7: 6. Correo Electronico | N7: SEDECIENAGA@GESTARSALUDIPS.COM
A8: 2. Ciudad | D8: CIENAGA DE ORO | K8: 7. Responsable del diligenciamiento | N8: YULIS DURANGO
A9: 3. Departamento | D9: CORDOBA | K9: 8. Cargo | N9: SERVICIOS GENERALES
A10: 4. Direccion | D10: CALLE 7 14-16 BARRIO CENTRO | K10: 9. Mes: | N10: JUNIO
A11: 5. Telefono
A16: CONSOLIDACION RESIDUOS POR ESTABLECIMIENTO GENERADOR DE RESIDUOS
B18: 10 | C18: 11 | D18: 12 | E18: 13 | F18: 14 | G18: 15 | H18: 16 | I18: 17 | J18: 18 | K18: 19 | L18: 20 | M18: 21 | N18: 22 | O18: 23 | P18: 24 | Q18: 0 | R18: 26
A19: DÍA | B19: RESIDUOS NO PELIGROS | E19: Subtotal Residuos no peligrosos | F19: RESIDUOS PELIGROSOS | Q19: Subtotal Residuos Peligrosos | R19: TOTAL
F20: INFECCIOSO O RIESGO BIOLOGICO | J20: Subtotal residuos de riesgo biologico o infeccioso | K20: OTROS RESIDUOS CON LAS SIGUIENTES CARACTERISTICAS | P20: Subtotal otros residuos
B21: BIODEGRADABLES (KG/DÍA) | C21: RECICLABLES (KG/DÍA) | D21: ORDINARIOS (KG/DÍA) | F21: BIOSANITARIOS (KG/DÍA) | G21: ANATOMOPATOLOGICOS (KG/DÍA) | H21: CORTOPUNZANTES (KG/DÍA) | I21: ANIMALES (KG/DÍA) | K21: CORROSIVA (KG/DÍA) | L21: EXPLOSIVO (KG/DÍA) | M21: TOXICO (KG/DÍA) | N21: INFLAMABLE (KG/DÍA) | O21: REACTIVO (KG/DÍA)
A22: 1 | E22: =+SUM(B22:D22) -> 0 | J22: =+SUM(F22:I22) -> 0 | P22: =+SUM(K22:O22) -> 0 | Q22: =+J22+P22 -> 0 | R22: =+E22+Q22 -> 0
A23: 2 | E23: =+SUM(B23:D23) -> 0 | J23: =+SUM(F23:I23) -> 0 | P23: =+SUM(K23:O23) -> 0 | Q23: =+J23+P23 -> 0 | R23: =+E23+Q23 -> 0
A24: 3 | E24: =+SUM(B24:D24) -> 0 | J24: =+SUM(F24:I24) -> 0 | P24: =+SUM(K24:O24) -> 0 | Q24: =+J24+P24 -> 0 | R24: =+E24+Q24 -> 0
A25: 4 | E25: =+SUM(B25:D25) -> 0 | J25: =+SUM(F25:I25) -> 0 | P25: =+SUM(K25:O25) -> 0 | Q25: =+J25+P25 -> 0 | R25: =+E25+Q25 -> 0
A26: 5 | E26: =+SUM(B26:D26) -> 0 | J26: =+SUM(F26:I26) -> 0 | P26: =+SUM(K26:O26) -> 0 | Q26: =+J26+P26 -> 0 | R26: =+E26+Q26 -> 0
A27: 6 | E27: =+SUM(B27:D27) -> 0 | J27: =+SUM(F27:I27) -> 0 | P27: =+SUM(K27:O27) -> 0 | Q27: =+J27+P27 -> 0 | R27: =+E27+Q27 -> 0
A28: 7 | E28: =+SUM(B28:D28) -> 0 | J28: =+SUM(F28:I28) -> 0 | P28: =+SUM(K28:O28) -> 0 | Q28: =+J28+P28 -> 0 | R28: =+E28+Q28 -> 0
A29: 8 | E29: =+SUM(B29:D29) -> 0 | J29: =+SUM(F29:I29) -> 0 | P29: =+SUM(K29:O29) -> 0 | Q29: =+J29+P29 -> 0 | R29: =+E29+Q29 -> 0
A30: 9 | E30: =+SUM(B30:D30) -> 0 | J30: =+SUM(F30:I30) -> 0 | P30: =+SUM(K30:O30) -> 0 | Q30: =+J30+P30 -> 0 | R30: =+E30+Q30 -> 0
A31: 10 | E31: =+SUM(B31:D31) -> 0 | J31: =+SUM(F31:I31) -> 0 | P31: =+SUM(K31:O31) -> 0 | Q31: =+J31+P31 -> 0 | R31: =+E31+Q31 -> 0
A32: 11 | D32: 10 | E32: =+SUM(B32:D32) -> 10 | H32: 0.5 | J32: =+SUM(F32:I32) -> 0.5 | P32: =+SUM(K32:O32) -> 0 | Q32: =+J32+P32 -> 0.5 | R32: =+E32+Q32 -> 10.5
A33: 12 | E33: =+SUM(B33:D33) -> 0 | J33: =+SUM(F33:I33) -> 0 | P33: =+SUM(K33:O33) -> 0 | Q33: =+J33+P33 -> 0 | R33: =+E33+Q33 -> 0
A34: 13 | E34: =+SUM(B34:D34) -> 0 | J34: =+SUM(F34:I34) -> 0 | P34: =+SUM(K34:O34) -> 0 | Q34: =+J34+P34 -> 0 | R34: =+E34+Q34 -> 0
A35: 14 | E35: =+SUM(B35:D35) -> 0 | J35: =+SUM(F35:I35) -> 0 | P35: =+SUM(K35:O35) -> 0 | Q35: =+J35+P35 -> 0 | R35: =+E35+Q35 -> 0
A36: 15 | E36: =+SUM(B36:D36) -> 0 | J36: =+SUM(F36:I36) -> 0 | P36: =+SUM(K36:O36) -> 0 | Q36: =+J36+P36 -> 0 | R36: =+E36+Q36 -> 0
A37: 16 | E37: =+SUM(B37:D37) -> 0 | J37: =+SUM(F37:I37) -> 0 | P37: =+SUM(K37:O37) -> 0 | Q37: =+J37+P37 -> 0 | R37: =+E37+Q37 -> 0
A38: 17 | E38: =+SUM(B38:D38) -> 0 | J38: =+SUM(F38:I38) -> 0 | P38: =+SUM(K38:O38) -> 0 | Q38: =+J38+P38 -> 0 | R38: =+E38+Q38 -> 0
A39: 18 | E39: =+SUM(B39:D39) -> 0 | J39: =+SUM(F39:I39) -> 0 | P39: =+SUM(K39:O39) -> 0 | Q39: =+J39+P39 -> 0 | R39: =+E39+Q39 -> 0
A40: 19 | E40: =+SUM(B40:D40) -> 0 | J40: =+SUM(F40:I40) -> 0 | P40: =+SUM(K40:O40) -> 0 | Q40: =+J40+P40 -> 0 | R40: =+E40+Q40 -> 0
A41: 20 | E41: =+SUM(B41:D41) -> 0 | J41: =+SUM(F41:I41) -> 0 | P41: =+SUM(K41:O41) -> 0 | Q41: =+J41+P41 -> 0 | R41: =+E41+Q41 -> 0
A42: 21 | E42: =+SUM(B42:D42) -> 0 | J42: =+SUM(F42:I42) -> 0 | P42: =+SUM(K42:O42) -> 0 | Q42: =+J42+P42 -> 0 | R42: =+E42+Q42 -> 0
A43: 22 | E43: =+SUM(B43:D43) -> 0 | J43: =+SUM(F43:I43) -> 0 | P43: =+SUM(K43:O43) -> 0 | Q43: =+J43+P43 -> 0 | R43: =+E43+Q43 -> 0
A44: 23 | E44: =+SUM(B44:D44) -> 0 | J44: =+SUM(F44:I44) -> 0 | P44: =+SUM(K44:O44) -> 0 | Q44: =+J44+P44 -> 0 | R44: =+E44+Q44 -> 0
A45: 24 | E45: =+SUM(B45:D45) -> 0 | J45: =+SUM(F45:I45) -> 0 | P45: =+SUM(K45:O45) -> 0 | Q45: =+J45+P45 -> 0 | R45: =+E45+Q45 -> 0
A46: 25 | D46: 10.3 | E46: =+SUM(B46:D46) -> 10.3 | J46: =+SUM(F46:I46) -> 0 | P46: =+SUM(K46:O46) -> 0 | Q46: =+J46+P46 -> 0 | R46: =+E46+Q46 -> 10.3
A47: 26 | E47: =+SUM(B47:D47) -> 0 | J47: =+SUM(F47:I47) -> 0 | P47: =+SUM(K47:O47) -> 0 | Q47: =+J47+P47 -> 0 | R47: =+E47+Q47 -> 0
A48: 27 | E48: =+SUM(B48:D48) -> 0 | J48: =+SUM(F48:I48) -> 0 | P48: =+SUM(K48:O48) -> 0 | Q48: =+J48+P48 -> 0 | R48: =+E48+Q48 -> 0
...

Sheet Julio
D1: FORMATO REGISTRO ANUAL DE GENERACION DE RESIDUOS GENERADOS EN LA ATENCION EN SALUD Y OTRAS ACTIVIDADES | Q1: Version 2.0
Q3: Fecha: 08/03/2022
Q5: CODIGO
A7: 1. Nombre del Generador | D7: GESTAR SALUD CIENAGA DE ORO CONTRIBUTIVO | K7: 6. Correo Electronico | N7: SEDECIENAGA@GESTARSALUDIPS.COM
A8: 2. Ciudad | D8: CIENAGA DE ORO | K8: 7. Responsable del diligenciamiento | N8: YULIS DURANGO
A9: 3. Departamento | D9: CORDOBA | K9: 8. Cargo | N9: SERVICIOS GENERALES
A10: 4. Direccion | D10: CALLE 7 14-16 BARRIO CENTRO | K10: 9. Mes: | N10: JULIO
A11: 5. Telefono
A16: CONSOLIDACION RESIDUOS POR ESTABLECIMIENTO GENERADOR DE RESIDUOS
B18: 10 | C18: 11 | D18: 12 | E18: 13 | F18: 14 | G18: 15 | H18: 16 | I18: 17 | J18: 18 | K18: 19 | L18: 20 | M18: 21 | N18: 22 | O18: 23 | P18: 24 | Q18: 0 | R18: 26
A19: DÍA | B19: RESIDUOS NO PELIGROS | E19: Subtotal Residuos no peligrosos | F19: RESIDUOS PELIGROSOS | Q19: Subtotal Residuos Peligrosos | R19: TOTAL
F20: INFECCIOSO O RIESGO BIOLOGICO | J20: Subtotal residuos de riesgo biologico o infeccioso | K20: OTROS RESIDUOS CON LAS SIGUIENTES CARACTERISTICAS | P20: Subtotal otros residuos
B21: BIODEGRADABLES (KG/DÍA) | C21: RECICLABLES (KG/DÍA) | D21: ORDINARIOS (KG/DÍA) | F21: BIOSANITARIOS (KG/DÍA) | G21: ANATOMOPATOLOGICOS (KG/DÍA) | H21: CORTOPUNZANTES (KG/DÍA) | I21: ANIMALES (KG/DÍA) | K21: CORROSIVA (KG/DÍA) | L21: EXPLOSIVO (KG/DÍA) | M21: TOXICO (KG/DÍA) | N21: INFLAMABLE (KG/DÍA) | O21: REACTIVO (KG/DÍA)
A22: 1 | E22: =+SUM(B22:D22) -> 0 | J22: =+SUM(F22:I22) -> 0 | P22: =+SUM(K22:O22) -> 0 | Q22: =+J22+P22 -> 0 | R22: =+E22+Q22 -> 0
A23: 2 | E23: =+SUM(B23:D23) -> 0 | J23: =+SUM(F23:I23) -> 0 | P23: =+SUM(K23:O23) -> 0 | Q23: =+J23+P23 -> 0 | R23: =+E23+Q23 -> 0
A24: 3 | E24: =+SUM(B24:D24) -> 0 | J24: =+SUM(F24:I24) -> 0 | P24: =+SUM(K24:O24) -> 0 | Q24: =+J24+P24 -> 0 | R24: =+E24+Q24 -> 0
A25: 4 | E25: =+SUM(B25:D25) -> 0 | J25: =+SUM(F25:I25) -> 0 | P25: =+SUM(K25:O25) -> 0 | Q25: =+J25+P25 -> 0 | R25: =+E25+Q25 -> 0
A26: 5 | E26: =+SUM(B26:D26) -> 0 | J26: =+SUM(F26:I26) -> 0 | P26: =+SUM(K26:O26) -> 0 | Q26: =+J26+P26 -> 0 | R26: =+E26+Q26 -> 0
A27: 6 | E27: =+SUM(B27:D27) -> 0 | J27: =+SUM(F27:I27) -> 0 | P27: =+SUM(K27:O27) -> 0 | Q27: =+J27+P27 -> 0 | R27: =+E27+Q27 -> 0
A28: 7 | E28: =+SUM(B28:D28) -> 0 | J28: =+SUM(F28:I28) -> 0 | P28: =+SUM(K28:O28) -> 0 | Q28: =+J28+P28 -> 0 | R28: =+E28+Q28 -> 0
A29: 8 | E29: =+SUM(B29:D29) -> 0 | J29: =+SUM(F29:I29) -> 0 | P29: =+SUM(K29:O29) -> 0 | Q29: =+J29+P29 -> 0 | R29: =+E29+Q29 -> 0
A30: 9 | D30: 9 | E30: =+SUM(B30:D30) -> 9 | H30: 0.5 | J30: =+SUM(F30:I30) -> 0.5 | P30: =+SUM(K30:O30) -> 0 | Q30: =+J30+P30 -> 0.5 | R30: =+E30+Q30 -> 9.5
A31: 10 | E31: =+SUM(B31:D31) -> 0 | J31: =+SUM(F31:I31) -> 0 | P31: =+SUM(K31:O31) -> 0 | Q31: =+J31+P31 -> 0 | R31: =+E31+Q31 -> 0
A32: 11 | E32: =+SUM(B32:D32) -> 0 | J32: =+SUM(F32:I32) -> 0 | P32: =+SUM(K32:O32) -> 0 | Q32: =+J32+P32 -> 0 | R32: =+E32+Q32 -> 0
A33: 12 | E33: =+SUM(B33:D33) -> 0 | J33: =+SUM(F33:I33) -> 0 | P33: =+SUM(K33:O33) -> 0 | Q33: =+J33+P33 -> 0 | R33: =+E33+Q33 -> 0
A34: 13 | E34: =+SUM(B34:D34) -> 0 | J34: =+SUM(F34:I34) -> 0 | P34: =+SUM(K34:O34) -> 0 | Q34: =+J34+P34 -> 0 | R34: =+E34+Q34 -> 0
A35: 14 | E35: =+SUM(B35:D35) -> 0 | J35: =+SUM(F35:I35) -> 0 | P35: =+SUM(K35:O35) -> 0 | Q35: =+J35+P35 -> 0 | R35: =+E35+Q35 -> 0
A36: 15 | E36: =+SUM(B36:D36) -> 0 | J36: =+SUM(F36:I36) -> 0 | P36: =+SUM(K36:O36) -> 0 | Q36: =+J36+P36 -> 0 | R36: =+E36+Q36 -> 0
A37: 16 | E37: =+SUM(B37:D37) -> 0 | J37: =+SUM(F37:I37) -> 0 | P37: =+SUM(K37:O37) -> 0 | Q37: =+J37+P37 -> 0 | R37: =+E37+Q37 -> 0
A38: 17 | E38: =+SUM(B38:D38) -> 0 | J38: =+SUM(F38:I38) -> 0 | P38: =+SUM(K38:O38) -> 0 | Q38: =+J38+P38 -> 0 | R38: =+E38+Q38 -> 0
A39: 18 | E39: =+SUM(B39:D39) -> 0 | J39: =+SUM(F39:I39) -> 0 | P39: =+SUM(K39:O39) -> 0 | Q39: =+J39+P39 -> 0 | R39: =+E39+Q39 -> 0
A40: 19 | E40: =+SUM(B40:D40) -> 0 | J40: =+SUM(F40:I40) -> 0 | P40: =+SUM(K40:O40) -> 0 | Q40: =+J40+P40 -> 0 | R40: =+E40+Q40 -> 0
A41: 20 | E41: =+SUM(B41:D41) -> 0 | J41: =+SUM(F41:I41) -> 0 | P41: =+SUM(K41:O41) -> 0 | Q41: =+J41+P41 -> 0 | R41: =+E41+Q41 -> 0
A42: 21 | E42: =+SUM(B42:D42) -> 0 | J42: =+SUM(F42:I42) -> 0 | P42: =+SUM(K42:O42) -> 0 | Q42: =+J42+P42 -> 0 | R42: =+E42+Q42 -> 0
A43: 22 | E43: =+SUM(B43:D43) -> 0 | J43: =+SUM(F43:I43) -> 0 | P43: =+SUM(K43:O43) -> 0 | Q43: =+J43+P43 -> 0 | R43: =+E43+Q43 -> 0
A44: 23 | D44: 10 | E44: =+SUM(B44:D44) -> 10 | J44: =+SUM(F44:I44) -> 0 | P44: =+SUM(K44:O44) -> 0 | Q44: =+J44+P44 -> 0 | R44: =+E44+Q44 -> 10
A45: 24 | E45: =+SUM(B45:D45) -> 0 | J45: =+SUM(F45:I45) -> 0 | P45: =+SUM(K45:O45) -> 0 | Q45: =+J45+P45 -> 0 | R45: =+E45+Q45 -> 0
A46: 25 | E46: =+SUM(B46:D46) -> 0 | J46: =+SUM(F46:I46) -> 0 | P46: =+SUM(K46:O46) -> 0 | Q46: =+J46+P46 -> 0 | R46: =+E46+Q46 -> 0
A47: 26 | E47: =+SUM(B47:D47) -> 0 | J47: =+SUM(F47:I47) -> 0 | P47: =+SUM(K47:O47) -> 0 | Q47: =+J47+P47 -> 0 | R47: =+E47+Q47 -> 0
A48: 27 | E48: =+SUM(B48:D48) -> 0 | J48: =+SUM(F48:I48) -> 0 | P48: =+SUM(K48:O48) -> 0 | Q48: =+J48+P48 -> 0 | R48: =+E48+Q48 -> 0
...

Sheet Agosto
D1: FORMATO REGISTRO ANUAL DE GENERACION DE RESIDUOS GENERADOS EN LA ATENCION EN SALUD Y OTRAS ACTIVIDADES | Q1: Version 2.0
Q3: Fecha: 08/03/2022
Q5: CODIGO
A7: 1. Nombre del Generador | D7: GESTAR SALUD CIENAGA DE ORO-CONTRIBUTIVO | K7: 6. Correo Electronico | N7: SEDECIENAGA@GESTARSALUDIPS.COM
A8: 2. Ciudad | D8: CIENAGA DE ORO | K8: 7. Responsable del diligenciamiento | N8: YULIS DURANGO
A9: 3. Departamento | D9: CORDOBA | K9: 8. Cargo | N9: SERVICIOS GENERALES
A10: 4. Direccion | D10: CALLE 7 14-16 BARRIO CENTRO | K10: 9. Mes: | N10: AGOSTO
A11: 5. Telefono
A16: CONSOLIDACION RESIDUOS POR ESTABLECIMIENTO GENERADOR DE RESIDUOS
B18: 10 | C18: 11 | D18: 12 | E18: 13 | F18: 14 | G18: 15 | H18: 16 | I18: 17 | J18: 18 | K18: 19 | L18: 20 | M18: 21 | N18: 22 | O18: 23 | P18: 24 | Q18: 0 | R18: 26
A19: DÍA | B19: RESIDUOS NO PELIGROS | E19: Subtotal Residuos no peligrosos | F19: RESIDUOS PELIGROSOS | Q19: Subtotal Residuos Peligrosos | R19: TOTAL
F20: INFECCIOSO O RIESGO BIOLOGICO | J20: Subtotal residuos de riesgo biologico o infeccioso | K20: OTROS RESIDUOS CON LAS SIGUIENTES CARACTERISTICAS | P20: Subtotal otros residuos
B21: BIODEGRADABLES (KG/DÍA) | C21: RECICLABLES (KG/DÍA) | D21: ORDINARIOS (KG/DÍA) | F21: BIOSANITARIOS (KG/DÍA) | G21: ANATOMOPATOLOGICOS (KG/DÍA) | H21: CORTOPUNZANTES (KG/DÍA) | I21: ANIMALES (KG/DÍA) | K21: CORROSIVA (KG/DÍA) | L21: EXPLOSIVO (KG/DÍA) | M21: TOXICO (KG/DÍA) | N21: INFLAMABLE (KG/DÍA) | O21: REACTIVO (KG/DÍA)
A22: 1 | E22: =+SUM(B22:D22) -> 0 | J22: =+SUM(F22:I22) -> 0 | P22: =+SUM(K22:O22) -> 0 | Q22: =+J22+P22 -> 0 | R22: =+E22+Q22 -> 0
A23: 2 | E23: =+SUM(B23:D23) -> 0 | J23: =+SUM(F23:I23) -> 0 | P23: =+SUM(K23:O23) -> 0 | Q23: =+J23+P23 -> 0 | R23: =+E23+Q23 -> 0
A24: 3 | E24: =+SUM(B24:D24) -> 0 | J24: =+SUM(F24:I24) -> 0 | P24: =+SUM(K24:O24) -> 0 | Q24: =+J24+P24 -> 0 | R24: =+E24+Q24 -> 0
A25: 4 | E25: =+SUM(B25:D25) -> 0 | J25: =+SUM(F25:I25) -> 0 | P25: =+SUM(K25:O25) -> 0 | Q25: =+J25+P25 -> 0 | R25: =+E25+Q25 -> 0
A26: 5 | E26: =+SUM(B26:D26) -> 0 | J26: =+SUM(F26:I26) -> 0 | P26: =+SUM(K26:O26) -> 0 | Q26: =+J26+P26 -> 0 | R26: =+E26+Q26 -> 0
A27: 6 | D27: 9.3 | E27: =+SUM(B27:D27) -> 9.3 | J27: =+SUM(F27:I27) -> 0 | P27: =+SUM(K27:O27) -> 0 | Q27: =+J27+P27 -> 0 | R27: =+E27+Q27 -> 9.3
A28: 7 | E28: =+SUM(B28:D28) -> 0 | J28: =+SUM(F28:I28) -> 0 | P28: =+SUM(K28:O28) -> 0 | Q28: =+J28+P28 -> 0 | R28: =+E28+Q28 -> 0
A29: 8 | E29: =+SUM(B29:D29) -> 0 | J29: =+SUM(F29:I29) -> 0 | P29: =+SUM(K29:O29) -> 0 | Q29: =+J29+P29 -> 0 | R29: =+E29+Q29 -> 0
A30: 9 | E30: =+SUM(B30:D30) -> 0 | J30: =+SUM(F30:I30) -> 0 | P30: =+SUM(K30:O30) -> 0 | Q30: =+J30+P30 -> 0 | R30: =+E30+Q30 -> 0
A31: 10 | E31: =+SUM(B31:D31) -> 0 | J31: =+SUM(F31:I31) -> 0 | P31: =+SUM(K31:O31) -> 0 | Q31: =+J31+P31 -> 0 | R31: =+E31+Q31 -> 0
A32: 11 | E32: =+SUM(B32:D32) -> 0 | J32: =+SUM(F32:I32) -> 0 | P32: =+SUM(K32:O32) -> 0 | Q32: =+J32+P32 -> 0 | R32: =+E32+Q32 -> 0
A33: 12 | E33: =+SUM(B33:D33) -> 0 | J33: =+SUM(F33:I33) -> 0 | P33: =+SUM(K33:O33) -> 0 | Q33: =+J33+P33 -> 0 | R33: =+E33+Q33 -> 0
A34: 13 | E34: =+SUM(B34:D34) -> 0 | J34: =+SUM(F34:I34) -> 0 | P34: =+SUM(K34:O34) -> 0 | Q34: =+J34+P34 -> 0 | R34: =+E34+Q34 -> 0
A35: 14 | E35: =+SUM(B35:D35) -> 0 | J35: =+SUM(F35:I35) -> 0 | P35: =+SUM(K35:O35) -> 0 | Q35: =+J35+P35 -> 0 | R35: =+E35+Q35 -> 0
A36: 15 | E36: =+SUM(B36:D36) -> 0 | J36: =+SUM(F36:I36) -> 0 | P36: =+SUM(K36:O36) -> 0 | Q36: =+J36+P36 -> 0 | R36: =+E36+Q36 -> 0
A37: 16 | E37: =+SUM(B37:D37) -> 0 | J37: =+SUM(F37:I37) -> 0 | P37: =+SUM(K37:O37) -> 0 | Q37: =+J37+P37 -> 0 | R37: =+E37+Q37 -> 0
A38: 17 | E38: =+SUM(B38:D38) -> 0 | J38: =+SUM(F38:I38) -> 0 | P38: =+SUM(K38:O38) -> 0 | Q38: =+J38+P38 -> 0 | R38: =+E38+Q38 -> 0
A39: 18 | E39: =+SUM(B39:D39) -> 0 | J39: =+SUM(F39:I39) -> 0 | P39: =+SUM(K39:O39) -> 0 | Q39: =+J39+P39 -> 0 | R39: =+E39+Q39 -> 0
A40: 19 | E40: =+SUM(B40:D40) -> 0 | J40: =+SUM(F40:I40) -> 0 | P40: =+SUM(K40:O40) -> 0 | Q40: =+J40+P40 -> 0 | R40: =+E40+Q40 -> 0
A41: 20 | D41: 7.2 | E41: =+SUM(B41:D41) -> 7.2 | H41: 1 | J41: =+SUM(F41:I41) -> 1 | P41: =+SUM(K41:O41) -> 0 | Q41: =+J41+P41 -> 1 | R41: =+E41+Q41 -> 8.2
A42: 21 | E42: =+SUM(B42:D42) -> 0 | J42: =+SUM(F42:I42) -> 0 | P42: =+SUM(K42:O42) -> 0 | Q42: =+J42+P42 -> 0 | R42: =+E42+Q42 -> 0
A43: 22 | E43: =+SUM(B43:D43) -> 0 | J43: =+SUM(F43:I43) -> 0 | P43: =+SUM(K43:O43) -> 0 | Q43: =+J43+P43 -> 0 | R43: =+E43+Q43 -> 0
A44: 23 | E44: =+SUM(B44:D44) -> 0 | J44: =+SUM(F44:I44) -> 0 | P44: =+SUM(K44:O44) -> 0 | Q44: =+J44+P44 -> 0 | R44: =+E44+Q44 -> 0
A45: 24 | E45: =+SUM(B45:D45) -> 0 | J45: =+SUM(F45:I45) -> 0 | P45: =+SUM(K45:O45) -> 0 | Q45: =+J45+P45 -> 0 | R45: =+E45+Q45 -> 0
A46: 25 | E46: =+SUM(B46:D46) -> 0 | J46: =+SUM(F46:I46) -> 0 | P46: =+SUM(K46:O46) -> 0 | Q46: =+J46+P46 -> 0 | R46: =+E46+Q46 -> 0
A47: 26 | E47: =+SUM(B47:D47) -> 0 | J47: =+SUM(F47:I47) -> 0 | P47: =+SUM(K47:O47) -> 0 | Q47: =+J47+P47 -> 0 | R47: =+E47+Q47 -> 0
A48: 27 | E48: =+SUM(B48:D48) -> 0 | J48: =+SUM(F48:I48) -> 0 | P48: =+SUM(K48:O48) -> 0 | Q48: =+J48+P48 -> 0 | R48: =+E48+Q48 -> 0
...

Sheet Septiembre
D1: FORMATO REGISTRO ANUAL DE GENERACION DE RESIDUOS GENERADOS EN LA ATENCION EN SALUD Y OTRAS ACTIVIDADES | Q1: Version 2.0
Q3: Fecha: 08/03/2022
Q5: CODIGO
A7: 1. Nombre del Generador | D7: GESTAR SALUD CIENAGA DE ORO-CONTRIBUTIVO | K7: 6. Correo Electronico | N7: SEDECIENAGA@GESTARSALUDIPS.COM
A8: 2. Ciudad | D8: CIENAGA DE ORO | K8: 7. Responsable del diligenciamiento | N8: YULIS DURANGO
A9: 3. Departamento | D9: CORDOBA | K9: 8. Cargo | N9: SERVICIOS GENERALES
A10: 4. Direccion | D10: CALLE 7 14-16 BARRIO CENTRO | K10: 9. Mes: | N10: SEPTIEMBRE
A11: 5. Telefono
A16: CONSOLIDACION RESIDUOS POR ESTABLECIMIENTO GENERADOR DE RESIDUOS
B18: 10 | C18: 11 | D18: 12 | E18: 13 | F18: 14 | G18: 15 | H18: 16 | I18: 17 | J18: 18 | K18: 19 | L18: 20 | M18: 21 | N18: 22 | O18: 23 | P18: 24 | Q18: 0 | R18: 26
A19: DÍA | B19: RESIDUOS NO PELIGROS | E19: Subtotal Residuos no peligrosos | F19: RESIDUOS PELIGROSOS | Q19: Subtotal Residuos Peligrosos | R19: TOTAL
F20: INFECCIOSO O RIESGO BIOLOGICO | J20: Subtotal residuos de riesgo biologico o infeccioso | K20: OTROS RESIDUOS CON LAS SIGUIENTES CARACTERISTICAS | P20: Subtotal otros residuos
B21: BIODEGRADABLES (KG/DÍA) | C21: RECICLABLES (KG/DÍA) | D21: ORDINARIOS (KG/DÍA) | F21: BIOSANITARIOS (KG/DÍA) | G21: ANATOMOPATOLOGICOS (KG/DÍA) | H21: CORTOPUNZANTES (KG/DÍA) | I21: ANIMALES (KG/DÍA) | K21: CORROSIVA (KG/DÍA) | L21: EXPLOSIVO (KG/DÍA) | M21: TOXICO (KG/DÍA) | N21: INFLAMABLE (KG/DÍA) | O21: REACTIVO (KG/DÍA)
A22: 1 | E22: =+SUM(B22:D22) -> 0 | J22: =+SUM(F22:I22) -> 0 | P22: =+SUM(K22:O22) -> 0 | Q22: =+J22+P22 -> 0 | R22: =+E22+Q22 -> 0
A23: 2 | E23: =+SUM(B23:D23) -> 0 | J23: =+SUM(F23:I23) -> 0 | P23: =+SUM(K23:O23) -> 0 | Q23: =+J23+P23 -> 0 | R23: =+E23+Q23 -> 0
A24: 3 | D24: 11 | E24: =+SUM(B24:D24) -> 11 | J24: =+SUM(F24:I24) -> 0 | P24: =+SUM(K24:O24) -> 0 | Q24: =+J24+P24 -> 0 | R24: =+E24+Q24 -> 11
A25: 4 | E25: =+SUM(B25:D25) -> 0 | J25: =+SUM(F25:I25) -> 0 | P25: =+SUM(K25:O25) -> 0 | Q25: =+J25+P25 -> 0 | R25: =+E25+Q25 -> 0
A26: 5 | E26: =+SUM(B26:D26) -> 0 | J26: =+SUM(F26:I26) -> 0 | P26: =+SUM(K26:O26) -> 0 | Q26: =+J26+P26 -> 0 | R26: =+E26+Q26 -> 0
A27: 6 | E27: =+SUM(B27:D27) -> 0 | J27: =+SUM(F27:I27) -> 0 | P27: =+SUM(K27:O27) -> 0 | Q27: =+J27+P27 -> 0 | R27: =+E27+Q27 -> 0
A28: 7 | E28: =+SUM(B28:D28) -> 0 | J28: =+SUM(F28:I28) -> 0 | P28: =+SUM(K28:O28) -> 0 | Q28: =+J28+P28 -> 0 | R28: =+E28+Q28 -> 0
A29: 8 | E29: =+SUM(B29:D29) -> 0 | J29: =+SUM(F29:I29) -> 0 | P29: =+SUM(K29:O29) -> 0 | Q29: =+J29+P29 -> 0 | R29: =+E29+Q29 -> 0
A30: 9 | E30: =+SUM(B30:D30) -> 0 | J30: =+SUM(F30:I30) -> 0 | P30: =+SUM(K30:O30) -> 0 | Q30: =+J30+P30 -> 0 | R30: =+E30+Q30 -> 0
A31: 10 | E31: =+SUM(B31:D31) -> 0 | J31: =+SUM(F31:I31) -> 0 | P31: =+SUM(K31:O31) -> 0 | Q31: =+J31+P31 -> 0 | R31: =+E31+Q31 -> 0
A32: 11 | E32: =+SUM(B32:D32) -> 0 | J32: =+SUM(F32:I32) -> 0 | P32: =+SUM(K32:O32) -> 0 | Q32: =+J32+P32 -> 0 | R32: =+E32+Q32 -> 0
A33: 12 | E33: =+SUM(B33:D33) -> 0 | J33: =+SUM(F33:I33) -> 0 | P33: =+SUM(K33:O33) -> 0 | Q33: =+J33+P33 -> 0 | R33: =+E33+Q33 -> 0
A34: 13 | E34: =+SUM(B34:D34) -> 0 | J34: =+SUM(F34:I34) -> 0 | P34: =+SUM(K34:O34) -> 0 | Q34: =+J34+P34 -> 0 | R34: =+E34+Q34 -> 0
A35: 14 | E35: =+SUM(B35:D35) -> 0 | J35: =+SUM(F35:I35) -> 0 | P35: =+SUM(K35:O35) -> 0 | Q35: =+J35+P35 -> 0 | R35: =+E35+Q35 -> 0
A36: 15 | E36: =+SUM(B36:D36) -> 0 | J36: =+SUM(F36:I36) -> 0 | P36: =+SUM(K36:O36) -> 0 | Q36: =+J36+P36 -> 0 | R36: =+E36+Q36 -> 0
A37: 16 | E37: =+SUM(B37:D37) -> 0 | J37: =+SUM(F37:I37) -> 0 | P37: =+SUM(K37:O37) -> 0 | Q37: =+J37+P37 -> 0 | R37: =+E37+Q37 -> 0
A38: 17 | D38: 12 | E38: =+SUM(B38:D38) -> 12 | H38: 1 | J38: =+SUM(F38:I38) -> 1 | P38: =+SUM(K38:O38) -> 0 | Q38: =+J38+P38 -> 1 | R38: =+E38+Q38 -> 13
A39: 18 | E39: =+SUM(B39:D39) -> 0 | J39: =+SUM(F39:I39) -> 0 | P39: =+SUM(K39:O39) -> 0 | Q39: =+J39+P39 -> 0 | R39: =+E39+Q39 -> 0
A40: 19 | E40: =+SUM(B40:D40) -> 0 | J40: =+SUM(F40:I40) -> 0 | P40: =+SUM(K40:O40) -> 0 | Q40: =+J40+P40 -> 0 | R40: =+E40+Q40 -> 0
A41: 20 | E41: =+SUM(B41:D41) -> 0 | J41: =+SUM(F41:I41) -> 0 | P41: =+SUM(K41:O41) -> 0 | Q41: =+J41+P41 -> 0 | R41: =+E41+Q41 -> 0
A42: 21 | E42: =+SUM(B42:D42) -> 0 | J42: =+SUM(F42:I42) -> 0 | P42: =+SUM(K42:O42) -> 0 | Q42: =+J42+P42 -> 0 | R42: =+E42+Q42 -> 0
A43: 22 | E43: =+SUM(B43:D43) -> 0 | J43: =+SUM(F43:I43) -> 0 | P43: =+SUM(K43:O43) -> 0 | Q43: =+J43+P43 -> 0 | R43: =+E43+Q43 -> 0
A44: 23 | E44: =+SUM(B44:D44) -> 0 | J44: =+SUM(F44:I44) -> 0 | P44: =+SUM(K44:O44) -> 0 | Q44: =+J44+P44 -> 0 | R44: =+E44+Q44 -> 0
A45: 24 | E45: =+SUM(B45:D45) -> 0 | J45: =+SUM(F45:I45) -> 0 | P45: =+SUM(K45:O45) -> 0 | Q45: =+J45+P45 -> 0 | R45: =+E45+Q45 -> 0
A46: 25 | E46: =+SUM(B46:D46) -> 0 | J46: =+SUM(F46:I46) -> 0 | P46: =+SUM(K46:O46) -> 0 | Q46: =+J46+P46 -> 0 | R46: =+E46+Q46 -> 0
A47: 26 | E47: =+SUM(B47:D47) -> 0 | J47: =+SUM(F47:I47) -> 0 | P47: =+SUM(K47:O47) -> 0 | Q47: =+J47+P47 -> 0 | R47: =+E47+Q47 -> 0
A48: 27 | E48: =+SUM(B48:D48) -> 0 | J48: =+SUM(F48:I48) -> 0 | P48: =+SUM(K48:O48) -> 0 | Q48: =+J48+P48 -> 0 | R48: =+E48+Q48 -> 0
...

Sheet Octubre
D1: FORMATO REGISTRO ANUAL DE GENERACION DE RESIDUOS GENERADOS EN LA ATENCION EN SALUD Y OTRAS ACTIVIDADES | Q1: Version 2.0
Q3: Fecha: 08/03/2022
Q5: CODIGO
A7: 1. Nombre del Generador | D7: GESTAR SALUD CIENAGA DE ORO CONTRIBUTIVO | K7: 6. Correo Electronico | N7: SEDECIENAGA@GESTARSALUDIPS.COM
A8: 2. Ciudad | D8: CIENAGA DE ORO | K8: 7. Responsable del diligenciamiento | N8: YULIS DURANGO
A9: 3. Departamento | D9: CORDOBA | K9: 8. Cargo | N9: SERVICIOS GENERALES
A10: 4. Direccion | D10: CALLE 7 14-16 BARRIO CENTRO | K10: 9. Mes: | N10: OCTUBRE
A11: 5. Telefono
A16: CONSOLIDACION RESIDUOS POR ESTABLECIMIENTO GENERADOR DE RESIDUOS
B18: 10 | C18: 11 | D18: 12 | E18: 13 | F18: 14 | G18: 15 | H18: 16 | I18: 17 | J18: 18 | K18: 19 | L18: 20 | M18: 21 | N18: 22 | O18: 23 | P18: 24 | Q18: 0 | R18: 26
A19: DÍA | B19: RESIDUOS NO PELIGROS | E19: Subtotal Residuos no peligrosos | F19: RESIDUOS PELIGROSOS | Q19: Subtotal Residuos Peligrosos | R19: TOTAL
F20: INFECCIOSO O RIESGO BIOLOGICO | J20: Subtotal residuos de riesgo biologico o infeccioso | K20: OTROS RESIDUOS CON LAS SIGUIENTES CARACTERISTICAS | P20: Subtotal otros residuos
B21: BIODEGRADABLES (KG/DÍA) | C21: RECICLABLES (KG/DÍA) | D21: ORDINARIOS (KG/DÍA) | F21: BIOSANITARIOS (KG/DÍA) | G21: ANATOMOPATOLOGICOS (KG/DÍA) | H21: CORTOPUNZANTES (KG/DÍA) | I21: ANIMALES (KG/DÍA) | K21: CORROSIVA (KG/DÍA) | L21: EXPLOSIVO (KG/DÍA) | M21: TOXICO (KG/DÍA) | N21: INFLAMABLE (KG/DÍA) | O21: REACTIVO (KG/DÍA)
A22: 1 | E22: =+SUM(B22:D22) -> 0 | J22: =+SUM(F22:I22) -> 0 | P22: =+SUM(K22:O22) -> 0 | Q22: =+J22+P22 -> 0 | R22: =+E22+Q22 -> 0
A23: 2 | E23: =+SUM(B23:D23) -> 0 | J23: =+SUM(F23:I23) -> 0 | P23: =+SUM(K23:O23) -> 0 | Q23: =+J23+P23 -> 0 | R23: =+E23+Q23 -> 0
A24: 3 | E24: =+SUM(B24:D24) -> 0 | J24: =+SUM(F24:I24) -> 0 | P24: =+SUM(K24:O24) -> 0 | Q24: =+J24+P24 -> 0 | R24: =+E24+Q24 -> 0
A25: 4 | E25: =+SUM(B25:D25) -> 0 | J25: =+SUM(F25:I25) -> 0 | P25: =+SUM(K25:O25) -> 0 | Q25: =+J25+P25 -> 0 | R25: =+E25+Q25 -> 0
A26: 5 | E26: =+SUM(B26:D26) -> 0 | J26: =+SUM(F26:I26) -> 0 | P26: =+SUM(K26:O26) -> 0 | Q26: =+J26+P26 -> 0 | R26: =+E26+Q26 -> 0
A27: 6 | E27: =+SUM(B27:D27) -> 0 | J27: =+SUM(F27:I27) -> 0 | P27: =+SUM(K27:O27) -> 0 | Q27: =+J27+P27 -> 0 | R27: =+E27+Q27 -> 0
A28: 7 | E28: =+SUM(B28:D28) -> 0 | J28: =+SUM(F28:I28) -> 0 | P28: =+SUM(K28:O28) -> 0 | Q28: =+J28+P28 -> 0 | R28: =+E28+Q28 -> 0
A29: 8 | E29: =+SUM(B29:D29) -> 0 | J29: =+SUM(F29:I29) -> 0 | P29: =+SUM(K29:O29) -> 0 | Q29: =+J29+P29 -> 0 | R29: =+E29+Q29 -> 0
A30: 9 | E30: =+SUM(B30:D30) -> 0 | J30: =+SUM(F30:I30) -> 0 | P30: =+SUM(K30:O30) -> 0 | Q30: =+J30+P30 -> 0 | R30: =+E30+Q30 -> 0
A31: 10 | E31: =+SUM(B31:D31) -> 0 | J31: =+SUM(F31:I31) -> 0 | P31: =+SUM(K31:O31) -> 0 | Q31: =+J31+P31 -> 0 | R31: =+E31+Q31 -> 0
A32: 11 | E32: =+SUM(B32:D32) -> 0 | J32: =+SUM(F32:I32) -> 0 | P32: =+SUM(K32:O32) -> 0 | Q32: =+J32+P32 -> 0 | R32: =+E32+Q32 -> 0
A33: 12 | E33: =+SUM(B33:D33) -> 0 | J33: =+SUM(F33:I33) -> 0 | P33: =+SUM(K33:O33) -> 0 | Q33: =+J33+P33 -> 0 | R33: =+E33+Q33 -> 0
... A37: 16 | E37: =+SUM(B37:D37) -> 0 | J37: =+SUM(F37:I37) -> 0 | P37: =+SUM(K37:O37) -> 0 | Q37: =+J37+P37 -> 0 | R37: =+E37+Q37 -> 0
A38: 17 | D38: 18 | E38: =+SUM(B38:D38) -> 18 | H38: 0.5 | J38: =+SUM(F38:I38) -> 0.5 | P38: =+SUM(K38:O38) -> 0 | Q38: =+J38+P38 -> 0.5 | R38: =+E38+Q38 -> 18.5
A39: 18 | E39: =+SUM(B39:D39) -> 0 | J39: =+SUM(F39:I39) -> 0 | P39: =+SUM(K39:O39) -> 0 | Q39: =+J39+P39 -> 0 | R39: =+E39+Q39 -> 0
A40: 19 | E40: =+SUM(B40:D40) -> 0 | J40: =+SUM(F40:I40) -> 0 | P40: =+SUM(K40:O40) -> 0 | Q40: =+J40+P40 -> 0 | R40: =+E40+Q40 -> 0
A41: 20 | E41: =+SUM(B41:D41) -> 0 | J41: =+SUM(F41:I41) -> 0 | P41: =+SUM(K41:O41) -> 0 | Q41: =+J41+P41 -> 0 | R41: =+E41+Q41 -> 0
A42: 21 | E42: =+SUM(B42:D42) -> 0 | J42: =+SUM(F42:I42) -> 0 | P42: =+SUM(K42:O42) -> 0 | Q42: =+J42+P42 -> 0 | R42: =+E42+Q42 -> 0
A43: 22 | E43: =+SUM(B43:D43) -> 0 | J43: =+SUM(F43:I43) -> 0 | P43: =+SUM(K43:O43) -> 0 | Q43: =+J43+P43 -> 0 | R43: =+E43+Q43 -> 0
A44: 23 | E44: =+SUM(B44:D44) -> 0 | J44: =+SUM(F44:I44) -> 0 | P44: =+SUM(K44:O44) -> 0 | Q44: =+J44+P44 -> 0 | R44: =+E44+Q44 -> 0
A45: 24 | E45: =+SUM(B45:D45) -> 0 | J45: =+SUM(F45:I45) -> 0 | P45: =+SUM(K45:O45) -> 0 | Q45: =+J45+P45 -> 0 | R45: =+E45+Q45 -> 0
A46: 25 | E46: =+SUM(B46:D46) -> 0 | J46: =+SUM(F46:I46) -> 0 | P46: =+SUM(K46:O46) -> 0 | Q46: =+J46+P46 -> 0 | R46: =+E46+Q46 -> 0
A47: 26 | D47: 6 | E47: =+SUM(B47:D47) -> 6 | J47: =+SUM(F47:I47) -> 0 | P47: =+SUM(K47:O47) -> 0 | Q47: =+J47+P47 -> 0 | R47: =+E47+Q47 -> 6
A48: 27 | E48: =+SUM(B48:D48) -> 0 | J48: =+SUM(F48:I48) -> 0 | P48: =+SUM(K48:O48) -> 0 | Q48: =+J48+P48 -> 0 | R48: =+E48+Q48 -> 0
A49: 28 | E49: =+SUM(B49:D49) -> 0 | J49: =+SUM(F49:I49) -> 0 | P49: =+SUM(K49:O49) -> 0 | Q49: =+J49+P49 -> 0 | R49: =+E49+Q49 -> 0
A50: 29 | E50: =+SUM(B50:D50) -> 0 | J50: =+SUM(F50:I50) -> 0 | P50: =+SUM(K50:O50) -> 0 | Q50: =+J50+P50 -> 0 | R50: =+E50+Q50 -> 0
A51: 30 | E51: =+SUM(B51:D51) -> 0 | J51: =+SUM(F51:I51) -> 0 | P51: =+SUM(K51:O51) -> 0 | Q51: =+J51+P51 -> 0 | R51: =+E51+Q51 -> 0
...

Sheet Noviembre
D1: FORMATO REGISTRO ANUAL DE GENERACION DE RESIDUOS GENERADOS EN LA ATENCION EN SALUD Y OTRAS ACTIVIDADES | Q1: Version 2.0
Q3: Fecha: 08/03/2022
Q5: CODIGO
A7: 1. Nombre del Generador | D7: GESTAR SALUD CIENAGA DE ORO CONTRIBUTIVO | K7: 6. Correo Electronico | N7: SEDECIENAGA@GESTARSALUDIPS.COM
A8: 2. Ciudad | D8: CIENAGA DE ORO | K8: 7. Responsable del diligenciamiento | N8: YULIS DURANGO
A9: 3. Departamento | D9: CORDOBA | K9: 8. Cargo | N9: SERVICIOS GENERALES
A10: 4. Direccion | D10: CALLE 7 14-16 BARRIO CENTRO | K10: 9. Mes: | N10: NOVIEMBRE
A11: 5. Telefono
A16: CONSOLIDACION RESIDUOS POR ESTABLECIMIENTO GENERADOR DE RESIDUOS
B18: 10 | C18: 11 | D18: 12 | E18: 13 | F18: 14 | G18: 15 | H18: 16 | I18: 17 | J18: 18 | K18: 19 | L18: 20 | M18: 21 | N18: 22 | O18: 23 | P18: 24 | Q18: 0 | R18: 26
A19: DÍA | B19: RESIDUOS NO PELIGROS | E19: Subtotal Residuos no peligrosos | F19: RESIDUOS PELIGROSOS | Q19: Subtotal Residuos Peligrosos | R19: TOTAL
F20: INFECCIOSO O RIESGO BIOLOGICO | J20: Subtotal residuos de riesgo biologico o infeccioso | K20: OTROS RESIDUOS CON LAS SIGUIENTES CARACTERISTICAS | P20: Subtotal otros residuos
B21: BIODEGRADABLES (KG/DÍA) | C21: RECICLABLES (KG/DÍA) | D21: ORDINARIOS (KG/DÍA) | F21: BIOSANITARIOS (KG/DÍA) | G21: ANATOMOPATOLOGICOS (KG/DÍA) | H21: CORTOPUNZANTES (KG/DÍA) | I21: ANIMALES (KG/DÍA) | K21: CORROSIVA (KG/DÍA) | L21: EXPLOSIVO (KG/DÍA) | M21: TOXICO (KG/DÍA) | N21: INFLAMABLE (KG/DÍA) | O21: REACTIVO (KG/DÍA)
A22: 1 | E22: =+SUM(B22:D22) -> 0 | J22: =+SUM(F22:I22) -> 0 | P22: =+SUM(K22:O22) -> 0 | Q22: =+J22+P22 -> 0 | R22: =+E22+Q22 -> 0
A23: 2 | E23: =+SUM(B23:D23) -> 0 | J23: =+SUM(F23:I23) -> 0 | P23: =+SUM(K23:O23) -> 0 | Q23: =+J23+P23 -> 0 | R23: =+E23+Q23 -> 0
A24: 3 | E24: =+SUM(B24:D24) -> 0 | J24: =+SUM(F24:I24) -> 0 | P24: =+SUM(K24:O24) -> 0 | Q24: =+J24+P24 -> 0 | R24: =+E24+Q24 -> 0
A25: 4 | E25: =+SUM(B25:D25) -> 0 | J25: =+SUM(F25:I25) -> 0 | P25: =+SUM(K25:O25) -> 0 | Q25: =+J25+P25 -> 0 | R25: =+E25+Q25 -> 0
A26: 5 | E26: =+SUM(B26:D26) -> 0 | J26: =+SUM(F26:I26) -> 0 | P26: =+SUM(K26:O26) -> 0 | Q26: =+J26+P26 -> 0 | R26: =+E26+Q26 -> 0
A27: 6 | E27: =+SUM(B27:D27) -> 0 | J27: =+SUM(F27:I27) -> 0 | P27: =+SUM(K27:O27) -> 0 | Q27: =+J27+P27 -> 0 | R27: =+E27+Q27 -> 0
A28: 7 | E28: =+SUM(B28:D28) -> 0 | J28: =+SUM(F28:I28) -> 0 | P28: =+SUM(K28:O28) -> 0 | Q28: =+J28+P28 -> 0 | R28: =+E28+Q28 -> 0
A29: 8 | E29: =+SUM(B29:D29) -> 0 | J29: =+SUM(F29:I29) -> 0 | P29: =+SUM(K29:O29) -> 0 | Q29: =+J29+P29 -> 0 | R29: =+E29+Q29 -> 0
A30: 9 | E30: =+SUM(B30:D30) -> 0 | J30: =+SUM(F30:I30) -> 0 | P30: =+SUM(K30:O30) -> 0 | Q30: =+J30+P30 -> 0 | R30: =+E30+Q30 -> 0
A31: 10 | D31: 8.7 | E31: =+SUM(B31:D31) -> 8.7 | J31: =+SUM(F31:I31) -> 0 | P31: =+SUM(K31:O31) -> 0 | Q31: =+J31+P31 -> 0 | R31: =+E31+Q31 -> 8.7
A32: 11 | E32: =+SUM(B32:D32) -> 0 | J32: =+SUM(F32:I32) -> 0 | P32: =+SUM(K32:O32) -> 0 | Q32: =+J32+P32 -> 0 | R32: =+E32+Q32 -> 0
A33: 12 | E33: =+SUM(B33:D33) -> 0 | J33: =+SUM(F33:I33) -> 0 | P33: =+SUM(K33:O33) -> 0 | Q33: =+J33+P33 -> 0 | R33: =+E33+Q33 -> 0
